Workbook
Name LT_CategoryUS: Backend!$A$26:$A$31
Name LT_MacroDir: Backend!$A$11:$A$19
Name LT_RatePolicy: Backend!$A$20:$A$22
Name LT_RiskEnv: Backend!$A$23:$A$25
Name LT_Speakers: Backend!$A$35:$A$55
Name LT_TrendBull: Backend!$A$2:$A$7
Name LT_WeekNum: Backend!$A$8:$A$10

Sheet Instructions
A1: FOREX TRADING WORKBOOK — USER GUIDE
A2: Version 1.0 | Ready for distribution
A4: SECTION 1 — COLOR GUIDE
A5: Blue cells = YOU enter data here — click and type freely
A6: Grey cells = Auto-calculated — do NOT edit
A8: SECTION 2 — THE 5 TABS (what each one does)
A9: Instructions | B9: This page. Read first.
A10: Summary | B10: Monthly performance dashboard. Fill 6 cells at start of month.
A11: Daily Log | B11: Daily trading journal. Fill 4 columns per day.
A12: Raw daily data | B12: Paste broker export here daily. Columns A–H only.
A13: Advanced Setup Planner | B13: Fill every morning before your session.
A15: SECTION 3 — SUMMARY TAB
A16: Fill these 6 blue cells at the start of each month:
A17: Monthly Profit Target ($) → How much you aim to make
A18: Planned Active Trading Days → Days you plan to trade
A19: Weeks in Cycle → Usually 4
A20: Risk % per trade → e.g. 0.07 = 7% of NAV
A21: Max Daily Loss (R multiples) → e.g. 2 = stop after losing 2R
A22: Current NAV ($) → Account balance on day 1
A24: SECTION 4 — DAILY LOG TAB
A25: Each trading day, fill ONLY these 4 columns:
A26: Column A → Today's date
A27: Column B → Week number in cycle (1, 2, 3 or 4)
... A40: Fill this every morning BEFORE your trading session.
A41: Step 1 — EMAs | B41: EMA9/21/50 on 15m, SMA200 on 15m, EMA50 on 1H/4H/1D/1W, EMA100/200 on 1D, EMA20 on 1M, Current Price
A42: Step 2 — RSI & ATR | B42: RSI(14) from 15m, 1H, 4H. ATR(14) from 15m. ADR(14).
A43: Step 3 — Price Levels | B43: PWH/PWL, PDH/PDL, EQH/EQL, LTF Leg, Session High/Low, HTF Swing High/Low.
A44: Step 4 — FVG Zones | B44: Daily FVG high/low, 1H FVG high/low. Leave blank if no clear FVG.
A45: Step 5 — Options Gamma | B45: Up to 4 strike prices with open interest (bn). Leave blank if unavailable.
A46: Step 6 — Outputs | B46: SIDE, TRADE MODE, 4 LADDERS, NARRATIVE are auto-calculated — do not edit.
A48: SECTION 7 — NEW MONTH RESET
A49: 1. Save current file as Trading_[Month][Year].xlsx (e.g. Trading_Apr2026.xlsx)
A50: 2. Open this master template
A51: 3. Update Summary → Current NAV = ending balance of last month
A52: 4. Clear Daily Log columns A, B, D, M (keep formulas in other columns)
A53: 5. Delete rows 2+ in Raw daily data
A54: 6. Clear all blue input cells in Advanced Setup Planner
A55: 7. Save — ready for new month
A57: SECTION 8 — FAQs
A58: Q: Some cells show "" (empty) — is that a bug?
...

Sheet Summary
A1: Label | B1: Value
A2: Monthly Target ($) | B2: 20000
A3: Planned Active Trading Days | B3: 17
A4: Average Target per Trading Day ($) | B4: =B2/B3
A5: Weeks in Cycle | B5: 4
A6: Average Target per Week ($) | B6: =B2/B5
A7: Required R per week | B7: =B6/B17
A8: Risk % of NAV per trade | B8: 0.07
A9: Max Daily Loss (R multiples) | B9: 2
A10: Current NAV ($) | B10: 7175.38
A11: Cumulative P&L Month ($) | B11: =IFERROR(LOOKUP(2,1/('Daily Log'!$I:$I<>""),'Daily Log'!$I:$I),"")
A12: Remaining Target ($) | B12: =B2-B11
A13: Trading Days Used | B13: =COUNTIFS('Daily Log'!D:D,"Y")
A14: Trading Days Remaining | B14: =B3-B13
A15: Required P&L per Remaining Day | B15: =IF(B14>0,B12/B14,"")
A16: Target R per Day (approx) | B16: =IF(AND(B14>0,B18>0),B15/B18,"")
A17: Projected Month P&L ($) | B17: =B11+(B14*B16)
A18: Average R value ($) | B18: =IF(K22>0,B11/K22,"")
A19: Today’s expected plan P&L ($) | B19: ='Advanced Setup Planner'!EE18
A21: Week # | B21: Active Days | C21: Total Trades | D21: Total Wins | E21: Total Losses | F21: Week Net P&L | G21: Weekly Target | H21: Week Variance ($) | I21: Avg Win Rate % | J21: Avg Reward:Risk | K21: Total R | L21: Avg R per Day
A22: 1 | B22: =COUNTIFS('Daily Log'!$B:$B,$A22,'Daily Log'!$D:$D,"Y") | C22: =SUMIFS('Daily Log'!$N:$N,'Daily Log'!$B:$B,$A22) | D22: =SUMIFS('Daily Log'!$O:$O,'Daily Log'!$B:$B,$A22) | E22: =SUMIFS('Daily Log'!$P:$P,'Daily Log'!$B:$B,$A22) | F22: =SUMIFS('Daily Log'!$H:$H,'Daily Log'!$B:$B,$A22) | G22: =$B$6 | H22: =F22-G22 | I22: =IF(B22>0,AVERAGEIFS('Daily Log'!$S:$S,'Daily Log'!$B:$B,$A22,'Daily Log'!$D:$D,"Y"),"") | J22: =IF(B22>0,IFERROR(AVERAGEIFS('Daily Log'!$T:$T,'Daily Log'!$B:$B,$A22,'Daily Log'!$D:$D,"Y",'Daily Log'!$T:$T,">0"),""),"") | K22: =SUMIFS('Daily Log'!$U:$U,'Daily Log'!$B:$B,$A22,'Daily Log'!$D:$D,"Y") | L22: =IF(B22>0,K22/B22,"")
A23: 2 | B23: =COUNTIFS('Daily Log'!$B:$B,$A23,'Daily Log'!$D:$D,"Y") | C23: =SUMIFS('Daily Log'!$N:$N,'Daily Log'!$B:$B,$A23) | D23: =SUMIFS('Daily Log'!$O:$O,'Daily Log'!$B:$B,$A23) | E23: =SUMIFS('Daily Log'!$P:$P,'Daily Log'!$B:$B,$A23) | F23: =SUMIFS('Daily Log'!$H:$H,'Daily Log'!$B:$B,$A23) | G23: =$B$6 | H23: =F23-G23 | I23: =IF(B23>0,AVERAGEIFS('Daily Log'!$S:$S,'Daily Log'!$B:$B,$A23,'Daily Log'!$D:$D,"Y"),"") | J23: =IF(B23>0,AVERAGEIFS('Daily Log'!$T:$T,'Daily Log'!$B:$B,$A23,'Daily Log'!$D:$D,"Y",'Daily Log'!$T:$T,">0"),"") | K23: =SUMIFS('Daily Log'!$U:$U,'Daily Log'!$B:$B,$A23,'Daily Log'!$D:$D,"Y") | L23: =IF(B23>0,K23/B23,"")
A24: 3 | B24: =COUNTIFS('Daily Log'!$B:$B,$A24,'Daily Log'!$D:$D,"Y") | C24: =SUMIFS('Daily Log'!$N:$N,'Daily Log'!$B:$B,$A24) | D24: =SUMIFS('Daily Log'!$O:$O,'Daily Log'!$B:$B,$A24) | E24: =SUMIFS('Daily Log'!$P:$P,'Daily Log'!$B:$B,$A24) | F24: =SUMIFS('Daily Log'!$H:$H,'Daily Log'!$B:$B,$A24) | G24: =$B$6 | H24: =F24-G24 | I24: =IF(B24>0,AVERAGEIFS('Daily Log'!$S:$S,'Daily Log'!$B:$B,$A24,'Daily Log'!$D:$D,"Y"),"") | J24: =IF(B24>0,AVERAGEIFS('Daily Log'!$T:$T,'Daily Log'!$B:$B,$A24,'Daily Log'!$D:$D,"Y",'Daily Log'!$T:$T,">0"),"") | K24: =SUMIFS('Daily Log'!$U:$U,'Daily Log'!$B:$B,$A24,'Daily Log'!$D:$D,"Y") | L24: =IF(B24>0,K24/B24,"")
A25: 4 | B25: =COUNTIFS('Daily Log'!$B:$B,$A25,'Daily Log'!$D:$D,"Y") | C25: =SUMIFS('Daily Log'!$N:$N,'Daily Log'!$B:$B,$A25) | D25: =SUMIFS('Daily Log'!$O:$O,'Daily Log'!$B:$B,$A25) | E25: =SUMIFS('Daily Log'!$P:$P,'Daily Log'!$B:$B,$A25) | F25: =SUMIFS('Daily Log'!$H:$H,'Daily Log'!$B:$B,$A25) | G25: =$B$6 | H25: =F25-G25 | I25: =IF(B25>0,AVERAGEIFS('Daily Log'!$S:$S,'Daily Log'!$B:$B,$A25,'Daily Log'!$D:$D,"Y"),"") | J25: =IF(B25>0,AVERAGEIFS('Daily Log'!$T:$T,'Daily Log'!$B:$B,$A25,'Daily Log'!$D:$D,"Y",'Daily Log'!$T:$T,">0"),"") | K25: =SUMIFS('Daily Log'!$U:$U,'Daily Log'!$B:$B,$A25,'Daily Log'!$D:$D,"Y") | L25: =IF(B25>0,K25/B25,"")

Sheet Daily Log
A1: Date | B1: Week # | C1: Day of Week | D1: Active Trading Day? (Y/N) | E1: Start NAV ($) | F1: Risk per Trade R ($) | G1: Max Daily Loss Cap ($) | H1: Net P&L ($) | I1: Cumulative P&L Month ($) | J1: Week P&L ($) | K1: Weekly Target ($) | L1: Week Variance vs Target ($) | M1: Notes | N1: # Trades | O1: # Wins | P1: # Losses | Q1: Total Wins ($) | R1: Total Losses ($) | S1: Win Rate (%) | T1: Reward:Risk | U1: Daily R-multiple | V1: Losses vs Cap | W1: Intraday Net P&L (so far) | X1: % of Cap Used (Net) | Y1: Worst Intraday DD % of Cap
A2: 46033 | B2: 1 | C2: =TEXT(A2,"dddd") | D2: Y | E2: 7175.38 | F2: =IF($A2="","",$E2*Summary!$B$8) | G2: =IF($A2="","",F2*Summary!$B$9) | H2: =IF($A2="","",SUMIFS('Raw daily data'!$F:$F,'Raw daily data'!$I:$I,$A2)) | I2: =H2 | J2: =SUMIF($B$2:$B$41,B2,$H$2:$H$41) | K2: =Summary!$B$6 | L2: =J2-K2 | N2: =IF($A2="","",COUNTIFS('Raw daily data'!$I:$I,$A2)) | O2: =IF($A2="","",COUNTIFS('Raw daily data'!$I:$I,$A2,'Raw daily data'!$F:$F,">0")) | P2: =IF($A2="","",COUNTIFS('Raw daily data'!$I:$I,$A2,'Raw daily data'!$F:$F,"<0")) | Q2: =IF($A2="","",SUMIFS('Raw daily data'!$F:$F,'Raw daily data'!$I:$I,$A2,'Raw daily data'!$F:$F,">0")) | R2: =IF($A2="","",ABS(SUMIFS('Raw daily data'!$F:$F,'Raw daily data'!$I:$I,$A2,'Raw daily data'!$F:$F,"<0"))) | S2: =IF(N2>0,O2/N2,"") | T2: =IF(R2>0,Q2/ABS(R2),"") | U2: =IF(F2>0,H2/F2,"") | V2: =IF(H2<0,MIN(ABS(H2)/G2,1),0) | W2: =IF($A2="","",_xlfn.MAXIFS('Raw daily data'!$J:$J,'Raw daily data'!$I:$I,$A2)) | X2: =IF(W2>=0,0,ABS(W2)/G2) | Y2: =IF($A2="","",ABS(MIN(0,_xlfn.MINIFS('Raw daily data'!$J:$J,'Raw daily data'!$I:$I,$A2)))/G2)
A3: 46034 | B3: 1 | C3: =TEXT(A3,"dddd") | D3: Y | E3: =E2+H2 | F3: =IF($A3="","",$E3*Summary!$B$8) | G3: =IF($A3="","",F3*Summary!$B$9) | H3: =IF($A3="","",SUMIFS('Raw daily data'!$F:$F,'Raw daily data'!$I:$I,$A3)) | I3: =I2+H3 | J3: =SUMIF($B$2:$B$41,B3,$H$2:$H$41) | K3: =Summary!$B$6 | L3: =J3-K3 | N3: =IF($A3="","",COUNTIFS('Raw daily data'!$I:$I,$A3)) | O3: =IF($A3="","",COUNTIFS('Raw daily data'!$I:$I,$A3,'Raw daily data'!$F:$F,">0")) | P3: =IF($A3="","",COUNTIFS('Raw daily data'!$I:$I,$A3,'Raw daily data'!$F:$F,"<0")) | Q3: =IF($A3="","",SUMIFS('Raw daily data'!$F:$F,'Raw daily data'!$I:$I,$A3,'Raw daily data'!$F:$F,">0")) | R3: =IF($A3="","",ABS(SUMIFS('Raw daily data'!$F:$F,'Raw daily data'!$I:$I,$A3,'Raw daily data'!$F:$F,"<0"))) | S3: =IF(N3>0,O3/N3,"") | T3: =IF(R3>0,Q3/ABS(R3),"") | U3: =IF(F3>0,H3/F3,"") | V3: =IF(H3<0,MIN(ABS(H3)/G3,1),0) | W3: =IF($A3="","",_xlfn.MAXIFS('Raw daily data'!$J:$J,'Raw daily data'!$I:$I,$A3)) | X3: =IF(W3>=0,0,ABS(W3)/G3) | Y3: =IF($A3="","",ABS(MIN(0,_xlfn.MINIFS('Raw daily data'!$J:$J,'Raw daily data'!$I:$I,$A3)))/G3)
A4: 46035 | B4: 1 | C4: =TEXT(A4,"dddd") | D4: N | E4: =E3+H3 | F4: =IF($A4="","",$E4*Summary!$B$8) | G4: =IF($A4="","",F4*Summary!$B$9) | H4: =IF($A4="","",SUMIFS('Raw daily data'!$F:$F,'Raw daily data'!$I:$I,$A4)) | I4: =I3+H4 | J4: =SUMIF($B$2:$B$41,B4,$H$2:$H$41) | K4: =Summary!$B$6 | L4: =J4-K4 | N4: =IF($A4="","",COUNTIFS('Raw daily data'!$I:$I,$A4)) | O4: =IF($A4="","",COUNTIFS('Raw daily data'!$I:$I,$A4,'Raw daily data'!$F:$F,">0")) | P4: =IF($A4="","",COUNTIFS('Raw daily data'!$I:$I,$A4,'Raw daily data'!$F:$F,"<0")) | Q4: =IF($A4="","",SUMIFS('Raw daily data'!$F:$F,'Raw daily data'!$I:$I,$A4,'Raw daily data'!$F:$F,">0")) | R4: =IF($A4="","",ABS(SUMIFS('Raw daily data'!$F:$F,'Raw daily data'!$I:$I,$A4,'Raw daily data'!$F:$F,"<0"))) | S4: =IF(N4>0,O4/N4,"") | T4: =IF(R4>0,Q4/ABS(R4),"") | U4: =IF(F4>0,H4/F4,"") | V4: =IF(H4<0,MIN(ABS(H4)/G4,1),0) | W4: =IF($A4="","",_xlfn.MAXIFS('Raw daily data'!$J:$J,'Raw daily data'!$I:$I,$A4)) | X4: =IF(W4>=0,0,ABS(W4)/G4) | Y4: =IF($A4="","",ABS(MIN(0,_xlfn.MINIFS('Raw daily data'!$J:$J,'Raw daily data'!$I:$I,$A4)))/G4)
A5: 46036 | B5: 1 | C5: =TEXT(A5,"dddd") | D5: N | E5: =E4+H4 | F5: =IF($A5="","",$E5*Summary!$B$8) | G5: =IF($A5="","",F5*Summary!$B$9) | H5: =IF($A5="","",SUMIFS('Raw daily data'!$F:$F,'Raw daily data'!$I:$I,$A5)) | I5: =I4+H5 | J5: =SUMIF($B$2:$B$41,B5,$H$2:$H$41) | K5: =Summary!$B$6 | L5: =J5-K5 | N5: =IF($A5="","",COUNTIFS('Raw daily data'!$I:$I,$A5)) | O5: =IF($A5="","",COUNTIFS('Raw daily data'!$I:$I,$A5,'Raw daily data'!$F:$F,">0")) | P5: =IF($A5="","",COUNTIFS('Raw daily data'!$I:$I,$A5,'Raw daily data'!$F:$F,"<0")) | Q5: =IF($A5="","",SUMIFS('Raw daily data'!$F:$F,'Raw daily data'!$I:$I,$A5,'Raw daily data'!$F:$F,">0")) | R5: =IF($A5="","",ABS(SUMIFS('Raw daily data'!$F:$F,'Raw daily data'!$I:$I,$A5,'Raw daily data'!$F:$F,"<0"))) | S5: =IF(N5>0,O5/N5,"") | T5: =IF(R5>0,Q5/ABS(R5),"") | U5: =IF(F5>0,H5/F5,"") | V5: =IF(H5<0,MIN(ABS(H5)/G5,1),0) | W5: =IF($A5="","",_xlfn.MAXIFS('Raw daily data'!$J:$J,'Raw daily data'!$I:$I,$A5)) | X5: =IF(W5>=0,0,ABS(W5)/G5) | Y5: =IF($A5="","",ABS(MIN(0,_xlfn.MINIFS('Raw daily data'!$J:$J,'Raw daily data'!$I:$I,$A5)))/G5)
A6: 46037 | B6: 1 | C6: =TEXT(A6,"dddd") | D6: N | E6: =E5+H5 | F6: =IF($A6="","",$E6*Summary!$B$8) | G6: =IF($A6="","",F6*Summary!$B$9) | H6: =IF($A6="","",SUMIFS('Raw daily data'!$F:$F,'Raw daily data'!$I:$I,$A6)) | I6: =I5+H6 | J6: =SUMIF($B$2:$B$41,B6,$H$2:$H$41) | K6: =Summary!$B$6 | L6: =J6-K6 | N6: =IF($A6="","",COUNTIFS('Raw daily data'!$I:$I,$A6)) | O6: =IF($A6="","",COUNTIFS('Raw daily data'!$I:$I,$A6,'Raw daily data'!$F:$F,">0")) | P6: =IF($A6="","",COUNTIFS('Raw daily data'!$I:$I,$A6,'Raw daily data'!$F:$F,"<0")) | Q6: =IF($A6="","",SUMIFS('Raw daily data'!$F:$F,'Raw daily data'!$I:$I,$A6,'Raw daily data'!$F:$F,">0")) | R6: =IF($A6="","",ABS(SUMIFS('Raw daily data'!$F:$F,'Raw daily data'!$I:$I,$A6,'Raw daily data'!$F:$F,"<0"))) | S6: =IF(N6>0,O6/N6,"") | T6: =IF(R6>0,Q6/ABS(R6),"") | U6: =IF(F6>0,H6/F6,"") | V6: =IF(H6<0,MIN(ABS(H6)/G6,1),0) | W6: =IF($A6="","",_xlfn.MAXIFS('Raw daily data'!$J:$J,'Raw daily data'!$I:$I,$A6)) | X6: =IF(W6>=0,0,ABS(W6)/G6) | Y6: =IF($A6="","",ABS(MIN(0,_xlfn.MINIFS('Raw daily data'!$J:$J,'Raw daily data'!$I:$I,$A6)))/G6)
A7: 46038 | B7: 1 | C7: =TEXT(A7,"dddd") | D7: N | E7: =E6+H6 | F7: =IF($A7="","",$E7*Summary!$B$8) | G7: =IF($A7="","",F7*Summary!$B$9) | H7: =IF($A7="","",SUMIFS('Raw daily data'!$F:$F,'Raw daily data'!$I:$I,$A7)) | I7: =I6+H7 | J7: =SUMIF($B$2:$B$41,B7,$H$2:$H$41) | K7: =Summary!$B$6 | L7: =J7-K7 | N7: =IF($A7="","",COUNTIFS('Raw daily data'!$I:$I,$A7)) | O7: =IF($A7="","",COUNTIFS('Raw daily data'!$I:$I,$A7,'Raw daily data'!$F:$F,">0")) | P7: =IF($A7="","",COUNTIFS('Raw daily data'!$I:$I,$A7,'Raw daily data'!$F:$F,"<0")) | Q7: =IF($A7="","",SUMIFS('Raw daily data'!$F:$F,'Raw daily data'!$I:$I,$A7,'Raw daily data'!$F:$F,">0")) | R7: =IF($A7="","",ABS(SUMIFS('Raw daily data'!$F:$F,'Raw daily data'!$I:$I,$A7,'Raw daily data'!$F:$F,"<0"))) | S7: =IF(N7>0,O7/N7,"") | T7: =IF(R7>0,Q7/ABS(R7),"") | U7: =IF(F7>0,H7/F7,"") | V7: =IF(H7<0,MIN(ABS(H7)/G7,1),0) | W7: =IF($A7="","",_xlfn.MAXIFS('Raw daily data'!$J:$J,'Raw daily data'!$I:$I,$A7)) | X7: =IF(W7>=0,0,ABS(W7)/G7) | Y7: =IF($A7="","",ABS(MIN(0,_xlfn.MINIFS('Raw daily data'!$J:$J,'Raw daily data'!$I:$I,$A7)))/G7)
A8: 46039 | B8: 1 | C8: =TEXT(A8,"dddd") | D8: N | E8: =E7+H7 | F8: =IF($A8="","",$E8*Summary!$B$8) | G8: =IF($A8="","",F8*Summary!$B$9) | H8: =IF($A8="","",SUMIFS('Raw daily data'!$F:$F,'Raw daily data'!$I:$I,$A8)) | I8: =I7+H8 | J8: =SUMIF($B$2:$B$41,B8,$H$2:$H$41) | K8: =Summary!$B$6 | L8: =J8-K8 | N8: =IF($A8="","",COUNTIFS('Raw daily data'!$I:$I,$A8)) | O8: =IF($A8="","",COUNTIFS('Raw daily data'!$I:$I,$A8,'Raw daily data'!$F:$F,">0")) | P8: =IF($A8="","",COUNTIFS('Raw daily data'!$I:$I,$A8,'Raw daily data'!$F:$F,"<0")) | Q8: =IF($A8="","",SUMIFS('Raw daily data'!$F:$F,'Raw daily data'!$I:$I,$A8,'Raw daily data'!$F:$F,">0")) | R8: =IF($A8="","",ABS(SUMIFS('Raw daily data'!$F:$F,'Raw daily data'!$I:$I,$A8,'Raw daily data'!$F:$F,"<0"))) | S8: =IF(N8>0,O8/N8,"") | T8: =IF(R8>0,Q8/ABS(R8),"") | U8: =IF(F8>0,H8/F8,"") | V8: =IF(H8<0,MIN(ABS(H8)/G8,1),0) | W8: =IF($A8="","",_xlfn.MAXIFS('Raw daily data'!$J:$J,'Raw daily data'!$I:$I,$A8)) | X8: =IF(W8>=0,0,ABS(W8)/G8) | Y8: =IF($A8="","",ABS(MIN(0,_xlfn.MINIFS('Raw daily data'!$J:$J,'Raw daily data'!$I:$I,$A8)))/G8)
A9: 46040 | B9: 2 | C9: =TEXT(A9,"dddd") | D9: N | E9: =E8+H8 | F9: =IF($A9="","",$E9*Summary!$B$8) | G9: =IF($A9="","",F9*Summary!$B$9) | H9: =IF($A9="","",SUMIFS('Raw daily data'!$F:$F,'Raw daily data'!$I:$I,$A9)) | I9: =I8+H9 | J9: =SUMIF($B$2:$B$41,B9,$H$2:$H$41) | K9: =Summary!$B$6 | L9: =J9-K9 | N9: =IF($A9="","",COUNTIFS('Raw daily data'!$I:$I,$A9)) | O9: =IF($A9="","",COUNTIFS('Raw daily data'!$I:$I,$A9,'Raw daily data'!$F:$F,">0")) | P9: =IF($A9="","",COUNTIFS('Raw daily data'!$I:$I,$A9,'Raw daily data'!$F:$F,"<0")) | Q9: =IF($A9="","",SUMIFS('Raw daily data'!$F:$F,'Raw daily data'!$I:$I,$A9,'Raw daily data'!$F:$F,">0")) | R9: =IF($A9="","",ABS(SUMIFS('Raw daily data'!$F:$F,'Raw daily data'!$I:$I,$A9,'Raw daily data'!$F:$F,"<0"))) | S9: =IF(N9>0,O9/N9,"") | T9: =IF(R9>0,Q9/ABS(R9),"") | U9: =IF(F9>0,H9/F9,"") | V9: =IF(H9<0,MIN(ABS(H9)/G9,1),0) | W9: =IF($A9="","",_xlfn.MAXIFS('Raw daily data'!$J:$J,'Raw daily data'!$I:$I,$A9)) | X9: =IF(W9>=0,0,ABS(W9)/G9) | Y9: =IF($A9="","",ABS(MIN(0,_xlfn.MINIFS('Raw daily data'!$J:$J,'Raw daily data'!$I:$I,$A9)))/G9)
A10: 46041 | B10: 2 | C10: =TEXT(A10,"dddd") | E10: =E9+H9 | F10: =IF($A10="","",$E10*Summary!$B$8) | G10: =IF($A10="","",F10*Summary!$B$9) | H10: =IF($A10="","",SUMIFS('Raw daily data'!$F:$F,'Raw daily data'!$I:$I,$A10)) | I10: =I9+H10 | J10: =SUMIF($B$2:$B$41,B10,$H$2:$H$41) | K10: =Summary!$B$6 | L10: =J10-K10 | N10: =IF($A10="","",COUNTIFS('Raw daily data'!$I:$I,$A10)) | O10: =IF($A10="","",COUNTIFS('Raw daily data'!$I:$I,$A10,'Raw daily data'!$F:$F,">0")) | P10: =IF($A10="","",COUNTIFS('Raw daily data'!$I:$I,$A10,'Raw daily data'!$F:$F,"<0")) | Q10: =IF($A10="","",SUMIFS('Raw daily data'!$F:$F,'Raw daily data'!$I:$I,$A10,'Raw daily data'!$F:$F,">0")) | R10: =IF($A10="","",ABS(SUMIFS('Raw daily data'!$F:$F,'Raw daily data'!$I:$I,$A10,'Raw daily data'!$F:$F,"<0"))) | S10: =IF(N10>0,O10/N10,"") | T10: =IF(R10>0,Q10/ABS(R10),"") | U10: =IF(F10>0,H10/F10,"") | V10: =IF(H10<0,MIN(ABS(H10)/G10,1),0) | W10: =IF($A10="","",_xlfn.MAXIFS('Raw daily data'!$J:$J,'Raw daily data'!$I:$I,$A10)) | X10: =IF(W10>=0,0,ABS(W10)/G10) | Y10: =IF($A10="","",ABS(MIN(0,_xlfn.MINIFS('Raw daily data'!$J:$J,'Raw daily data'!$I:$I,$A10)))/G10)
A11: 46042 | B11: 2 | C11: =TEXT(A11,"dddd") | E11: =E10+H10 | F11: =IF($A11="","",$E11*Summary!$B$8) | G11: =IF($A11="","",F11*Summary!$B$9) | H11: =IF($A11="","",SUMIFS('Raw daily data'!$F:$F,'Raw daily data'!$I:$I,$A11)) | I11: =I10+H11 | J11: =SUMIF($B$2:$B$41,B11,$H$2:$H$41) | K11: =Summary!$B$6 | L11: =J11-K11 | N11: =IF($A11="","",COUNTIFS('Raw daily data'!$I:$I,$A11)) | O11: =IF($A11="","",COUNTIFS('Raw daily data'!$I:$I,$A11,'Raw daily data'!$F:$F,">0")) | P11: =IF($A11="","",COUNTIFS('Raw daily data'!$I:$I,$A11,'Raw daily data'!$F:$F,"<0")) | Q11: =IF($A11="","",SUMIFS('Raw daily data'!$F:$F,'Raw daily data'!$I:$I,$A11,'Raw daily data'!$F:$F,">0")) | R11: =IF($A11="","",ABS(SUMIFS('Raw daily data'!$F:$F,'Raw daily data'!$I:$I,$A11,'Raw daily data'!$F:$F,"<0"))) | S11: =IF(N11>0,O11/N11,"") | T11: =IF(R11>0,Q11/ABS(R11),"") | U11: =IF(F11>0,H11/F11,"") | V11: =IF(H11<0,MIN(ABS(H11)/G11,1),0) | W11: =IF($A11="","",_xlfn.MAXIFS('Raw daily data'!$J:$J,'Raw daily data'!$I:$I,$A11)) | X11: =IF(W11>=0,0,ABS(W11)/G11) | Y11: =IF($A11="","",ABS(MIN(0,_xlfn.MINIFS('Raw daily data'!$J:$J,'Raw daily data'!$I:$I,$A11)))/G11)
A12: 46043 | B12: 2 | C12: =TEXT(A12,"dddd") | E12: =E11+H11 | F12: =IF($A12="","",$E12*Summary!$B$8) | G12: =IF($A12="","",F12*Summary!$B$9) | H12: =IF($A12="","",SUMIFS('Raw daily data'!$F:$F,'Raw daily data'!$I:$I,$A12)) | I12: =I11+H12 | J12: =SUMIF($B$2:$B$41,B12,$H$2:$H$41) | K12: =Summary!$B$6 | L12: =J12-K12 | N12: =IF($A12="","",COUNTIFS('Raw daily data'!$I:$I,$A12)) | O12: =IF($A12="","",COUNTIFS('Raw daily data'!$I:$I,$A12,'Raw daily data'!$F:$F,">0")) | P12: =IF($A12="","",COUNTIFS('Raw daily data'!$I:$I,$A12,'Raw daily data'!$F:$F,"<0")) | Q12: =IF($A12="","",SUMIFS('Raw daily data'!$F:$F,'Raw daily data'!$I:$I,$A12,'Raw daily data'!$F:$F,">0")) | R12: =IF($A12="","",ABS(SUMIFS('Raw daily data'!$F:$F,'Raw daily data'!$I:$I,$A12,'Raw daily data'!$F:$F,"<0"))) | S12: =IF(N12>0,O12/N12,"") | T12: =IF(R12>0,Q12/ABS(R12),"") | U12: =IF(F12>0,H12/F12,"") | V12: =IF(H12<0,MIN(ABS(H12)/G12,1),0) | W12: =IF($A12="","",_xlfn.MAXIFS('Raw daily data'!$J:$J,'Raw daily data'!$I:$I,$A12)) | X12: =IF(W12>=0,0,ABS(W12)/G12) | Y12: =IF($A12="","",ABS(MIN(0,_xlfn.MINIFS('Raw daily data'!$J:$J,'Raw daily data'!$I:$I,$A12)))/G12)
A13: 46044 | B13: 2 | C13: =TEXT(A13,"dddd") | E13: =E12+H12 | F13: =IF($A13="","",$E13*Summary!$B$8) | G13: =IF($A13="","",F13*Summary!$B$9) | H13: =IF($A13="","",SUMIFS('Raw daily data'!$F:$F,'Raw daily data'!$I:$I,$A13)) | I13: =I12+H13 | J13: =SUMIF($B$2:$B$41,B13,$H$2:$H$41) | K13: =Summary!$B$6 | L13: =J13-K13 | N13: =IF($A13="","",COUNTIFS('Raw daily data'!$I:$I,$A13)) | O13: =IF($A13="","",COUNTIFS('Raw daily data'!$I:$I,$A13,'Raw daily data'!$F:$F,">0")) | P13: =IF($A13="","",COUNTIFS('Raw daily data'!$I:$I,$A13,'Raw daily data'!$F:$F,"<0")) | Q13: =IF($A13="","",SUMIFS('Raw daily data'!$F:$F,'Raw daily data'!$I:$I,$A13,'Raw daily data'!$F:$F,">0")) | R13: =IF($A13="","",ABS(SUMIFS('Raw daily data'!$F:$F,'Raw daily data'!$I:$I,$A13,'Raw daily data'!$F:$F,"<0"))) | S13: =IF(N13>0,O13/N13,"") | T13: =IF(R13>0,Q13/ABS(R13),"") | U13: =IF(F13>0,H13/F13,"") | V13: =IF(H13<0,MIN(ABS(H13)/G13,1),0) | W13: =IF($A13="","",_xlfn.MAXIFS('Raw daily data'!$J:$J,'Raw daily data'!$I:$I,$A13)) | X13: =IF(W13>=0,0,ABS(W13)/G13) | Y13: =IF($A13="","",ABS(MIN(0,_xlfn.MINIFS('Raw daily data'!$J:$J,'Raw daily data'!$I:$I,$A13)))/G13)
A14: 46045 | B14: 2 | C14: =TEXT(A14,"dddd") | E14: =E13+H13 | F14: =IF($A14="","",$E14*Summary!$B$8) | G14: =IF($A14="","",F14*Summary!$B$9) | H14: =IF($A14="","",SUMIFS('Raw daily data'!$F:$F,'Raw daily data'!$I:$I,$A14)) | I14: =I13+H14 | J14: =SUMIF($B$2:$B$41,B14,$H$2:$H$41) | K14: =Summary!$B$6 | L14: =J14-K14 | N14: =IF($A14="","",COUNTIFS('Raw daily data'!$I:$I,$A14)) | O14: =IF($A14="","",COUNTIFS('Raw daily data'!$I:$I,$A14,'Raw daily data'!$F:$F,">0")) | P14: =IF($A14="","",COUNTIFS('Raw daily data'!$I:$I,$A14,'Raw daily data'!$F:$F,"<0")) | Q14: =IF($A14="","",SUMIFS('Raw daily data'!$F:$F,'Raw daily data'!$I:$I,$A14,'Raw daily data'!$F:$F,">0")) | R14: =IF($A14="","",ABS(SUMIFS('Raw daily data'!$F:$F,'Raw daily data'!$I:$I,$A14,'Raw daily data'!$F:$F,"<0"))) | S14: =IF(N14>0,O14/N14,"") | T14: =IF(R14>0,Q14/ABS(R14),"") | U14: =IF(F14>0,H14/F14,"") | V14: =IF(H14<0,MIN(ABS(H14)/G14,1),0) | W14: =IF($A14="","",_xlfn.MAXIFS('Raw daily data'!$J:$J,'Raw daily data'!$I:$I,$A14)) | X14: =IF(W14>=0,0,ABS(W14)/G14) | Y14: =IF($A14="","",ABS(MIN(0,_xlfn.MINIFS('Raw daily data'!$J:$J,'Raw daily data'!$I:$I,$A14)))/G14)
A15: 46046 | B15: 2 | C15: =TEXT(A15,"dddd") | D15: N | E15: =E14+H14 | F15: =IF($A15="","",$E15*Summary!$B$8) | G15: =IF($A15="","",F15*Summary!$B$9) | H15: =IF($A15="","",SUMIFS('Raw daily data'!$F:$F,'Raw daily data'!$I:$I,$A15)) | I15: =I14+H15 | J15: =SUMIF($B$2:$B$41,B15,$H$2:$H$41) | K15: =Summary!$B$6 | L15: =J15-K15 | N15: =IF($A15="","",COUNTIFS('Raw daily data'!$I:$I,$A15)) | O15: =IF($A15="","",COUNTIFS('Raw daily data'!$I:$I,$A15,'Raw daily data'!$F:$F,">0")) | P15: =IF($A15="","",COUNTIFS('Raw daily data'!$I:$I,$A15,'Raw daily data'!$F:$F,"<0")) | Q15: =IF($A15="","",SUMIFS('Raw daily data'!$F:$F,'Raw daily data'!$I:$I,$A15,'Raw daily data'!$F:$F,">0")) | R15: =IF($A15="","",ABS(SUMIFS('Raw daily data'!$F:$F,'Raw daily data'!$I:$I,$A15,'Raw daily data'!$F:$F,"<0"))) | S15: =IF(N15>0,O15/N15,"") | T15: =IF(R15>0,Q15/ABS(R15),"") | U15: =IF(F15>0,H15/F15,"") | V15: =IF(H15<0,MIN(ABS(H15)/G15,1),0) | W15: =IF($A15="","",_xlfn.MAXIFS('Raw daily data'!$J:$J,'Raw daily data'!$I:$I,$A15)) | X15: =IF(W15>=0,0,ABS(W15)/G15) | Y15: =IF($A15="","",ABS(MIN(0,_xlfn.MINIFS('Raw daily data'!$J:$J,'Raw daily data'!$I:$I,$A15)))/G15)
A16: 46047 | B16: 3 | C16: =TEXT(A16,"dddd") | D16: N | E16: =E15+H15 | F16: =IF($A16="","",$E16*Summary!$B$8) | G16: =IF($A16="","",F16*Summary!$B$9) | H16: =IF($A16="","",SUMIFS('Raw daily data'!$F:$F,'Raw daily data'!$I:$I,$A16)) | I16: =I15+H16 | J16: =SUMIF($B$2:$B$41,B16,$H$2:$H$41) | K16: =Summary!$B$6 | L16: =J16-K16 | N16: =IF($A16="","",COUNTIFS('Raw daily data'!$I:$I,$A16)) | O16: =IF($A16="","",COUNTIFS('Raw daily data'!$I:$I,$A16,'Raw daily data'!$F:$F,">0")) | P16: =IF($A16="","",COUNTIFS('Raw daily data'!$I:$I,$A16,'Raw daily data'!$F:$F,"<0")) | Q16: =IF($A16="","",SUMIFS('Raw daily data'!$F:$F,'Raw daily data'!$I:$I,$A16,'Raw daily data'!$F:$F,">0")) | R16: =IF($A16="","",ABS(SUMIFS('Raw daily data'!$F:$F,'Raw daily data'!$I:$I,$A16,'Raw daily data'!$F:$F,"<0"))) | S16: =IF(N16>0,O16/N16,"") | T16: =IF(R16>0,Q16/ABS(R16),"") | U16: =IF(F16>0,H16/F16,"") | V16: =IF(H16<0,MIN(ABS(H16)/G16,1),0) | W16: =IF($A16="","",_xlfn.MAXIFS('Raw daily data'!$J:$J,'Raw daily data'!$I:$I,$A16)) | X16: =IF(W16>=0,0,ABS(W16)/G16) | Y16: =IF($A16="","",ABS(MIN(0,_xlfn.MINIFS('Raw daily data'!$J:$J,'Raw daily data'!$I:$I,$A16)))/G16)
A17: 46048 | B17: 3 | C17: =TEXT(A17,"dddd") | E17: =E16+H16 | F17: =IF($A17="","",$E17*Summary!$B$8) | G17: =IF($A17="","",F17*Summary!$B$9) | H17: =IF($A17="","",SUMIFS('Raw daily data'!$F:$F,'Raw daily data'!$I:$I,$A17)) | I17: =I16+H17 | J17: =SUMIF($B$2:$B$41,B17,$H$2:$H$41) | K17: =Summary!$B$6 | L17: =J17-K17 | N17: =IF($A17="","",COUNTIFS('Raw daily data'!$I:$I,$A17)) | O17: =IF($A17="","",COUNTIFS('Raw daily data'!$I:$I,$A17,'Raw daily data'!$F:$F,">0")) | P17: =IF($A17="","",COUNTIFS('Raw daily data'!$I:$I,$A17,'Raw daily data'!$F:$F,"<0")) | Q17: =IF($A17="","",SUMIFS('Raw daily data'!$F:$F,'Raw daily data'!$I:$I,$A17,'Raw daily data'!$F:$F,">0")) | R17: =IF($A17="","",ABS(SUMIFS('Raw daily data'!$F:$F,'Raw daily data'!$I:$I,$A17,'Raw daily data'!$F:$F,"<0"))) | S17: =IF(N17>0,O17/N17,"") | T17: =IF(R17>0,Q17/ABS(R17),"") | U17: =IF(F17>0,H17/F17,"") | V17: =IF(H17<0,MIN(ABS(H17)/G17,1),0) | W17: =IF($A17="","",_xlfn.MAXIFS('Raw daily data'!$J:$J,'Raw daily data'!$I:$I,$A17)) | X17: =IF(W17>=0,0,ABS(W17)/G17) | Y17: =IF($A17="","",ABS(MIN(0,_xlfn.MINIFS('Raw daily data'!$J:$J,'Raw daily data'!$I:$I,$A17)))/G17)
A18: 46049 | B18: 3 | C18: =TEXT(A18,"dddd") | E18: =E17+H17 | F18: =IF($A18="","",$E18*Summary!$B$8) | G18: =IF($A18="","",F18*Summary!$B$9) | H18: =IF($A18="","",SUMIFS('Raw daily data'!$F:$F,'Raw daily data'!$I:$I,$A18)) | I18: =I17+H18 | J18: =SUMIF($B$2:$B$41,B18,$H$2:$H$41) | K18: =Summary!$B$6 | L18: =J18-K18 | N18: =IF($A18="","",COUNTIFS('Raw daily data'!$I:$I,$A18)) | O18: =IF($A18="","",COUNTIFS('Raw daily data'!$I:$I,$A18,'Raw daily data'!$F:$F,">0")) | P18: =IF($A18="","",COUNTIFS('Raw daily data'!$I:$I,$A18,'Raw daily data'!$F:$F,"<0")) | Q18: =IF($A18="","",SUMIFS('Raw daily data'!$F:$F,'Raw daily data'!$I:$I,$A18,'Raw daily data'!$F:$F,">0")) | R18: =IF($A18="","",ABS(SUMIFS('Raw daily data'!$F:$F,'Raw daily data'!$I:$I,$A18,'Raw daily data'!$F:$F,"<0"))) | S18: =IF(N18>0,O18/N18,"") | T18: =IF(R18>0,Q18/ABS(R18),"") | U18: =IF(F18>0,H18/F18,"") | V18: =IF(H18<0,MIN(ABS(H18)/G18,1),0) | W18: =IF($A18="","",_xlfn.MAXIFS('Raw daily data'!$J:$J,'Raw daily data'!$I:$I,$A18)) | X18: =IF(W18>=0,0,ABS(W18)/G18) | Y18: =IF($A18="","",ABS(MIN(0,_xlfn.MINIFS('Raw daily data'!$J:$J,'Raw daily data'!$I:$I,$A18)))/G18)
A19: 46050 | B19: 3 | C19: =TEXT(A19,"dddd") | E19: =E18+H18 | F19: =IF($A19="","",$E19*Summary!$B$8) | G19: =IF($A19="","",F19*Summary!$B$9) | H19: =IF($A19="","",SUMIFS('Raw daily data'!$F:$F,'Raw daily data'!$I:$I,$A19)) | I19: =I18+H19 | J19: =SUMIF($B$2:$B$41,B19,$H$2:$H$41) | K19: =Summary!$B$6 | L19: =J19-K19 | N19: =IF($A19="","",COUNTIFS('Raw daily data'!$I:$I,$A19)) | O19: =IF($A19="","",COUNTIFS('Raw daily data'!$I:$I,$A19,'Raw daily data'!$F:$F,">0")) | P19: =IF($A19="","",COUNTIFS('Raw daily data'!$I:$I,$A19,'Raw daily data'!$F:$F,"<0")) | Q19: =IF($A19="","",SUMIFS('Raw daily data'!$F:$F,'Raw daily data'!$I:$I,$A19,'Raw daily data'!$F:$F,">0")) | R19: =IF($A19="","",ABS(SUMIFS('Raw daily data'!$F:$F,'Raw daily data'!$I:$I,$A19,'Raw daily data'!$F:$F,"<0"))) | S19: =IF(N19>0,O19/N19,"") | T19: =IF(R19>0,Q19/ABS(R19),"") | U19: =IF(F19>0,H19/F19,"") | V19: =IF(H19<0,MIN(ABS(H19)/G19,1),0) | W19: =IF($A19="","",_xlfn.MAXIFS('Raw daily data'!$J:$J,'Raw daily data'!$I:$I,$A19)) | X19: =IF(W19>=0,0,ABS(W19)/G19) | Y19: =IF($A19="","",ABS(MIN(0,_xlfn.MINIFS('Raw daily data'!$J:$J,'Raw daily data'!$I:$I,$A19)))/G19)
A20: 46051 | B20: 3 | C20: =TEXT(A20,"dddd") | E20: =E19+H19 | F20: =IF($A20="","",$E20*Summary!$B$8) | G20: =IF($A20="","",F20*Summary!$B$9) | H20: =IF($A20="","",SUMIFS('Raw daily data'!$F:$F,'Raw daily data'!$I:$I,$A20)) | I20: =I19+H20 | J20: =SUMIF($B$2:$B$41,B20,$H$2:$H$41) | K20: =Summary!$B$6 | L20: =J20-K20 | N20: =IF($A20="","",COUNTIFS('Raw daily data'!$I:$I,$A20)) | O20: =IF($A20="","",COUNTIFS('Raw daily data'!$I:$I,$A20,'Raw daily data'!$F:$F,">0")) | P20: =IF($A20="","",COUNTIFS('Raw daily data'!$I:$I,$A20,'Raw daily data'!$F:$F,"<0")) | Q20: =IF($A20="","",SUMIFS('Raw daily data'!$F:$F,'Raw daily data'!$I:$I,$A20,'Raw daily data'!$F:$F,">0")) | R20: =IF($A20="","",ABS(SUMIFS('Raw daily data'!$F:$F,'Raw daily data'!$I:$I,$A20,'Raw daily data'!$F:$F,"<0"))) | S20: =IF(N20>0,O20/N20,"") | T20: =IF(R20>0,Q20/ABS(R20),"") | U20: =IF(F20>0,H20/F20,"") | V20: =IF(H20<0,MIN(ABS(H20)/G20,1),0) | W20: =IF($A20="","",_xlfn.MAXIFS('Raw daily data'!$J:$J,'Raw daily data'!$I:$I,$A20)) | X20: =IF(W20>=0,0,ABS(W20)/G20) | Y20: =IF($A20="","",ABS(MIN(0,_xlfn.MINIFS('Raw daily data'!$J:$J,'Raw daily data'!$I:$I,$A20)))/G20)
A21: 46052 | B21: 3 | C21: =TEXT(A21,"dddd") | E21: =E20+H20 | F21: =IF($A21="","",$E21*Summary!$B$8) | G21: =IF($A21="","",F21*Summary!$B$9) | H21: =IF($A21="","",SUMIFS('Raw daily data'!$F:$F,'Raw daily data'!$I:$I,$A21)) | I21: =I20+H21 | J21: =SUMIF($B$2:$B$41,B21,$H$2:$H$41) | K21: =Summary!$B$6 | L21: =J21-K21 | N21: =IF($A21="","",COUNTIFS('Raw daily data'!$I:$I,$A21)) | O21: =IF($A21="","",COUNTIFS('Raw daily data'!$I:$I,$A21,'Raw daily data'!$F:$F,">0")) | P21: =IF($A21="","",COUNTIFS('Raw daily data'!$I:$I,$A21,'Raw daily data'!$F:$F,"<0")) | Q21: =IF($A21="","",SUMIFS('Raw daily data'!$F:$F,'Raw daily data'!$I:$I,$A21,'Raw daily data'!$F:$F,">0")) | R21: =IF($A21="","",ABS(SUMIFS('Raw daily data'!$F:$F,'Raw daily data'!$I:$I,$A21,'Raw daily data'!$F:$F,"<0"))) | S21: =IF(N21>0,O21/N21,"") | T21: =IF(R21>0,Q21/ABS(R21),"") | U21: =IF(F21>0,H21/F21,"") | V21: =IF(H21<0,MIN(ABS(H21)/G21,1),0) | W21: =IF($A21="","",_xlfn.MAXIFS('Raw daily data'!$J:$J,'Raw daily data'!$I:$I,$A21)) | X21: =IF(W21>=0,0,ABS(W21)/G21) | Y21: =IF($A21="","",ABS(MIN(0,_xlfn.MINIFS('Raw daily data'!$J:$J,'Raw daily data'!$I:$I,$A21)))/G21)
A22: 46053 | B22: 3 | C22: =TEXT(A22,"dddd") | D22: N | E22: =E21+H21 | F22: =IF($A22="","",$E22*Summary!$B$8) | G22: =IF($A22="","",F22*Summary!$B$9) | H22: =IF($A22="","",SUMIFS('Raw daily data'!$F:$F,'Raw daily data'!$I:$I,$A22)) | I22: =I21+H22 | J22: =SUMIF($B$2:$B$41,B22,$H$2:$H$41) | K22: =Summary!$B$6 | L22: =J22-K22 | N22: =IF($A22="","",COUNTIFS('Raw daily data'!$I:$I,$A22)) | O22: =IF($A22="","",COUNTIFS('Raw daily data'!$I:$I,$A22,'Raw daily data'!$F:$F,">0")) | P22: =IF($A22="","",COUNTIFS('Raw daily data'!$I:$I,$A22,'Raw daily data'!$F:$F,"<0")) | Q22: =IF($A22="","",SUMIFS('Raw daily data'!$F:$F,'Raw daily data'!$I:$I,$A22,'Raw daily data'!$F:$F,">0")) | R22: =IF($A22="","",ABS(SUMIFS('Raw daily data'!$F:$F,'Raw daily data'!$I:$I,$A22,'Raw daily data'!$F:$F,"<0"))) | S22: =IF(N22>0,O22/N22,"") | T22: =IF(R22>0,Q22/ABS(R22),"") | U22: =IF(F22>0,H22/F22,"") | V22: =IF(H22<0,MIN(ABS(H22)/G22,1),0) | W22: =IF($A22="","",_xlfn.MAXIFS('Raw daily data'!$J:$J,'Raw daily data'!$I:$I,$A22)) | X22: =IF(W22>=0,0,ABS(W22)/G22) | Y22: =IF($A22="","",ABS(MIN(0,_xlfn.MINIFS('Raw daily data'!$J:$J,'Raw daily data'!$I:$I,$A22)))/G22)
A23: 46054 | B23: 4 | C23: =TEXT(A23,"dddd") | D23: N | E23: =E22+H22 | F23: =IF($A23="","",$E23*Summary!$B$8) | G23: =IF($A23="","",F23*Summary!$B$9) | H23: =IF($A23="","",SUMIFS('Raw daily data'!$F:$F,'Raw daily data'!$I:$I,$A23)) | I23: =I22+H23 | J23: =SUMIF($B$2:$B$41,B23,$H$2:$H$41) | K23: =Summary!$B$6 | L23: =J23-K23 | N23: =IF($A23="","",COUNTIFS('Raw daily data'!$I:$I,$A23)) | O23: =IF($A23="","",COUNTIFS('Raw daily data'!$I:$I,$A23,'Raw daily data'!$F:$F,">0")) | P23: =IF($A23="","",COUNTIFS('Raw daily data'!$I:$I,$A23,'Raw daily data'!$F:$F,"<0")) | Q23: =IF($A23="","",SUMIFS('Raw daily data'!$F:$F,'Raw daily data'!$I:$I,$A23,'Raw daily data'!$F:$F,">0")) | R23: =IF($A23="","",ABS(SUMIFS('Raw daily data'!$F:$F,'Raw daily data'!$I:$I,$A23,'Raw daily data'!$F:$F,"<0"))) | S23: =IF(N23>0,O23/N23,"") | T23: =IF(R23>0,Q23/ABS(R23),"") | U23: =IF(F23>0,H23/F23,"") | V23: =IF(H23<0,MIN(ABS(H23)/G23,1),0) | W23: =IF($A23="","",_xlfn.MAXIFS('Raw daily data'!$J:$J,'Raw daily data'!$I:$I,$A23)) | X23: =IF(W23>=0,0,ABS(W23)/G23) | Y23: =IF($A23="","",ABS(MIN(0,_xlfn.MINIFS('Raw daily data'!$J:$J,'Raw daily data'!$I:$I,$A23)))/G23)
A24: 46055 | B24: 4 | C24: =TEXT(A24,"dddd") | F24: =IF($A24="","",$E24*Summary!$B$8) | G24: =IF($A24="","",F24*Summary!$B$9) | H24: =IF($A24="","",SUMIFS('Raw daily data'!$F:$F,'Raw daily data'!$I:$I,$A24)) | I24: =I23+H24 | J24: =SUMIF($B$2:$B$41,B24,$H$2:$H$41) | K24: =Summary!$B$6 | L24: =J24-K24 | N24: =IF($A24="","",COUNTIFS('Raw daily data'!$I:$I,$A24)) | O24: =IF($A24="","",COUNTIFS('Raw daily data'!$I:$I,$A24,'Raw daily data'!$F:$F,">0")) | P24: =IF($A24="","",COUNTIFS('Raw daily data'!$I:$I,$A24,'Raw daily data'!$F:$F,"<0")) | Q24: =IF($A24="","",SUMIFS('Raw daily data'!$F:$F,'Raw daily data'!$I:$I,$A24,'Raw daily data'!$F:$F,">0")) | R24: =IF($A24="","",ABS(SUMIFS('Raw daily data'!$F:$F,'Raw daily data'!$I:$I,$A24,'Raw daily data'!$F:$F,"<0"))) | S24: =IF(N24>0,O24/N24,"") | T24: =IF(R24>0,Q24/ABS(R24),"") | U24: =IF(F24>0,H24/F24,"") | V24: =IF(H24<0,MIN(ABS(H24)/G24,1),0) | W24: =IF($A24="","",_xlfn.MAXIFS('Raw daily data'!$J:$J,'Raw daily data'!$I:$I,$A24)) | X24: =IF(W24>=0,0,ABS(W24)/G24) | Y24: =IFERROR(IF($A24="","",ABS(MIN(0,_xlfn.MINIFS('Raw daily data'!$J:$J,'Raw daily data'!$I:$I,$A24)))/G24),"")
A25: 46056 | B25: 4 | C25: =TEXT(A25,"dddd") | F25: =IF($A25="","",$E25*Summary!$B$8) | G25: =IF($A25="","",F25*Summary!$B$9) | H25: =IF($A25="","",SUMIFS('Raw daily data'!$F:$F,'Raw daily data'!$I:$I,$A25)) | I25: =I24+H25 | J25: =SUMIF($B$2:$B$41,B25,$H$2:$H$41) | K25: =Summary!$B$6 | L25: =J25-K25 | N25: =IF($A25="","",COUNTIFS('Raw daily data'!$I:$I,$A25)) | O25: =IF($A25="","",COUNTIFS('Raw daily data'!$I:$I,$A25,'Raw daily data'!$F:$F,">0")) | P25: =IF($A25="","",COUNTIFS('Raw daily data'!$I:$I,$A25,'Raw daily data'!$F:$F,"<0")) | Q25: =IF($A25="","",SUMIFS('Raw daily data'!$F:$F,'Raw daily data'!$I:$I,$A25,'Raw daily data'!$F:$F,">0")) | R25: =IF($A25="","",ABS(SUMIFS('Raw daily data'!$F:$F,'Raw daily data'!$I:$I,$A25,'Raw daily data'!$F:$F,"<0"))) | S25: =IF(N25>0,O25/N25,"") | T25: =IF(R25>0,Q25/ABS(R25),"") | U25: =IF(F25>0,H25/F25,"") | V25: =IF(H25<0,MIN(ABS(H25)/G25,1),0) | W25: =IF($A25="","",_xlfn.MAXIFS('Raw daily data'!$J:$J,'Raw daily data'!$I:$I,$A25)) | X25: =IF(W25>=0,0,ABS(W25)/G25) | Y25: =IFERROR(IF($A25="","",ABS(MIN(0,_xlfn.MINIFS('Raw daily data'!$J:$J,'Raw daily data'!$I:$I,$A25)))/G25),"")
A26: 46057 | B26: 4 | C26: =TEXT(A26,"dddd") | F26: =IF($A26="","",$E26*Summary!$B$8) | G26: =IF($A26="","",F26*Summary!$B$9) | H26: =IF($A26="","",SUMIFS('Raw daily data'!$F:$F,'Raw daily data'!$I:$I,$A26)) | I26: =I25+H26 | J26: =SUMIF($B$2:$B$41,B26,$H$2:$H$41) | K26: =Summary!$B$6 | L26: =J26-K26 | N26: =IF($A26="","",COUNTIFS('Raw daily data'!$I:$I,$A26)) | O26: =IF($A26="","",COUNTIFS('Raw daily data'!$I:$I,$A26,'Raw daily data'!$F:$F,">0")) | P26: =IF($A26="","",COUNTIFS('Raw daily data'!$I:$I,$A26,'Raw daily data'!$F:$F,"<0")) | Q26: =IF($A26="","",SUMIFS('Raw daily data'!$F:$F,'Raw daily data'!$I:$I,$A26,'Raw daily data'!$F:$F,">0")) | R26: =IF($A26="","",ABS(SUMIFS('Raw daily data'!$F:$F,'Raw daily data'!$I:$I,$A26,'Raw daily data'!$F:$F,"<0"))) | S26: =IF(N26>0,O26/N26,"") | T26: =IF(R26>0,Q26/ABS(R26),"") | U26: =IF(F26>0,H26/F26,"") | V26: =IF(H26<0,MIN(ABS(H26)/G26,1),0) | W26: =IF($A26="","",_xlfn.MAXIFS('Raw daily data'!$J:$J,'Raw daily data'!$I:$I,$A26)) | X26: =IF(W26>=0,0,ABS(W26)/G26) | Y26: =IFERROR(IF($A26="","",ABS(MIN(0,_xlfn.MINIFS('Raw daily data'!$J:$J,'Raw daily data'!$I:$I,$A26)))/G26),"")
A27: 46058 | B27: 4 | C27: =TEXT(A27,"dddd") | F27: =IF($A27="","",$E27*Summary!$B$8) | G27: =IF($A27="","",F27*Summary!$B$9) | H27: =IF($A27="","",SUMIFS('Raw daily data'!$F:$F,'Raw daily data'!$I:$I,$A27)) | I27: =I26+H27 | J27: =SUMIF($B$2:$B$41,B27,$H$2:$H$41) | K27: =Summary!$B$6 | L27: =J27-K27 | N27: =IF($A27="","",COUNTIFS('Raw daily data'!$I:$I,$A27)) | O27: =IF($A27="","",COUNTIFS('Raw daily data'!$I:$I,$A27,'Raw daily data'!$F:$F,">0")) | P27: =IF($A27="","",COUNTIFS('Raw daily data'!$I:$I,$A27,'Raw daily data'!$F:$F,"<0")) | Q27: =IF($A27="","",SUMIFS('Raw daily data'!$F:$F,'Raw daily data'!$I:$I,$A27,'Raw daily data'!$F:$F,">0")) | R27: =IF($A27="","",ABS(SUMIFS('Raw daily data'!$F:$F,'Raw daily data'!$I:$I,$A27,'Raw daily data'!$F:$F,"<0"))) | S27: =IF(N27>0,O27/N27,"") | T27: =IF(R27>0,Q27/ABS(R27),"") | U27: =IF(F27>0,H27/F27,"") | V27: =IF(H27<0,MIN(ABS(H27)/G27,1),0) | W27: =IF($A27="","",_xlfn.MAXIFS('Raw daily data'!$J:$J,'Raw daily data'!$I:$I,$A27)) | X27: =IF(W27>=0,0,ABS(W27)/G27) | Y27: =IFERROR(IF($A27="","",ABS(MIN(0,_xlfn.MINIFS('Raw daily data'!$J:$J,'Raw daily data'!$I:$I,$A27)))/G27),"")
A28: 46059 | B28: 4 | C28: =TEXT(A28,"dddd") | F28: =IF($A28="","",$E28*Summary!$B$8) | G28: =IF($A28="","",F28*Summary!$B$9) | H28: =IF($A28="","",SUMIFS('Raw daily data'!$F:$F,'Raw daily data'!$I:$I,$A28)) | I28: =I27+H28 | J28: =SUMIF($B$2:$B$41,B28,$H$2:$H$41) | K28: =Summary!$B$6 | L28: =J28-K28 | N28: =IF($A28="","",COUNTIFS('Raw daily data'!$I:$I,$A28)) | O28: =IF($A28="","",COUNTIFS('Raw daily data'!$I:$I,$A28,'Raw daily data'!$F:$F,">0")) | P28: =IF($A28="","",COUNTIFS('Raw daily data'!$I:$I,$A28,'Raw daily data'!$F:$F,"<0")) | Q28: =IF($A28="","",SUMIFS('Raw daily data'!$F:$F,'Raw daily data'!$I:$I,$A28,'Raw daily data'!$F:$F,">0")) | R28: =IF($A28="","",ABS(SUMIFS('Raw daily data'!$F:$F,'Raw daily data'!$I:$I,$A28,'Raw daily data'!$F:$F,"<0"))) | S28: =IF(N28>0,O28/N28,"") | T28: =IF(R28>0,Q28/ABS(R28),"") | U28: =IF(F28>0,H28/F28,"") | V28: =IF(H28<0,MIN(ABS(H28)/G28,1),0) | W28: =IF($A28="","",_xlfn.MAXIFS('Raw daily data'!$J:$J,'Raw daily data'!$I:$I,$A28)) | X28: =IF(W28>=0,0,ABS(W28)/G28) | Y28: =IFERROR(IF($A28="","",ABS(MIN(0,_xlfn.MINIFS('Raw daily data'!$J:$J,'Raw daily data'!$I:$I,$A28)))/G28),"")
A29: 46060 | B29: 4 | C29: =TEXT(A29,"dddd") | D29: N | F29: =IF($A29="","",$E29*Summary!$B$8) | G29: =IF($A29="","",F29*Summary!$B$9) | H29: =IF($A29="","",SUMIFS('Raw daily data'!$F:$F,'Raw daily data'!$I:$I,$A29)) | I29: =I28+H29 | J29: =SUMIF($B$2:$B$41,B29,$H$2:$H$41) | K29: =Summary!$B$6 | L29: =J29-K29 | N29: =IF($A29="","",COUNTIFS('Raw daily data'!$I:$I,$A29)) | O29: =IF($A29="","",COUNTIFS('Raw daily data'!$I:$I,$A29,'Raw daily data'!$F:$F,">0")) | P29: =IF($A29="","",COUNTIFS('Raw daily data'!$I:$I,$A29,'Raw daily data'!$F:$F,"<0")) | Q29: =IF($A29="","",SUMIFS('Raw daily data'!$F:$F,'Raw daily data'!$I:$I,$A29,'Raw daily data'!$F:$F,">0")) | R29: =IF($A29="","",ABS(SUMIFS('Raw daily data'!$F:$F,'Raw daily data'!$I:$I,$A29,'Raw daily data'!$F:$F,"<0"))) | S29: =IF(N29>0,O29/N29,"") | T29: =IF(R29>0,Q29/ABS(R29),"") | U29: =IF(F29>0,H29/F29,"") | V29: =IF(H29<0,MIN(ABS(H29)/G29,1),0) | W29: =IF($A29="","",_xlfn.MAXIFS('Raw daily data'!$J:$J,'Raw daily data'!$I:$I,$A29)) | X29: =IF(W29>=0,0,ABS(W29)/G29) | Y29: =IFERROR(IF($A29="","",ABS(MIN(0,_xlfn.MINIFS('Raw daily data'!$J:$J,'Raw daily data'!$I:$I,$A29)))/G29),"")
A30: 46061 | B30: 4 | C30: =TEXT(A30,"dddd") | D30: N | F30: =IF($A30="","",$E30*Summary!$B$8) | G30: =IF($A30="","",F30*Summary!$B$9) | H30: =IF($A30="","",SUMIFS('Raw daily data'!$F:$F,'Raw daily data'!$I:$I,$A30)) | I30: =I29+H30 | J30: =SUMIF($B$2:$B$41,B30,$H$2:$H$41) | K30: =Summary!$B$6 | L30: =J30-K30 | N30: =IF($A30="","",COUNTIFS('Raw daily data'!$I:$I,$A30)) | O30: =IF($A30="","",COUNTIFS('Raw daily data'!$I:$I,$A30,'Raw daily data'!$F:$F,">0")) | P30: =IF($A30="","",COUNTIFS('Raw daily data'!$I:$I,$A30,'Raw daily data'!$F:$F,"<0")) | Q30: =IF($A30="","",SUMIFS('Raw daily data'!$F:$F,'Raw daily data'!$I:$I,$A30,'Raw daily data'!$F:$F,">0")) | R30: =IF($A30="","",ABS(SUMIFS('Raw daily data'!$F:$F,'Raw daily data'!$I:$I,$A30,'Raw daily data'!$F:$F,"<0"))) | S30: =IF(N30>0,O30/N30,"") | T30: =IF(R30>0,Q30/ABS(R30),"") | U30: =IF(F30>0,H30/F30,"") | V30: =IF(H30<0,MIN(ABS(H30)/G30,1),0) | W30: =IF($A30="","",_xlfn.MAXIFS('Raw daily data'!$J:$J,'Raw daily data'!$I:$I,$A30)) | X30: =IF(W30>=0,0,ABS(W30)/G30) | Y30: =IFERROR(IF($A30="","",ABS(MIN(0,_xlfn.MINIFS('Raw daily data'!$J:$J,'Raw daily data'!$I:$I,$A30)))/G30),"")
A31: 46062 | C31: =TEXT(A31,"dddd") | F31: =IF($A31="","",$E31*Summary!$B$8) | G31: =IF($A31="","",F31*Summary!$B$9) | H31: =IF($A31="","",SUMIFS('Raw daily data'!$F:$F,'Raw daily data'!$I:$I,$A31)) | I31: =I30+H31 | J31: =SUMIF($B$2:$B$41,B31,$H$2:$H$41) | K31: =Summary!$B$6 | L31: =J31-K31 | N31: =IF($A31="","",COUNTIFS('Raw daily data'!$I:$I,$A31)) | O31: =IF($A31="","",COUNTIFS('Raw daily data'!$I:$I,$A31,'Raw daily data'!$F:$F,">0")) | P31: =IF($A31="","",COUNTIFS('Raw daily data'!$I:$I,$A31,'Raw daily data'!$F:$F,"<0")) | Q31: =IF($A31="","",SUMIFS('Raw daily data'!$F:$F,'Raw daily data'!$I:$I,$A31,'Raw daily data'!$F:$F,">0")) | R31: =IF($A31="","",ABS(SUMIFS('Raw daily data'!$F:$F,'Raw daily data'!$I:$I,$A31,'Raw daily data'!$F:$F,"<0"))) | S31: =IF(N31>0,O31/N31,"") | T31: =IF(R31>0,Q31/ABS(R31),"") | U31: =IF(F31>0,H31/F31,"") | V31: =IF(H31<0,MIN(ABS(H31)/G31,1),0) | W31: =IF($A31="","",_xlfn.MAXIFS('Raw daily data'!$J:$J,'Raw daily data'!$I:$I,$A31)) | X31: =IF(W31>=0,0,ABS(W31)/G31) | Y31: =IFERROR(IF($A31="","",ABS(MIN(0,_xlfn.MINIFS('Raw daily data'!$J:$J,'Raw daily data'!$I:$I,$A31)))/G31),"")
A32: 46063 | C32: =TEXT(A32,"dddd") | F32: =IF($A32="","",$E32*Summary!$B$8) | G32: =IF($A32="","",F32*Summary!$B$9) | H32: =IF($A32="","",SUMIFS('Raw daily data'!$F:$F,'Raw daily data'!$I:$I,$A32)) | I32: =I31+H32 | J32: =SUMIF($B$2:$B$41,B32,$H$2:$H$41) | K32: =Summary!$B$6 | L32: =J32-K32 | N32: =IF($A32="","",COUNTIFS('Raw daily data'!$I:$I,$A32)) | O32: =IF($A32="","",COUNTIFS('Raw daily data'!$I:$I,$A32,'Raw daily data'!$F:$F,">0")) | P32: =IF($A32="","",COUNTIFS('Raw daily data'!$I:$I,$A32,'Raw daily data'!$F:$F,"<0")) | Q32: =IF($A32="","",SUMIFS('Raw daily data'!$F:$F,'Raw daily data'!$I:$I,$A32,'Raw daily data'!$F:$F,">0")) | R32: =IF($A32="","",ABS(SUMIFS('Raw daily data'!$F:$F,'Raw daily data'!$I:$I,$A32,'Raw daily data'!$F:$F,"<0"))) | S32: =IF(N32>0,O32/N32,"") | T32: =IF(R32>0,Q32/ABS(R32),"") | U32: =IF(F32>0,H32/F32,"") | V32: =IF(H32<0,MIN(ABS(H32)/G32,1),0) | W32: =IF($A32="","",_xlfn.MAXIFS('Raw daily data'!$J:$J,'Raw daily data'!$I:$I,$A32)) | X32: =IF(W32>=0,0,ABS(W32)/G32) | Y32: =IFERROR(IF($A32="","",ABS(MIN(0,_xlfn.MINIFS('Raw daily data'!$J:$J,'Raw daily data'!$I:$I,$A32)))/G32),"")
A33: 46064 | C33: =TEXT(A33,"dddd") | F33: =IF($A33="","",$E33*Summary!$B$8) | G33: =IF($A33="","",F33*Summary!$B$9) | H33: =IF($A33="","",SUMIFS('Raw daily data'!$F:$F,'Raw daily data'!$I:$I,$A33)) | I33: =I32+H33 | J33: =SUMIF($B$2:$B$41,B33,$H$2:$H$41) | K33: =Summary!$B$6 | L33: =J33-K33 | N33: =IF($A33="","",COUNTIFS('Raw daily data'!$I:$I,$A33)) | O33: =IF($A33="","",COUNTIFS('Raw daily data'!$I:$I,$A33,'Raw daily data'!$F:$F,">0")) | P33: =IF($A33="","",COUNTIFS('Raw daily data'!$I:$I,$A33,'Raw daily data'!$F:$F,"<0")) | Q33: =IF($A33="","",SUMIFS('Raw daily data'!$F:$F,'Raw daily data'!$I:$I,$A33,'Raw daily data'!$F:$F,">0")) | R33: =IF($A33="","",ABS(SUMIFS('Raw daily data'!$F:$F,'Raw daily data'!$I:$I,$A33,'Raw daily data'!$F:$F,"<0"))) | S33: =IF(N33>0,O33/N33,"") | T33: =IF(R33>0,Q33/ABS(R33),"") | U33: =IF(F33>0,H33/F33,"") | V33: =IF(H33<0,MIN(ABS(H33)/G33,1),0) | W33: =IF($A33="","",_xlfn.MAXIFS('Raw daily data'!$J:$J,'Raw daily data'!$I:$I,$A33)) | X33: =IF(W33>=0,0,ABS(W33)/G33) | Y33: =IFERROR(IF($A33="","",ABS(MIN(0,_xlfn.MINIFS('Raw daily data'!$J:$J,'Raw daily data'!$I:$I,$A33)))/G33),"")
A34: 46065 | C34: =TEXT(A34,"dddd") | F34: =IF($A34="","",$E34*Summary!$B$8) | G34: =IF($A34="","",F34*Summary!$B$9) | H34: =IF($A34="","",SUMIFS('Raw daily data'!$F:$F,'Raw daily data'!$I:$I,$A34)) | I34: =I33+H34 | J34: =SUMIF($B$2:$B$41,B34,$H$2:$H$41) | K34: =Summary!$B$6 | L34: =J34-K34 | N34: =IF($A34="","",COUNTIFS('Raw daily data'!$I:$I,$A34)) | O34: =IF($A34="","",COUNTIFS('Raw daily data'!$I:$I,$A34,'Raw daily data'!$F:$F,">0")) | P34: =IF($A34="","",COUNTIFS('Raw daily data'!$I:$I,$A34,'Raw daily data'!$F:$F,"<0")) | Q34: =IF($A34="","",SUMIFS('Raw daily data'!$F:$F,'Raw daily data'!$I:$I,$A34,'Raw daily data'!$F:$F,">0")) | R34: =IF($A34="","",ABS(SUMIFS('Raw daily data'!$F:$F,'Raw daily data'!$I:$I,$A34,'Raw daily data'!$F:$F,"<0"))) | S34: =IF(N34>0,O34/N34,"") | T34: =IF(R34>0,Q34/ABS(R34),"") | U34: =IF(F34>0,H34/F34,"") | V34: =IF(H34<0,MIN(ABS(H34)/G34,1),0) | W34: =IF($A34="","",_xlfn.MAXIFS('Raw daily data'!$J:$J,'Raw daily data'!$I:$I,$A34)) | X34: =IF(W34>=0,0,ABS(W34)/G34) | Y34: =IFERROR(IF($A34="","",ABS(MIN(0,_xlfn.MINIFS('Raw daily data'!$J:$J,'Raw daily data'!$I:$I,$A34)))/G34),"")
A35: 46066 | C35: =TEXT(A35,"dddd") | F35: =IF($A35="","",$E35*Summary!$B$8) | G35: =IF($A35="","",F35*Summary!$B$9) | H35: =IF($A35="","",SUMIFS('Raw daily data'!$F:$F,'Raw daily data'!$I:$I,$A35)) | I35: =I34+H35 | J35: =SUMIF($B$2:$B$41,B35,$H$2:$H$41) | K35: =Summary!$B$6 | L35: =J35-K35 | N35: =IF($A35="","",COUNTIFS('Raw daily data'!$I:$I,$A35)) | O35: =IF($A35="","",COUNTIFS('Raw daily data'!$I:$I,$A35,'Raw daily data'!$F:$F,">0")) | P35: =IF($A35="","",COUNTIFS('Raw daily data'!$I:$I,$A35,'Raw daily data'!$F:$F,"<0")) | Q35: =IF($A35="","",SUMIFS('Raw daily data'!$F:$F,'Raw daily data'!$I:$I,$A35,'Raw daily data'!$F:$F,">0")) | R35: =IF($A35="","",ABS(SUMIFS('Raw daily data'!$F:$F,'Raw daily data'!$I:$I,$A35,'Raw daily data'!$F:$F,"<0"))) | S35: =IF(N35>0,O35/N35,"") | T35: =IF(R35>0,Q35/ABS(R35),"") | U35: =IF(F35>0,H35/F35,"") | V35: =IF(H35<0,MIN(ABS(H35)/G35,1),0) | W35: =IF($A35="","",_xlfn.MAXIFS('Raw daily data'!$J:$J,'Raw daily data'!$I:$I,$A35)) | X35: =IF(W35>=0,0,ABS(W35)/G35) | Y35: =IFERROR(IF($A35="","",ABS(MIN(0,_xlfn.MINIFS('Raw daily data'!$J:$J,'Raw daily data'!$I:$I,$A35)))/G35),"")
A36: 46067 | C36: =TEXT(A36,"dddd") | F36: =IF($A36="","",$E36*Summary!$B$8) | G36: =IF($A36="","",F36*Summary!$B$9) | H36: =IF($A36="","",SUMIFS('Raw daily data'!$F:$F,'Raw daily data'!$I:$I,$A36)) | I36: =I35+H36 | J36: =SUMIF($B$2:$B$41,B36,$H$2:$H$41) | K36: =Summary!$B$6 | L36: =J36-K36 | N36: =IF($A36="","",COUNTIFS('Raw daily data'!$I:$I,$A36)) | O36: =IF($A36="","",COUNTIFS('Raw daily data'!$I:$I,$A36,'Raw daily data'!$F:$F,">0")) | P36: =IF($A36="","",COUNTIFS('Raw daily data'!$I:$I,$A36,'Raw daily data'!$F:$F,"<0")) | Q36: =IF($A36="","",SUMIFS('Raw daily data'!$F:$F,'Raw daily data'!$I:$I,$A36,'Raw daily data'!$F:$F,">0")) | R36: =IF($A36="","",ABS(SUMIFS('Raw daily data'!$F:$F,'Raw daily data'!$I:$I,$A36,'Raw daily data'!$F:$F,"<0"))) | S36: =IF(N36>0,O36/N36,"") | T36: =IF(R36>0,Q36/ABS(R36),"") | U36: =IF(F36>0,H36/F36,"") | V36: =IF(H36<0,MIN(ABS(H36)/G36,1),0) | W36: =IF($A36="","",_xlfn.MAXIFS('Raw daily data'!$J:$J,'Raw daily data'!$I:$I,$A36)) | X36: =IF(W36>=0,0,ABS(W36)/G36) | Y36: =IFERROR(IF($A36="","",ABS(MIN(0,_xlfn.MINIFS('Raw daily data'!$J:$J,'Raw daily data'!$I:$I,$A36)))/G36),"")
A37: 46068 | C37: =TEXT(A37,"dddd") | F37: =IF($A37="","",$E37*Summary!$B$8) | G37: =IF($A37="","",F37*Summary!$B$9) | H37: =IF($A37="","",SUMIFS('Raw daily data'!$F:$F,'Raw daily data'!$I:$I,$A37)) | I37: =I36+H37 | J37: =SUMIF($B$2:$B$41,B37,$H$2:$H$41) | K37: =Summary!$B$6 | L37: =J37-K37 | N37: =IF($A37="","",COUNTIFS('Raw daily data'!$I:$I,$A37)) | O37: =IF($A37="","",COUNTIFS('Raw daily data'!$I:$I,$A37,'Raw daily data'!$F:$F,">0")) | P37: =IF($A37="","",COUNTIFS('Raw daily data'!$I:$I,$A37,'Raw daily data'!$F:$F,"<0")) | Q37: =IF($A37="","",SUMIFS('Raw daily data'!$F:$F,'Raw daily data'!$I:$I,$A37,'Raw daily data'!$F:$F,">0")) | R37: =IF($A37="","",ABS(SUMIFS('Raw daily data'!$F:$F,'Raw daily data'!$I:$I,$A37,'Raw daily data'!$F:$F,"<0"))) | S37: =IF(N37>0,O37/N37,"") | T37: =IF(R37>0,Q37/ABS(R37),"") | U37: =IF(F37>0,H37/F37,"") | V37: =IF(H37<0,MIN(ABS(H37)/G37,1),0) | W37: =IF($A37="","",_xlfn.MAXIFS('Raw daily data'!$J:$J,'Raw daily data'!$I:$I,$A37)) | X37: =IF(W37>=0,0,ABS(W37)/G37) | Y37: =IFERROR(IF($A37="","",ABS(MIN(0,_xlfn.MINIFS('Raw daily data'!$J:$J,'Raw daily data'!$I:$I,$A37)))/G37),"")
A38: 46069 | C38: =TEXT(A38,"dddd") | F38: =IF($A38="","",$E38*Summary!$B$8) | G38: =IF($A38="","",F38*Summary!$B$9) | H38: =IF($A38="","",SUMIFS('Raw daily data'!$F:$F,'Raw daily data'!$I:$I,$A38)) | I38: =I37+H38 | J38: =SUMIF($B$2:$B$41,B38,$H$2:$H$41) | K38: =Summary!$B$6 | L38: =J38-K38 | N38: =IF($A38="","",COUNTIFS('Raw daily data'!$I:$I,$A38)) | O38: =IF($A38="","",COUNTIFS('Raw daily data'!$I:$I,$A38,'Raw daily data'!$F:$F,">0")) | P38: =IF($A38="","",COUNTIFS('Raw daily data'!$I:$I,$A38,'Raw daily data'!$F:$F,"<0")) | Q38: =IF($A38="","",SUMIFS('Raw daily data'!$F:$F,'Raw daily data'!$I:$I,$A38,'Raw daily data'!$F:$F,">0")) | R38: =IF($A38="","",ABS(SUMIFS('Raw daily data'!$F:$F,'Raw daily data'!$I:$I,$A38,'Raw daily data'!$F:$F,"<0"))) | S38: =IF(N38>0,O38/N38,"") | T38: =IF(R38>0,Q38/ABS(R38),"") | U38: =IF(F38>0,H38/F38,"") | V38: =IF(H38<0,MIN(ABS(H38)/G38,1),0) | W38: =IF($A38="","",_xlfn.MAXIFS('Raw daily data'!$J:$J,'Raw daily data'!$I:$I,$A38)) | X38: =IF(W38>=0,0,ABS(W38)/G38) | Y38: =IFERROR(IF($A38="","",ABS(MIN(0,_xlfn.MINIFS('Raw daily data'!$J:$J,'Raw daily data'!$I:$I,$A38)))/G38),"")
A39: 46070 | C39: =TEXT(A39,"dddd") | F39: =IF($A39="","",$E39*Summary!$B$8) | G39: =IF($A39="","",F39*Summary!$B$9) | H39: =IF($A39="","",SUMIFS('Raw daily data'!$F:$F,'Raw daily data'!$I:$I,$A39)) | I39: =I38+H39 | J39: =SUMIF($B$2:$B$41,B39,$H$2:$H$41) | K39: =Summary!$B$6 | L39: =J39-K39 | N39: =IF($A39="","",COUNTIFS('Raw daily data'!$I:$I,$A39)) | O39: =IF($A39="","",COUNTIFS('Raw daily data'!$I:$I,$A39,'Raw daily data'!$F:$F,">0")) | P39: =IF($A39="","",COUNTIFS('Raw daily data'!$I:$I,$A39,'Raw daily data'!$F:$F,"<0")) | Q39: =IF($A39="","",SUMIFS('Raw daily data'!$F:$F,'Raw daily data'!$I:$I,$A39,'Raw daily data'!$F:$F,">0")) | R39: =IF($A39="","",ABS(SUMIFS('Raw daily data'!$F:$F,'Raw daily data'!$I:$I,$A39,'Raw daily data'!$F:$F,"<0"))) | S39: =IF(N39>0,O39/N39,"") | T39: =IF(R39>0,Q39/ABS(R39),"") | U39: =IF(F39>0,H39/F39,"") | V39: =IF(H39<0,MIN(ABS(H39)/G39,1),0) | W39: =IF($A39="","",_xlfn.MAXIFS('Raw daily data'!$J:$J,'Raw daily data'!$I:$I,$A39)) | X39: =IF(W39>=0,0,ABS(W39)/G39) | Y39: =IFERROR(IF($A39="","",ABS(MIN(0,_xlfn.MINIFS('Raw daily data'!$J:$J,'Raw daily data'!$I:$I,$A39)))/G39),"")
A40: 46071 | C40: =TEXT(A40,"dddd") | F40: =IF($A40="","",$E40*Summary!$B$8) | G40: =IF($A40="","",F40*Summary!$B$9) | H40: =IF($A40="","",SUMIFS('Raw daily data'!$F:$F,'Raw daily data'!$I:$I,$A40)) | I40: =I39+H40 | J40: =SUMIF($B$2:$B$41,B40,$H$2:$H$41) | K40: =Summary!$B$6 | L40: =J40-K40 | N40: =IF($A40="","",COUNTIFS('Raw daily data'!$I:$I,$A40)) | O40: =IF($A40="","",COUNTIFS('Raw daily data'!$I:$I,$A40,'Raw daily data'!$F:$F,">0")) | P40: =IF($A40="","",COUNTIFS('Raw daily data'!$I:$I,$A40,'Raw daily data'!$F:$F,"<0")) | Q40: =IF($A40="","",SUMIFS('Raw daily data'!$F:$F,'Raw daily data'!$I:$I,$A40,'Raw daily data'!$F:$F,">0")) | R40: =IF($A40="","",ABS(SUMIFS('Raw daily data'!$F:$F,'Raw daily data'!$I:$I,$A40,'Raw daily data'!$F:$F,"<0"))) | S40: =IF(N40>0,O40/N40,"") | T40: =IF(R40>0,Q40/ABS(R40),"") | U40: =IF(F40>0,H40/F40,"") | V40: =IF(H40<0,MIN(ABS(H40)/G40,1),0) | W40: =IF($A40="","",_xlfn.MAXIFS('Raw daily data'!$J:$J,'Raw daily data'!$I:$I,$A40)) | X40: =IF(W40>=0,0,ABS(W40)/G40) | Y40: =IFERROR(IF($A40="","",ABS(MIN(0,_xlfn.MINIFS('Raw daily data'!$J:$J,'Raw daily data'!$I:$I,$A40)))/G40),"")
...

Sheet Raw daily data
A1: Symbol | B1: Name | C1: Side | D1: Quantity | E1: Price | F1: Profit | G1: Deal ID | H1: Time | I1: Trade Date | J1: Cumulative P&L for the day
A2: EURUSD | B2: EUR_USD | C2: sell | D2: 200000 | E2: 1.15899 | F2: -60 | G2: 12607 | H2: Wed, 11 Jan 2026 12:06:06 GMT | I2: =IF(H2="","",DATEVALUE(MID(H2,6,11))) | J2: =IF(F2="","",F2+IF(I2=I1,J1,0))
A3: EURUSD | B3: EUR_USD | C3: sell | D3: 500002 | E3: 1.15829 | F3: 575.0023 | G3: 12594 | H3: Wed, 12 Jan 2026 12:06:06 GMT | I3: =IF(H3="","",DATEVALUE(MID(H3,6,11))) | J3: =IF(F3="","",F3+IF(I3=I2,J2,0))
I4: =IF(H4="","",DATEVALUE(MID(H4,6,11))) | J4: =IF(F4="","",F4+IF(I4=I3,J3,0))
I5: =IF(H5="","",DATEVALUE(MID(H5,6,11))) | J5: =IF(F5="","",F5+IF(I5=I4,J4,0))
I6: =IF(H6="","",DATEVALUE(MID(H6,6,11))) | J6: =IF(F6="","",F6+IF(I6=I5,J5,0))
I7: =IF(H7="","",DATEVALUE(MID(H7,6,11))) | J7: =IF(F7="","",F7+IF(I7=I6,J6,0))
I8: =IF(H8="","",DATEVALUE(MID(H8,6,11))) | J8: =IF(F8="","",F8+IF(I8=I7,J7,0))
I9: =IF(H9="","",DATEVALUE(MID(H9,6,11))) | J9: =IF(F9="","",F9+IF(I9=I8,J8,0))
I10: =IF(H10="","",DATEVALUE(MID(H10,6,11))) | J10: =IF(F10="","",F10+IF(I10=I9,J9,0))
I11: =IF(H11="","",DATEVALUE(MID(H11,6,11))) | J11: =IF(F11="","",F11+IF(I11=I10,J10,0))
I12: =IF(H12="","",DATEVALUE(MID(H12,6,11))) | J12: =IF(F12="","",F12+IF(I12=I11,J11,0))
I13: =IF(H13="","",DATEVALUE(MID(H13,6,11))) | J13: =IF(F13="","",F13+IF(I13=I12,J12,0))
I14: =IF(H14="","",DATEVALUE(MID(H14,6,11))) | J14: =IF(F14="","",F14+IF(I14=I13,J13,0))
I15: =IF(H15="","",DATEVALUE(MID(H15,6,11))) | J15: =IF(F15="","",F15+IF(I15=I14,J14,0))
... I52: =IF(H52="","",DATEVALUE(MID(H52,6,11))) | J52: =IF(F52="","",F52+IF(I52=I51,J51,0))

Sheet Advanced Setup Planner
A1: EURUSD Planner HUD (inputs → outputs) | N1: BACKEND CALC — Use Planner_HUD (inputs & ladders) | S1: Structure (SMC) – D1 / H4 / H1 / 15m | X1: Side | Y1: =IF(AND($T$8,NOT($T$9)),"LONG",IF(AND($T$9,NOT($T$8)),"SHORT","")) | AC1: PRIMARY LADDER | AD1: Entry | AE1: TP | AF1: SL | AG1: Pips to TP1 | AH1: Eff Pips to SL | AI1: Weight | AJ1: Risk $ | AK1: Reward $ | AL1: Units | AM1: R per rung | EH1: CT_Entry | EI1: =IF(SUM($AI$28:$AI$30)=0,"",SUMPRODUCT($AD$28:$AD$30,$AI$28:$AI$30)/SUM($AI$28:$AI$30))
A2: Edit BLUE cells only. Planner_v2 reads from here. | N2: Market snapshot (15m + HTF EMAs & ATR) | S2: TF | T2: Trend | U2: Last BOS | V2: Last CHOCH | X2: Risk per Trade R ($) | Y2: =Summary!B10*Summary!B8 | AC2: Entry 0.382 | AD2: =IF($Y$1="LONG",IF($ED$58,$T$19,$O$7),IF($Y$1="SHORT",$Q$23,"")) | AE2: =IF(AD2="","",$ED$40) | AF2: =IF($Y$1="LONG",IF(OR($ED$58,$O$3>=$T$19),$ED$27,$T$20-0.0002),IF($Y$1="SHORT",IF($ED$58,MAX($O$39,$O$7)+0.0002,$T$19+0.0002),"")) | AG2: =IF(OR(AD2="",AE2=""),"",ABS((AE2-AD2)*10000)) | AH2: =IF(OR(AD2="",AF2=""),"",MAX(ABS((AD2-AF2)*10000),$ED$19)) | AI2: =$Y$7 | AJ2: =IF(OR(AI2=0,$ED$11=0,AD2=""),"",$Y$2*$ED$8*AI2/$ED$11) | AK2: =IF(OR(AJ2="",AJ2=0,AG2=""),"",AJ2*AG2/MAX(AH2,$ED$19)) | AL2: =IF(OR(AD2="",AH2="",AJ2=""),"",AJ2/(MAX(AH2,$ED$19)*$ED$3)) | AM2: =IF(OR(AG2="",AH2=""),"",AG2/MAX(AH2,$ED$19)) | AN2: =IF(AH2="","",MAX(AH2,$ED$7)) | EA2: Scoring & HUD | EC2: Ladder Controls | EE2: Big Picture | EF2: =IF($EB$25,"Avoid trading this leg – system rules (R, room, macro) are not met.",IF($EB$56=1,"HTF up, shallow pullback in Tier 1 (15m 0.382–0.618). Long bias but less room; prefer buying dips closer to Tier 2/3.",IF($EB$56=2,"HTF up, intraday pullback trading in Tier 2 (4H FVG + HTF 0.382 + EMA50D). Macro bias: buy dips; this is a B-grade but tradable zone when ladder and R/room are valid.",IF($EB$56=3,"HTF up, deep discount near structural support (Tier 3). If trend remains intact, this is a high-value region.","Price is above all discount tiers (premium) near PMH/PDH/EQH. This is not a location for fresh longs; either manage existing longs or wait for a pullback into Tier 2/3 or a clearly defined CT short setup.")))) | EH2: CT_SL | EI2: =$EB$48+0.0008
N3: Current Price | O3: ='Advanced Setup Planner'!B5 | S3: 1D | T3: =IF($O$12="","",IF(AND($O$12>$O$13,$O$13>$O$14,$O$3>$O$12+0.0002),"Bull",IF(AND($O$12<$O$13,$O$13<$O$14,$O$3<$O$12-0.0002),"Bear","Range"))) | U3: ='Advanced Setup Planner'!C24 | V3: ='Advanced Setup Planner'!D24 | X3: TP1 Price | Y3: =IF($Y$1="LONG",MIN(IF($T$15>$O$3,$T$15,10^6),IF($T$17>$O$3,$T$17,10^6),IF($T$19>$O$3,$T$19,10^6),IF($T$21>$O$3,$T$21,10^6)),IF($Y$1="SHORT",MAX(IF($T$16<$O$3,$T$16,-10^6),IF($T$18<$O$3,$T$18,-10^6),IF($T$20<$O$3,$T$20,-10^6),IF($T$22<$O$3,$T$22,-10^6)),"")) | AC3: Entry 0.500 | AD3: =IF($Y$1="LONG",IF($ED$58,AVERAGE($O$39,$O$40),$O$8),IF($Y$1="SHORT",$Q$24,"")) | AE3: =IF(AD3="","",$ED$40) | AF3: =IF($Y$1="LONG",IF(OR($ED$58,$O$3>=$T$19),$ED$27,$T$20-0.0002),IF($Y$1="SHORT",IF($ED$58,MAX($O$39,$O$7)+0.0002,$T$19+0.0002),"")) | AG3: =IF(OR(AD3="",AE3=""),"",ABS((AE3-AD3)*10000)) | AH3: =IF(OR(AD3="",AF3=""),"",MAX(ABS((AD3-AF3)*10000),$ED$19)) | AI3: =$Y$8 | AJ3: =IF(OR(AI3=0,$ED$11=0,AD3=""),"",$Y$2*$ED$8*AI3/$ED$11) | AK3: =IF(OR(AJ3="",AJ3=0,AG3=""),"",AJ3*AG3/MAX(AH3,$ED$19)) | AL3: =IF(OR(AD3="",AH3="",AJ3=""),"",AJ3/(MAX(AH3,$ED$19)*$ED$3)) | AM3: =IF(OR(AG3="",AH3=""),"",AG3/MAX(AH3,$ED$19)) | AN3: =IF(AH3="","",MAX(AH3,$ED$7)) | EC3: PipSize | ED3: 0.0001 | EF3: =IFERROR(IF(EB23<>"CoreLong","",IF($EB$55=1,"Shallow long zone (Tier 1): "&TEXT(EB51,"0.00000")&" → "&TEXT(EC51,"0.00000")&" (15m fib 0.382–0.618, less room).",IF($EB$55=2,"Main long zone (Tier 2): "&TEXT(EB52,"0.00000")&" → "&TEXT(EC52,"0.00000")&" (4H FVG + HTF 0.382 + EMA50D).",IF($EB$55=3,"Deep long zone (Tier 3): "&TEXT(EB53,"0.00000")&" → "&TEXT(EC53,"0.00000")&" (EMA100D + PWL + HTF fib).","")))),"") | EH3: CT_TP1 | EI3: =$EB$32
A4: Market snapshot (update from chart) | D4: Liquidity / Session levels | G4: FVG / value blocks | J4: Options expiry + risk/weights | S4: 4H | T4: =IF($O$11="","",IF($O$3>$O$11+0.0002,"Bull",IF($O$3<$O$11-0.0002,"Bear","Range"))) | U4: ='Advanced Setup Planner'!C25 | V4: ='Advanced Setup Planner'!D25 | X4: SL Price (Auto) | Y4: =IF($Y$5<>"",$Y$5,IF($Y$1="LONG",IF($Y$22="","",$Y$22-0.0003),IF($Y$1="SHORT",IF($Y$23="","",$Y$23+0.0003),""))) | AC4: Entry 0.618 | AD4: =IF($Y$1="LONG",IF($ED$58,MIN($O$40,$O$7),$O$10),IF($Y$1="SHORT",$Q$25,"")) | AE4: =IF(AD4="","",$ED$40) | AF4: =IF($Y$1="LONG",IF(OR($ED$58,$O$3>=$T$19),$ED$27,$T$20-0.0002),IF($Y$1="SHORT",IF($ED$58,MAX($O$39,$O$7)+0.0002,$T$19+0.0002),"")) | AG4: =IF(OR(AD4="",AE4=""),"",ABS((AE4-AD4)*10000)) | AH4: =IF(OR(AD4="",AF4=""),"",MAX(ABS((AD4-AF4)*10000),$ED$19)) | AI4: =$Y$9 | AJ4: =IF(OR(AI4=0,$ED$11=0,AD4=""),"",$Y$2*$ED$8*AI4/$ED$11) | AK4: =IF(OR(AJ4="",AJ4=0,AG4=""),"",AJ4*AG4/MAX(AH4,$ED$19)) | AL4: =IF(OR(AD4="",AH4="",AJ4=""),"",AJ4/(MAX(AH4,$ED$19)*$ED$3)) | AM4: =IF(OR(AG4="",AH4=""),"",AG4/MAX(AH4,$ED$19)) | AN4: =IF(AH4="","",MAX(AH4,$ED$7)) | EA4: PipTol_Value | EB4: =ROUND($O$18*10000*0.8,0) | EC4: MinStopPips | ED4: 8 | EE4: Long Zone (A+) | EF4: ="Deep A+ long pocket candidate (Tier 3): "&TEXT($EB$53,"0.00000")&" → "&TEXT($EC$53,"0.00000")&". Ladder (upper/mid/deep): "&TEXT($AD$15,"0.00000")&"/"&TEXT($AD$16,"0.00000")&"/"&TEXT($AD$17,"0.00000")&", SL "&TEXT($AF$15,"0.00000")&", TP1 "&TEXT($AE$15,"0.00000")&". Use this only if price flushes into Tier 3 with HTF trend intact and R/room are satisfied." | EH4: CT_TP2 | EI4: =IF($Y$1="SHORT",$Y$3,"")
A5: Current Price | B5: 1.165 | D5: PMH | E5: 1.1808 | G5: 4H FVG high | H5: 1.16139 | J5: Strike 1 | K5: 1.185 | N5: EMA9 15m | O5: ='Advanced Setup Planner'!B6 | S5: 1H | T5: =IF($O$10="","",IF($O$3>$O$10+0.0002,"Bull",IF($O$3<$O$10-0.0002,"Bear","Range"))) | U5: ='Advanced Setup Planner'!C26 | V5: ='Advanced Setup Planner'!D26 | X5: Manual SL override? | EA5: PipTol_Fib | EB5: =ROUND($O$18*10000*0.5,0) | EC5: ATR_StopMult | ED5: 1.5 | EE5: Trend Long Plan | EF5: =IFERROR(IF(AND($EB$23="CoreLong",NOT($EB$25)),"Trend long plan (current tier "&$EB$56&"): ladder at "&TEXT($AD$2,"0.00000")&"/"&TEXT($AD$3,"0.00000")&"/"&TEXT($AD$4,"0.00000")&", SL "&TEXT($AF$2,"0.00000")&", TP1 "&TEXT($AE$2,"0.00000")&". Confirm 15m/1H CHOCH up in this tier, then manage toward TP1 (and potentially PDH/PWH) using the ladder.",""),"") | EH5: CT_Risk$ | EI5: =$Y$2*0.5 | EJ5: =IFERROR(IF(EI9=0,"",(EI1-EI3)*EI9),"")
A6: EMA9 15m | B6: 1.1645 | D6: PML | E6: 1.15889 | G6: 4H FVG low | H6: 1.1605 | J6: Size 1 (bn) | K6: 1.46 | N6: EMA21 15m | O6: ='Advanced Setup Planner'!B7 | S6: 15M | T6: =IF($O$5="","",IF(AND($O$5>$O$6,$O$6>$O$7,$O$7>$O$8),"Bull",IF(AND($O$5<$O$6,$O$6<$O$7,$O$7<$O$8),"Bear","Range"))) | U6: ='Advanced Setup Planner'!C27 | V6: ='Advanced Setup Planner'!D27 | AC6: Avg Pips to SL | AD6: =IF(SUM(AL2:AL4)=0,0,SUMPRODUCT(AN2:AN4,AL2:AL4)/SUM(AL2:AL4)) | EA6: PipTol_Mid | EB6: =ROUND($O$18*10000*1,0) | EC6: ATR15m_pips | ED6: =ROUND($O$18*10000,1) | EH6: CT_PipsSL | EI6: =IF(OR(EI1="",EI2=""),"",ABS((EI1-EI2)*10000))
