Workbook
Name LT_CategoryUS: Backend!$A$26:$A$31
Name LT_MacroDir: Backend!$A$11:$A$19
Name LT_RatePolicy: Backend!$A$20:$A$22
Name LT_RiskEnv: Backend!$A$23:$A$25
Name LT_Speakers: Backend!$A$35:$A$55
Name LT_TrendBull: Backend!$A$2:$A$7
Name LT_WeekNum: Backend!$A$8:$A$10

Sheet Instructions
B1: FOREX TRADING WORKBOOK — USER GUIDE
B2: Version 1.0 | Ready for distribution
B4: SECTION 1 — COLOR GUIDE
B6: ■ INPUT CELL | E6: YOU enter data here — these are your inputs
B7: ■ FORMULA CELL | E7: Auto-calculated by the workbook — do NOT edit
B9: SECTION 2 — HOW THIS WORKBOOK WORKS
B11: This workbook has 5 tabs:
B13: 1. Instructions | E13: You are here. Read this first.
B14: 2. Summary | E14: Monthly performance dashboard. Fill once per month.
B15: 3. Daily Log | E15: Your daily trading journal. Fill each trading day.
B16: 4. Raw daily data | E16: Paste your broker trade history here daily.
B17: 5. Setup Planner | E17: Fill before each trading session for auto trade plan.
B19: Data Flow:
B20: Raw daily data ➜ Daily Log ➜ Summary (automatic aggregation)
B21: Your inputs ➜ Setup Planner ➜ Trade Plan (automatic calculation)
B23: SECTION 3 — SUMMARY TAB
B25: Fill these 6 cells at the start of each month:
B27: Monthly Target ($) | E27: How much you aim to make this month
B28: Active Trading Days | E28: How many days you plan to trade
B29: Weeks in Cycle | E29: Usually 4
B30: Risk % per trade | E30: e.g. 0.07 = 7% of NAV
B31: Max Daily Loss (R) | E31: e.g. 2 = stop after -2R intraday
B32: Current NAV ($) | E32: Your account balance on day 1
B34: Everything else auto-calculates:
B35: Projected P&L | E35: Forecast if you maintain current pace
B36: Required R/Day | E36: How many R you need each remaining day
B37: Weekly Table | E37: Auto-summary for each of the 4 weeks
B39: SECTION 4 — DAILY LOG TAB
B41: Each trading day, fill only these 4 columns:
B43: Column A | E43: Today's date
B44: Column B | E44: Week of the cycle (1, 2, 3, or 4)
B45: Column D | E45: Y if you traded, N if not
B46: Column M | E46: Notes — psychology, conditions, lessons
B48: ⚠ Do NOT touch columns E–L, N–Y — they auto-calculate.
B50: Column reference:
B51: E=NAV | F=Risk$ | G=MaxLoss | H=P&L | I=CumPnL | J=WeekPnL | K=Target | L=Variance
B52: N=#Trades | O=#Wins | P=#Loss | Q=Win$ | R=Loss$ | S=WinRate | T=R:R | U=DailyR | V=Loss%
B54: SECTION 5 — RAW DAILY DATA TAB
B56: How to import from your broker (MT4/MT5):
B58: Step 1: In MT4/MT5, go to Account History
...

Sheet Summary
A1: TRADING PERFORMANCE SUMMARY | B1: TRADING PERFORMANCE SUMMARY2
A2: Monthly Target ($) | B2: 2000
A3: Planned Active Trading Days | B3: 20
A4: Average Target per Trading Day ($) | B4: =IFERROR(B2/B3,"") -> 100
A5: Weeks in Cycle | B5: 4
A6: Average Target per Week ($) | B6: =IFERROR(B2/B5,"") -> 500
A7: Required R per week | B7: =IFERROR(B6/B17,"") -> 0.095238095
A8: Risk % of NAV per trade | B8: 0.05
A9: Max Daily Loss (R multiples) | B9: 2
A10: Starting NAV ($) | B10: 10000 | E10: Current NAV ➔ | F10: =B10+B11 -> 11050
A11: Cumulative P&L Month ($) | B11: =SUM('Daily Log'!$H$2:$H$100) -> 1050
A12: Remaining Target ($) | B12: =IFERROR(IF(B11="",B2,B2-B11),"") -> 950
A13: Trading Days Used | B13: =COUNTIFS('Daily Log'!D:D,"Y") -> 4
A14: Trading Days Remaining | B14: =B3-B13 -> 16
A15: Required P&L per Remaining Day | B15: =IFERROR(IF(B14>0,B12/B14,""),"") -> 59.375
A16: Target R per Day (approx) | B16: =IFERROR(IF(B8>0,B15/(B10*B8),""),"") -> 0.11875
A17: Projected Month P&L ($) | B17: =IFERROR(IF(B11="","",B11/MAX(1,B13)*B3),"") -> 5250
A18: Average R value ($) | B18: =IFERROR(IF(K22>0,B11/K22,""),"")
A19: Today’s expected plan P&L ($) | B19: ='Advanced Setup Planner'!EE18 -> 3796457.1
A21: Week # | B21: Active Days | C21: Total Trades | D21: Total Wins | E21: Total Losses | F21: Week Net P&L | G21: Weekly Target | H21: Week Variance ($) | I21: Avg Win Rate % | J21: Avg Reward:Risk | K21: Total R
A22: 1 | B22: =COUNTIFS('Daily Log'!$B:$B,$A22,'Daily Log'!$D:$D,"Y") -> 1 | C22: =SUMIFS('Daily Log'!N:N,'Daily Log'!B:B,$A22) -> 1 | D22: =SUMIFS('Daily Log'!O:O,'Daily Log'!B:B,$A22) -> 1 | E22: =SUMIFS('Daily Log'!P:P,'Daily Log'!B:B,$A22) -> 0 | F22: =SUMIFS('Daily Log'!H:H,'Daily Log'!B:B,$A22) -> 250 | G22: =$B$6 -> 500 | H22: =F22-G22 -> -250 | I22: =IFERROR(D22/C22,0) -> 1 | J22: =IFERROR(SUMIFS('Daily Log'!T:T,'Daily Log'!B:B,$A22)/B22,0) -> 0 | K22: =SUMIFS('Daily Log'!U:U,'Daily Log'!B:B,$A22) -> #VALUE!
A23: 2 | B23: =COUNTIFS('Daily Log'!$B:$B,$A23,'Daily Log'!$D:$D,"Y") -> 1 | C23: =SUMIFS('Daily Log'!N:N,'Daily Log'!B:B,$A23) -> 2 | D23: =SUMIFS('Daily Log'!O:O,'Daily Log'!B:B,$A23) -> 0 | E23: =SUMIFS('Daily Log'!P:P,'Daily Log'!B:B,$A23) -> 2 | F23: =SUMIFS('Daily Log'!H:H,'Daily Log'!B:B,$A23) -> -200 | G23: =$B$6 -> 500 | H23: =F23-G23 -> -700 | I23: =IFERROR(D23/C23,0) -> 0 | J23: =IFERROR(SUMIFS('Daily Log'!T:T,'Daily Log'!B:B,$A23)/B23,0) -> 0 | K23: =SUMIFS('Daily Log'!U:U,'Daily Log'!B:B,$A23) -> #VALUE!
A24: 3 | B24: =COUNTIFS('Daily Log'!$B:$B,$A24,'Daily Log'!$D:$D,"Y") -> 2 | C24: =SUMIFS('Daily Log'!N:N,'Daily Log'!B:B,$A24) -> 2 | D24: =SUMIFS('Daily Log'!O:O,'Daily Log'!B:B,$A24) -> 2 | E24: =SUMIFS('Daily Log'!P:P,'Daily Log'!B:B,$A24) -> 0 | F24: =SUMIFS('Daily Log'!H:H,'Daily Log'!B:B,$A24) -> 1000 | G24: =$B$6 -> 500 | H24: =F24-G24 -> 500 | I24: =IFERROR(D24/C24,0) -> 1 | J24: =IFERROR(SUMIFS('Daily Log'!T:T,'Daily Log'!B:B,$A24)/B24,0) -> 0 | K24: =SUMIFS('Daily Log'!U:U,'Daily Log'!B:B,$A24) -> #VALUE!
A25: 4 | B25: =COUNTIFS('Daily Log'!$B:$B,$A25,'Daily Log'!$D:$D,"Y") -> 0 | C25: =SUMIFS('Daily Log'!N:N,'Daily Log'!B:B,$A25) -> 0 | D25: =SUMIFS('Daily Log'!O:O,'Daily Log'!B:B,$A25) -> 0 | E25: =SUMIFS('Daily Log'!P:P,'Daily Log'!B:B,$A25) -> 0 | F25: =SUMIFS('Daily Log'!H:H,'Daily Log'!B:B,$A25) -> 0 | G25: =$B$6 -> 500 | H25: =F25-G25 -> -500 | I25: =IFERROR(D25/C25,0) -> 0 | J25: =IFERROR(SUMIFS('Daily Log'!T:T,'Daily Log'!B:B,$A25)/B25,0) -> 0 | K25: =SUMIFS('Daily Log'!U:U,'Daily Log'!B:B,$A25) -> 0

Sheet Daily Log
A1: Date | B1: Week # | C1: Day of Week | D1: Active Trading Day? (Y/N) | E1: Start NAV ($) | F1: Risk per Trade R ($) | G1: Max Daily Loss Cap ($) | H1: Net P&L ($) | I1: Cumulative P&L Month ($) | J1: Week P&L ($) | K1: Weekly Target ($) | L1: Week Variance vs Target ($) | M1: Notes | N1: # Trades | O1: # Wins | P1: # Losses | Q1: Total Wins ($) | R1: Total Losses ($) | S1: Win Rate (%) | T1: Reward:Risk | U1: Daily R-multiple | V1: Losses vs Cap | W1: Intraday Net P&L (so far) | X1: % of Cap Used (Net) | Y1: Worst Intraday DD % of Cap
A2: 46143 | B2: 1 | C2: =IF($A2="","",TEXT($A2,"dddd")) -> Friday | D2: Y | E2: =IF($A2="","", E1+H1) -> #VALUE! | F2: =IF($A2="","",$E2*Summary!$B$8) -> #VALUE! | G2: =IF($A2="","",F2*Summary!$B$9) -> #VALUE! | H2: =IF($A2="","",SUMIFS('Raw daily data'!$F:$F,'Raw daily data'!$I:$I,$A2)) -> 250 | I2: =IF($A2="","", I1+H2) -> #VALUE! | J2: =IF($A2="","",SUMIF($B$2:$B$100,B2,$H$2:$H$100)) -> 250 | K2: =IF($A2="","",Summary!$B$6) -> 500 | L2: =IF($A2="","",IFERROR(J2-K2,"")) -> -250 | N2: =IF($A2="","",COUNTIFS('Raw daily data'!$I:$I,$A2)) -> 1 | O2: =IF($A2="","",COUNTIFS('Raw daily data'!$I:$I,$A2,'Raw daily data'!$F:$F,">0")) -> 1 | P2: =IF($A2="","",COUNTIFS('Raw daily data'!$I:$I,$A2,'Raw daily data'!$F:$F,"<0")) -> 0 | Q2: =IF($A2="","",SUMIFS('Raw daily data'!$F:$F,'Raw daily data'!$I:$I,$A2,'Raw daily data'!$F:$F,">0")) -> 250 | R2: =IF($A2="","",ABS(SUMIFS('Raw daily data'!$F:$F,'Raw daily data'!$I:$I,$A2,'Raw daily data'!$F:$F,"<0"))) -> 0 | S2: =IF($A2="","",IF(N2>0,O2/N2,"")) -> 1 | T2: =IF($A2="","",IF(R2>0,Q2/ABS(R2),"")) | U2: =IF($A2="","",IF(F2>0,H2/F2,"")) -> #VALUE! | V2: =IF($A2="","",IFERROR(IF(H2<0,MIN(ABS(H2)/G2,1),0),"")) -> 0 | W2: =IF($A2="","",_xlfn.MAXIFS('Raw daily data'!$J:$J,'Raw daily data'!$I:$I,$A2)) -> 250 | X2: =IF($A2="","",IFERROR(IF(W2>=0,0,ABS(W2)/G2),"")) -> 0 | Y2: =IF($A2="","",IFERROR(ABS(MIN(0,_xlfn.MINIFS('Raw daily data'!$J:$J,'Raw daily data'!$I:$I,$A2)))/G2,""))
A3: 46151 | B3: 2 | C3: =IF($A3="","",TEXT($A3,"dddd")) -> Saturday | D3: Y | E3: =IF($A3="","", E2+H2) -> #VALUE! | F3: =IF($A3="","",$E3*Summary!$B$8) -> #VALUE! | G3: =IF($A3="","",F3*Summary!$B$9) -> #VALUE! | H3: =IF($A3="","",SUMIFS('Raw daily data'!$F:$F,'Raw daily data'!$I:$I,$A3)) -> -200 | I3: =IF($A3="","", I2+H3) -> #VALUE! | J3: =IF($A3="","",SUMIF($B$2:$B$100,B3,$H$2:$H$100)) -> -200 | K3: =IF($A3="","",Summary!$B$6) -> 500 | L3: =IF($A3="","",IFERROR(J3-K3,"")) -> -700 | N3: =IF($A3="","",COUNTIFS('Raw daily data'!$I:$I,$A3)) -> 2 | O3: =IF($A3="","",COUNTIFS('Raw daily data'!$I:$I,$A3,'Raw daily data'!$F:$F,">0")) -> 0 | P3: =IF($A3="","",COUNTIFS('Raw daily data'!$I:$I,$A3,'Raw daily data'!$F:$F,"<0")) -> 2 | Q3: =IF($A3="","",SUMIFS('Raw daily data'!$F:$F,'Raw daily data'!$I:$I,$A3,'Raw daily data'!$F:$F,">0")) -> 0 | R3: =IF($A3="","",ABS(SUMIFS('Raw daily data'!$F:$F,'Raw daily data'!$I:$I,$A3,'Raw daily data'!$F:$F,"<0"))) -> 200 | S3: =IF($A3="","",IF(N3>0,O3/N3,"")) -> 0 | T3: =IF($A3="","",IF(R3>0,Q3/ABS(R3),"")) -> 0 | U3: =IF($A3="","",IF(F3>0,H3/F3,"")) -> #VALUE! | V3: =IF($A3="","",IFERROR(IF(H3<0,MIN(ABS(H3)/G3,1),0),"")) | W3: =IF($A3="","",_xlfn.MAXIFS('Raw daily data'!$J:$J,'Raw daily data'!$I:$I,$A3)) -> -100 | X3: =IF($A3="","",IFERROR(IF(W3>=0,0,ABS(W3)/G3),"")) | Y3: =IF($A3="","",IFERROR(ABS(MIN(0,_xlfn.MINIFS('Raw daily data'!$J:$J,'Raw daily data'!$I:$I,$A3)))/G3,""))
A4: 46159 | B4: 3 | C4: =IF($A4="","",TEXT($A4,"dddd")) -> Sunday | D4: Y | E4: =IF($A4="","", E3+H3) -> #VALUE! | F4: =IF($A4="","",$E4*Summary!$B$8) -> #VALUE! | G4: =IF($A4="","",F4*Summary!$B$9) -> #VALUE! | H4: =IF($A4="","",SUMIFS('Raw daily data'!$F:$F,'Raw daily data'!$I:$I,$A4)) -> 800 | I4: =IF($A4="","", I3+H4) -> #VALUE! | J4: =IF($A4="","",SUMIF($B$2:$B$100,B4,$H$2:$H$100)) -> 1000 | K4: =IF($A4="","",Summary!$B$6) -> 500 | L4: =IF($A4="","",IFERROR(J4-K4,"")) -> 500 | N4: =IF($A4="","",COUNTIFS('Raw daily data'!$I:$I,$A4)) -> 1 | O4: =IF($A4="","",COUNTIFS('Raw daily data'!$I:$I,$A4,'Raw daily data'!$F:$F,">0")) -> 1 | P4: =IF($A4="","",COUNTIFS('Raw daily data'!$I:$I,$A4,'Raw daily data'!$F:$F,"<0")) -> 0 | Q4: =IF($A4="","",SUMIFS('Raw daily data'!$F:$F,'Raw daily data'!$I:$I,$A4,'Raw daily data'!$F:$F,">0")) -> 800 | R4: =IF($A4="","",ABS(SUMIFS('Raw daily data'!$F:$F,'Raw daily data'!$I:$I,$A4,'Raw daily data'!$F:$F,"<0"))) -> 0 | S4: =IF($A4="","",IF(N4>0,O4/N4,"")) -> 1 | T4: =IF($A4="","",IF(R4>0,Q4/ABS(R4),"")) | U4: =IF($A4="","",IF(F4>0,H4/F4,"")) -> #VALUE! | V4: =IF($A4="","",IFERROR(IF(H4<0,MIN(ABS(H4)/G4,1),0),"")) -> 0 | W4: =IF($A4="","",_xlfn.MAXIFS('Raw daily data'!$J:$J,'Raw daily data'!$I:$I,$A4)) -> 800 | X4: =IF($A4="","",IFERROR(IF(W4>=0,0,ABS(W4)/G4),"")) -> 0 | Y4: =IF($A4="","",IFERROR(ABS(MIN(0,_xlfn.MINIFS('Raw daily data'!$J:$J,'Raw daily data'!$I:$I,$A4)))/G4,""))
A5: 46160 | B5: 3 | C5: =IF($A5="","",TEXT($A5,"dddd")) -> Monday | D5: Y | E5: =IF($A5="","", E4+H4) -> #VALUE! | F5: =IF($A5="","",$E5*Summary!$B$8) -> #VALUE! | G5: =IF($A5="","",F5*Summary!$B$9) -> #VALUE! | H5: =IF($A5="","",SUMIFS('Raw daily data'!$F:$F,'Raw daily data'!$I:$I,$A5)) -> 200 | I5: =IF($A5="","", I4+H5) -> #VALUE! | J5: =IF($A5="","",SUMIF($B$2:$B$100,B5,$H$2:$H$100)) -> 1000 | K5: =IF($A5="","",Summary!$B$6) -> 500 | L5: =IF($A5="","",IFERROR(J5-K5,"")) -> 500 | N5: =IF($A5="","",COUNTIFS('Raw daily data'!$I:$I,$A5)) -> 1 | O5: =IF($A5="","",COUNTIFS('Raw daily data'!$I:$I,$A5,'Raw daily data'!$F:$F,">0")) -> 1 | P5: =IF($A5="","",COUNTIFS('Raw daily data'!$I:$I,$A5,'Raw daily data'!$F:$F,"<0")) -> 0 | Q5: =IF($A5="","",SUMIFS('Raw daily data'!$F:$F,'Raw daily data'!$I:$I,$A5,'Raw daily data'!$F:$F,">0")) -> 200 | R5: =IF($A5="","",ABS(SUMIFS('Raw daily data'!$F:$F,'Raw daily data'!$I:$I,$A5,'Raw daily data'!$F:$F,"<0"))) -> 0 | S5: =IF($A5="","",IF(N5>0,O5/N5,"")) -> 1 | T5: =IF($A5="","",IF(R5>0,Q5/ABS(R5),"")) | U5: =IF($A5="","",IF(F5>0,H5/F5,"")) -> #VALUE! | V5: =IF($A5="","",IFERROR(IF(H5<0,MIN(ABS(H5)/G5,1),0),"")) -> 0 | W5: =IF($A5="","",_xlfn.MAXIFS('Raw daily data'!$J:$J,'Raw daily data'!$I:$I,$A5)) -> 200 | X5: =IF($A5="","",IFERROR(IF(W5>=0,0,ABS(W5)/G5),"")) -> 0 | Y5: =IF($A5="","",IFERROR(ABS(MIN(0,_xlfn.MINIFS('Raw daily data'!$J:$J,'Raw daily data'!$I:$I,$A5)))/G5,""))
C6: =IF($A6="","",TEXT($A6,"dddd")) | E6: =IF($A6="","", E5+H5) | F6: =IF($A6="","",$E6*Summary!$B$8) | G6: =IF($A6="","",F6*Summary!$B$9) | H6: =IF($A6="","",SUMIFS('Raw daily data'!$F:$F,'Raw daily data'!$I:$I,$A6)) | I6: =IF($A6="","", I5+H6) | J6: =IF($A6="","",SUMIF($B$2:$B$100,B6,$H$2:$H$100)) | K6: =IF($A6="","",Summary!$B$6) | L6: =IF($A6="","",IFERROR(J6-K6,"")) | N6: =IF($A6="","",COUNTIFS('Raw daily data'!$I:$I,$A6)) | O6: =IF($A6="","",COUNTIFS('Raw daily data'!$I:$I,$A6,'Raw daily data'!$F:$F,">0")) | P6: =IF($A6="","",COUNTIFS('Raw daily data'!$I:$I,$A6,'Raw daily data'!$F:$F,"<0")) | Q6: =IF($A6="","",SUMIFS('Raw daily data'!$F:$F,'Raw daily data'!$I:$I,$A6,'Raw daily data'!$F:$F,">0")) | R6: =IF($A6="","",ABS(SUMIFS('Raw daily data'!$F:$F,'Raw daily data'!$I:$I,$A6,'Raw daily data'!$F:$F,"<0"))) | S6: =IF($A6="","",IF(N6>0,O6/N6,"")) | T6: =IF($A6="","",IF(R6>0,Q6/ABS(R6),"")) | U6: =IF($A6="","",IF(F6>0,H6/F6,"")) | V6: =IF($A6="","",IFERROR(IF(H6<0,MIN(ABS(H6)/G6,1),0),"")) | W6: =IF($A6="","",_xlfn.MAXIFS('Raw daily data'!$J:$J,'Raw daily data'!$I:$I,$A6)) | X6: =IF($A6="","",IFERROR(IF(W6>=0,0,ABS(W6)/G6),"")) | Y6: =IF($A6="","",IFERROR(ABS(MIN(0,_xlfn.MINIFS('Raw daily data'!$J:$J,'Raw daily data'!$I:$I,$A6)))/G6,""))
C7: =IF($A7="","",TEXT($A7,"dddd")) | E7: =IF($A7="","", E6+H6) | F7: =IF($A7="","",$E7*Summary!$B$8) | G7: =IF($A7="","",F7*Summary!$B$9) | H7: =IF($A7="","",SUMIFS('Raw daily data'!$F:$F,'Raw daily data'!$I:$I,$A7)) | I7: =IF($A7="","", I6+H7) | J7: =IF($A7="","",SUMIF($B$2:$B$100,B7,$H$2:$H$100)) | K7: =IF($A7="","",Summary!$B$6) | L7: =IF($A7="","",IFERROR(J7-K7,"")) | N7: =IF($A7="","",COUNTIFS('Raw daily data'!$I:$I,$A7)) | O7: =IF($A7="","",COUNTIFS('Raw daily data'!$I:$I,$A7,'Raw daily data'!$F:$F,">0")) | P7: =IF($A7="","",COUNTIFS('Raw daily data'!$I:$I,$A7,'Raw daily data'!$F:$F,"<0")) | Q7: =IF($A7="","",SUMIFS('Raw daily data'!$F:$F,'Raw daily data'!$I:$I,$A7,'Raw daily data'!$F:$F,">0")) | R7: =IF($A7="","",ABS(SUMIFS('Raw daily data'!$F:$F,'Raw daily data'!$I:$I,$A7,'Raw daily data'!$F:$F,"<0"))) | S7: =IF($A7="","",IF(N7>0,O7/N7,"")) | T7: =IF($A7="","",IF(R7>0,Q7/ABS(R7),"")) | U7: =IF($A7="","",IF(F7>0,H7/F7,"")) | V7: =IF($A7="","",IFERROR(IF(H7<0,MIN(ABS(H7)/G7,1),0),"")) | W7: =IF($A7="","",_xlfn.MAXIFS('Raw daily data'!$J:$J,'Raw daily data'!$I:$I,$A7)) | X7: =IF($A7="","",IFERROR(IF(W7>=0,0,ABS(W7)/G7),"")) | Y7: =IF($A7="","",IFERROR(ABS(MIN(0,_xlfn.MINIFS('Raw daily data'!$J:$J,'Raw daily data'!$I:$I,$A7)))/G7,""))
C8: =IF($A8="","",TEXT($A8,"dddd")) | E8: =IF($A8="","", E7+H7) | F8: =IF($A8="","",$E8*Summary!$B$8) | G8: =IF($A8="","",F8*Summary!$B$9) | H8: =IF($A8="","",SUMIFS('Raw daily data'!$F:$F,'Raw daily data'!$I:$I,$A8)) | I8: =IF($A8="","", I7+H8) | J8: =IF($A8="","",SUMIF($B$2:$B$100,B8,$H$2:$H$100)) | K8: =IF($A8="","",Summary!$B$6) | L8: =IF($A8="","",IFERROR(J8-K8,"")) | N8: =IF($A8="","",COUNTIFS('Raw daily data'!$I:$I,$A8)) | O8: =IF($A8="","",COUNTIFS('Raw daily data'!$I:$I,$A8,'Raw daily data'!$F:$F,">0")) | P8: =IF($A8="","",COUNTIFS('Raw daily data'!$I:$I,$A8,'Raw daily data'!$F:$F,"<0")) | Q8: =IF($A8="","",SUMIFS('Raw daily data'!$F:$F,'Raw daily data'!$I:$I,$A8,'Raw daily data'!$F:$F,">0")) | R8: =IF($A8="","",ABS(SUMIFS('Raw daily data'!$F:$F,'Raw daily data'!$I:$I,$A8,'Raw daily data'!$F:$F,"<0"))) | S8: =IF($A8="","",IF(N8>0,O8/N8,"")) | T8: =IF($A8="","",IF(R8>0,Q8/ABS(R8),"")) | U8: =IF($A8="","",IF(F8>0,H8/F8,"")) | V8: =IF($A8="","",IFERROR(IF(H8<0,MIN(ABS(H8)/G8,1),0),"")) | W8: =IF($A8="","",_xlfn.MAXIFS('Raw daily data'!$J:$J,'Raw daily data'!$I:$I,$A8)) | X8: =IF($A8="","",IFERROR(IF(W8>=0,0,ABS(W8)/G8),"")) | Y8: =IF($A8="","",IFERROR(ABS(MIN(0,_xlfn.MINIFS('Raw daily data'!$J:$J,'Raw daily data'!$I:$I,$A8)))/G8,""))
C9: =IF($A9="","",TEXT($A9,"dddd")) | E9: =IF($A9="","", E8+H8) | F9: =IF($A9="","",$E9*Summary!$B$8) | G9: =IF($A9="","",F9*Summary!$B$9) | H9: =IF($A9="","",SUMIFS('Raw daily data'!$F:$F,'Raw daily data'!$I:$I,$A9)) | I9: =IF($A9="","", I8+H9) | J9: =IF($A9="","",SUMIF($B$2:$B$100,B9,$H$2:$H$100)) | K9: =IF($A9="","",Summary!$B$6) | L9: =IF($A9="","",IFERROR(J9-K9,"")) | N9: =IF($A9="","",COUNTIFS('Raw daily data'!$I:$I,$A9)) | O9: =IF($A9="","",COUNTIFS('Raw daily data'!$I:$I,$A9,'Raw daily data'!$F:$F,">0")) | P9: =IF($A9="","",COUNTIFS('Raw daily data'!$I:$I,$A9,'Raw daily data'!$F:$F,"<0")) | Q9: =IF($A9="","",SUMIFS('Raw daily data'!$F:$F,'Raw daily data'!$I:$I,$A9,'Raw daily data'!$F:$F,">0")) | R9: =IF($A9="","",ABS(SUMIFS('Raw daily data'!$F:$F,'Raw daily data'!$I:$I,$A9,'Raw daily data'!$F:$F,"<0"))) | S9: =IF($A9="","",IF(N9>0,O9/N9,"")) | T9: =IF($A9="","",IF(R9>0,Q9/ABS(R9),"")) | U9: =IF($A9="","",IF(F9>0,H9/F9,"")) | V9: =IF($A9="","",IFERROR(IF(H9<0,MIN(ABS(H9)/G9,1),0),"")) | W9: =IF($A9="","",_xlfn.MAXIFS('Raw daily data'!$J:$J,'Raw daily data'!$I:$I,$A9)) | X9: =IF($A9="","",IFERROR(IF(W9>=0,0,ABS(W9)/G9),"")) | Y9: =IF($A9="","",IFERROR(ABS(MIN(0,_xlfn.MINIFS('Raw daily data'!$J:$J,'Raw daily data'!$I:$I,$A9)))/G9,""))
C10: =IF($A10="","",TEXT($A10,"dddd")) | E10: =IF($A10="","", E9+H9) | F10: =IF($A10="","",$E10*Summary!$B$8) | G10: =IF($A10="","",F10*Summary!$B$9) | H10: =IF($A10="","",SUMIFS('Raw daily data'!$F:$F,'Raw daily data'!$I:$I,$A10)) | I10: =IF($A10="","", I9+H10) | J10: =IF($A10="","",SUMIF($B$2:$B$100,B10,$H$2:$H$100)) | K10: =IF($A10="","",Summary!$B$6) | L10: =IF($A10="","",IFERROR(J10-K10,"")) | N10: =IF($A10="","",COUNTIFS('Raw daily data'!$I:$I,$A10)) | O10: =IF($A10="","",COUNTIFS('Raw daily data'!$I:$I,$A10,'Raw daily data'!$F:$F,">0")) | P10: =IF($A10="","",COUNTIFS('Raw daily data'!$I:$I,$A10,'Raw daily data'!$F:$F,"<0")) | Q10: =IF($A10="","",SUMIFS('Raw daily data'!$F:$F,'Raw daily data'!$I:$I,$A10,'Raw daily data'!$F:$F,">0")) | R10: =IF($A10="","",ABS(SUMIFS('Raw daily data'!$F:$F,'Raw daily data'!$I:$I,$A10,'Raw daily data'!$F:$F,"<0"))) | S10: =IF($A10="","",IF(N10>0,O10/N10,"")) | T10: =IF($A10="","",IF(R10>0,Q10/ABS(R10),"")) | U10: =IF($A10="","",IF(F10>0,H10/F10,"")) | V10: =IF($A10="","",IFERROR(IF(H10<0,MIN(ABS(H10)/G10,1),0),"")) | W10: =IF($A10="","",_xlfn.MAXIFS('Raw daily data'!$J:$J,'Raw daily data'!$I:$I,$A10)) | X10: =IF($A10="","",IFERROR(IF(W10>=0,0,ABS(W10)/G10),"")) | Y10: =IF($A10="","",IFERROR(ABS(MIN(0,_xlfn.MINIFS('Raw daily data'!$J:$J,'Raw daily data'!$I:$I,$A10)))/G10,""))
C11: =IF($A11="","",TEXT($A11,"dddd")) | E11: =IF($A11="","", E10+H10) | F11: =IF($A11="","",$E11*Summary!$B$8) | G11: =IF($A11="","",F11*Summary!$B$9) | H11: =IF($A11="","",SUMIFS('Raw daily data'!$F:$F,'Raw daily data'!$I:$I,$A11)) | I11: =IF($A11="","", I10+H11) | J11: =IF($A11="","",SUMIF($B$2:$B$100,B11,$H$2:$H$100)) | K11: =IF($A11="","",Summary!$B$6) | L11: =IF($A11="","",IFERROR(J11-K11,"")) | N11: =IF($A11="","",COUNTIFS('Raw daily data'!$I:$I,$A11)) | O11: =IF($A11="","",COUNTIFS('Raw daily data'!$I:$I,$A11,'Raw daily data'!$F:$F,">0")) | P11: =IF($A11="","",COUNTIFS('Raw daily data'!$I:$I,$A11,'Raw daily data'!$F:$F,"<0")) | Q11: =IF($A11="","",SUMIFS('Raw daily data'!$F:$F,'Raw daily data'!$I:$I,$A11,'Raw daily data'!$F:$F,">0")) | R11: =IF($A11="","",ABS(SUMIFS('Raw daily data'!$F:$F,'Raw daily data'!$I:$I,$A11,'Raw daily data'!$F:$F,"<0"))) | S11: =IF($A11="","",IF(N11>0,O11/N11,"")) | T11: =IF($A11="","",IF(R11>0,Q11/ABS(R11),"")) | U11: =IF($A11="","",IF(F11>0,H11/F11,"")) | V11: =IF($A11="","",IFERROR(IF(H11<0,MIN(ABS(H11)/G11,1),0),"")) | W11: =IF($A11="","",_xlfn.MAXIFS('Raw daily data'!$J:$J,'Raw daily data'!$I:$I,$A11)) | X11: =IF($A11="","",IFERROR(IF(W11>=0,0,ABS(W11)/G11),"")) | Y11: =IF($A11="","",IFERROR(ABS(MIN(0,_xlfn.MINIFS('Raw daily data'!$J:$J,'Raw daily data'!$I:$I,$A11)))/G11,""))
C12: =IF($A12="","",TEXT($A12,"dddd")) | E12: =IF($A12="","", E11+H11) | F12: =IF($A12="","",$E12*Summary!$B$8) | G12: =IF($A12="","",F12*Summary!$B$9) | H12: =IF($A12="","",SUMIFS('Raw daily data'!$F:$F,'Raw daily data'!$I:$I,$A12)) | I12: =IF($A12="","", I11+H12) | J12: =IF($A12="","",SUMIF($B$2:$B$100,B12,$H$2:$H$100)) | K12: =IF($A12="","",Summary!$B$6) | L12: =IF($A12="","",IFERROR(J12-K12,"")) | N12: =IF($A12="","",COUNTIFS('Raw daily data'!$I:$I,$A12)) | O12: =IF($A12="","",COUNTIFS('Raw daily data'!$I:$I,$A12,'Raw daily data'!$F:$F,">0")) | P12: =IF($A12="","",COUNTIFS('Raw daily data'!$I:$I,$A12,'Raw daily data'!$F:$F,"<0")) | Q12: =IF($A12="","",SUMIFS('Raw daily data'!$F:$F,'Raw daily data'!$I:$I,$A12,'Raw daily data'!$F:$F,">0")) | R12: =IF($A12="","",ABS(SUMIFS('Raw daily data'!$F:$F,'Raw daily data'!$I:$I,$A12,'Raw daily data'!$F:$F,"<0"))) | S12: =IF($A12="","",IF(N12>0,O12/N12,"")) | T12: =IF($A12="","",IF(R12>0,Q12/ABS(R12),"")) | U12: =IF($A12="","",IF(F12>0,H12/F12,"")) | V12: =IF($A12="","",IFERROR(IF(H12<0,MIN(ABS(H12)/G12,1),0),"")) | W12: =IF($A12="","",_xlfn.MAXIFS('Raw daily data'!$J:$J,'Raw daily data'!$I:$I,$A12)) | X12: =IF($A12="","",IFERROR(IF(W12>=0,0,ABS(W12)/G12),"")) | Y12: =IF($A12="","",IFERROR(ABS(MIN(0,_xlfn.MINIFS('Raw daily data'!$J:$J,'Raw daily data'!$I:$I,$A12)))/G12,""))
C13: =IF($A13="","",TEXT($A13,"dddd")) | E13: =IF($A13="","", E12+H12) | F13: =IF($A13="","",$E13*Summary!$B$8) | G13: =IF($A13="","",F13*Summary!$B$9) | H13: =IF($A13="","",SUMIFS('Raw daily data'!$F:$F,'Raw daily data'!$I:$I,$A13)) | I13: =IF($A13="","", I12+H13) | J13: =IF($A13="","",SUMIF($B$2:$B$100,B13,$H$2:$H$100)) | K13: =IF($A13="","",Summary!$B$6) | L13: =IF($A13="","",IFERROR(J13-K13,"")) | N13: =IF($A13="","",COUNTIFS('Raw daily data'!$I:$I,$A13)) | O13: =IF($A13="","",COUNTIFS('Raw daily data'!$I:$I,$A13,'Raw daily data'!$F:$F,">0")) | P13: =IF($A13="","",COUNTIFS('Raw daily data'!$I:$I,$A13,'Raw daily data'!$F:$F,"<0")) | Q13: =IF($A13="","",SUMIFS('Raw daily data'!$F:$F,'Raw daily data'!$I:$I,$A13,'Raw daily data'!$F:$F,">0")) | R13: =IF($A13="","",ABS(SUMIFS('Raw daily data'!$F:$F,'Raw daily data'!$I:$I,$A13,'Raw daily data'!$F:$F,"<0"))) | S13: =IF($A13="","",IF(N13>0,O13/N13,"")) | T13: =IF($A13="","",IF(R13>0,Q13/ABS(R13),"")) | U13: =IF($A13="","",IF(F13>0,H13/F13,"")) | V13: =IF($A13="","",IFERROR(IF(H13<0,MIN(ABS(H13)/G13,1),0),"")) | W13: =IF($A13="","",_xlfn.MAXIFS('Raw daily data'!$J:$J,'Raw daily data'!$I:$I,$A13)) | X13: =IF($A13="","",IFERROR(IF(W13>=0,0,ABS(W13)/G13),"")) | Y13: =IF($A13="","",IFERROR(ABS(MIN(0,_xlfn.MINIFS('Raw daily data'!$J:$J,'Raw daily data'!$I:$I,$A13)))/G13,""))
C14: =IF($A14="","",TEXT($A14,"dddd")) | E14: =IF($A14="","", E13+H13) | F14: =IF($A14="","",$E14*Summary!$B$8) | G14: =IF($A14="","",F14*Summary!$B$9) | H14: =IF($A14="","",SUMIFS('Raw daily data'!$F:$F,'Raw daily data'!$I:$I,$A14)) | I14: =IF($A14="","", I13+H14) | J14: =IF($A14="","",SUMIF($B$2:$B$100,B14,$H$2:$H$100)) | K14: =IF($A14="","",Summary!$B$6) | L14: =IF($A14="","",IFERROR(J14-K14,"")) | N14: =IF($A14="","",COUNTIFS('Raw daily data'!$I:$I,$A14)) | O14: =IF($A14="","",COUNTIFS('Raw daily data'!$I:$I,$A14,'Raw daily data'!$F:$F,">0")) | P14: =IF($A14="","",COUNTIFS('Raw daily data'!$I:$I,$A14,'Raw daily data'!$F:$F,"<0")) | Q14: =IF($A14="","",SUMIFS('Raw daily data'!$F:$F,'Raw daily data'!$I:$I,$A14,'Raw daily data'!$F:$F,">0")) | R14: =IF($A14="","",ABS(SUMIFS('Raw daily data'!$F:$F,'Raw daily data'!$I:$I,$A14,'Raw daily data'!$F:$F,"<0"))) | S14: =IF($A14="","",IF(N14>0,O14/N14,"")) | T14: =IF($A14="","",IF(R14>0,Q14/ABS(R14),"")) | U14: =IF($A14="","",IF(F14>0,H14/F14,"")) | V14: =IF($A14="","",IFERROR(IF(H14<0,MIN(ABS(H14)/G14,1),0),"")) | W14: =IF($A14="","",_xlfn.MAXIFS('Raw daily data'!$J:$J,'Raw daily data'!$I:$I,$A14)) | X14: =IF($A14="","",IFERROR(IF(W14>=0,0,ABS(W14)/G14),"")) | Y14: =IF($A14="","",IFERROR(ABS(MIN(0,_xlfn.MINIFS('Raw daily data'!$J:$J,'Raw daily data'!$I:$I,$A14)))/G14,""))
C15: =IF($A15="","",TEXT($A15,"dddd")) | E15: =IF($A15="","", E14+H14) | F15: =IF($A15="","",$E15*Summary!$B$8) | G15: =IF($A15="","",F15*Summary!$B$9) | H15: =IF($A15="","",SUMIFS('Raw daily data'!$F:$F,'Raw daily data'!$I:$I,$A15)) | I15: =IF($A15="","", I14+H15) | J15: =IF($A15="","",SUMIF($B$2:$B$100,B15,$H$2:$H$100)) | K15: =IF($A15="","",Summary!$B$6) | L15: =IF($A15="","",IFERROR(J15-K15,"")) | N15: =IF($A15="","",COUNTIFS('Raw daily data'!$I:$I,$A15)) | O15: =IF($A15="","",COUNTIFS('Raw daily data'!$I:$I,$A15,'Raw daily data'!$F:$F,">0")) | P15: =IF($A15="","",COUNTIFS('Raw daily data'!$I:$I,$A15,'Raw daily data'!$F:$F,"<0")) | Q15: =IF($A15="","",SUMIFS('Raw daily data'!$F:$F,'Raw daily data'!$I:$I,$A15,'Raw daily data'!$F:$F,">0")) | R15: =IF($A15="","",ABS(SUMIFS('Raw daily data'!$F:$F,'Raw daily data'!$I:$I,$A15,'Raw daily data'!$F:$F,"<0"))) | S15: =IF($A15="","",IF(N15>0,O15/N15,"")) | T15: =IF($A15="","",IF(R15>0,Q15/ABS(R15),"")) | U15: =IF($A15="","",IF(F15>0,H15/F15,"")) | V15: =IF($A15="","",IFERROR(IF(H15<0,MIN(ABS(H15)/G15,1),0),"")) | W15: =IF($A15="","",_xlfn.MAXIFS('Raw daily data'!$J:$J,'Raw daily data'!$I:$I,$A15)) | X15: =IF($A15="","",IFERROR(IF(W15>=0,0,ABS(W15)/G15),"")) | Y15: =IF($A15="","",IFERROR(ABS(MIN(0,_xlfn.MINIFS('Raw daily data'!$J:$J,'Raw daily data'!$I:$I,$A15)))/G15,""))
C16: =IF($A16="","",TEXT($A16,"dddd")) | E16: =IF($A16="","", E15+H15) | F16: =IF($A16="","",$E16*Summary!$B$8) | G16: =IF($A16="","",F16*Summary!$B$9) | H16: =IF($A16="","",SUMIFS('Raw daily data'!$F:$F,'Raw daily data'!$I:$I,$A16)) | I16: =IF($A16="","", I15+H16) | J16: =IF($A16="","",SUMIF($B$2:$B$100,B16,$H$2:$H$100)) | K16: =IF($A16="","",Summary!$B$6) | L16: =IF($A16="","",IFERROR(J16-K16,"")) | N16: =IF($A16="","",COUNTIFS('Raw daily data'!$I:$I,$A16)) | O16: =IF($A16="","",COUNTIFS('Raw daily data'!$I:$I,$A16,'Raw daily data'!$F:$F,">0")) | P16: =IF($A16="","",COUNTIFS('Raw daily data'!$I:$I,$A16,'Raw daily data'!$F:$F,"<0")) | Q16: =IF($A16="","",SUMIFS('Raw daily data'!$F:$F,'Raw daily data'!$I:$I,$A16,'Raw daily data'!$F:$F,">0")) | R16: =IF($A16="","",ABS(SUMIFS('Raw daily data'!$F:$F,'Raw daily data'!$I:$I,$A16,'Raw daily data'!$F:$F,"<0"))) | S16: =IF($A16="","",IF(N16>0,O16/N16,"")) | T16: =IF($A16="","",IF(R16>0,Q16/ABS(R16),"")) | U16: =IF($A16="","",IF(F16>0,H16/F16,"")) | V16: =IF($A16="","",IFERROR(IF(H16<0,MIN(ABS(H16)/G16,1),0),"")) | W16: =IF($A16="","",_xlfn.MAXIFS('Raw daily data'!$J:$J,'Raw daily data'!$I:$I,$A16)) | X16: =IF($A16="","",IFERROR(IF(W16>=0,0,ABS(W16)/G16),"")) | Y16: =IF($A16="","",IFERROR(ABS(MIN(0,_xlfn.MINIFS('Raw daily data'!$J:$J,'Raw daily data'!$I:$I,$A16)))/G16,""))
C17: =IF($A17="","",TEXT($A17,"dddd")) | E17: =IF($A17="","", E16+H16) | F17: =IF($A17="","",$E17*Summary!$B$8) | G17: =IF($A17="","",F17*Summary!$B$9) | H17: =IF($A17="","",SUMIFS('Raw daily data'!$F:$F,'Raw daily data'!$I:$I,$A17)) | I17: =IF($A17="","", I16+H17) | J17: =IF($A17="","",SUMIF($B$2:$B$100,B17,$H$2:$H$100)) | K17: =IF($A17="","",Summary!$B$6) | L17: =IF($A17="","",IFERROR(J17-K17,"")) | N17: =IF($A17="","",COUNTIFS('Raw daily data'!$I:$I,$A17)) | O17: =IF($A17="","",COUNTIFS('Raw daily data'!$I:$I,$A17,'Raw daily data'!$F:$F,">0")) | P17: =IF($A17="","",COUNTIFS('Raw daily data'!$I:$I,$A17,'Raw daily data'!$F:$F,"<0")) | Q17: =IF($A17="","",SUMIFS('Raw daily data'!$F:$F,'Raw daily data'!$I:$I,$A17,'Raw daily data'!$F:$F,">0")) | R17: =IF($A17="","",ABS(SUMIFS('Raw daily data'!$F:$F,'Raw daily data'!$I:$I,$A17,'Raw daily data'!$F:$F,"<0"))) | S17: =IF($A17="","",IF(N17>0,O17/N17,"")) | T17: =IF($A17="","",IF(R17>0,Q17/ABS(R17),"")) | U17: =IF($A17="","",IF(F17>0,H17/F17,"")) | V17: =IF($A17="","",IFERROR(IF(H17<0,MIN(ABS(H17)/G17,1),0),"")) | W17: =IF($A17="","",_xlfn.MAXIFS('Raw daily data'!$J:$J,'Raw daily data'!$I:$I,$A17)) | X17: =IF($A17="","",IFERROR(IF(W17>=0,0,ABS(W17)/G17),"")) | Y17: =IF($A17="","",IFERROR(ABS(MIN(0,_xlfn.MINIFS('Raw daily data'!$J:$J,'Raw daily data'!$I:$I,$A17)))/G17,""))
... C41: =IF($A41="","",TEXT($A41,"dddd")) | E41: =IF($A41="","", E40+H40) | F41: =IF($A41="","",$E41*Summary!$B$8) | G41: =IF($A41="","",F41*Summary!$B$9) | H41: =IF($A41="","",SUMIFS('Raw daily data'!$F:$F,'Raw daily data'!$I:$I,$A41)) | I41: =IF($A41="","", I40+H41) | J41: =IF($A41="","",SUMIF($B$2:$B$100,B41,$H$2:$H$100)) | K41: =IF($A41="","",Summary!$B$6) | L41: =IF($A41="","",IFERROR(J41-K41,"")) | N41: =IF($A41="","",COUNTIFS('Raw daily data'!$I:$I,$A41)) | O41: =IF($A41="","",COUNTIFS('Raw daily data'!$I:$I,$A41,'Raw daily data'!$F:$F,">0")) | P41: =IF($A41="","",COUNTIFS('Raw daily data'!$I:$I,$A41,'Raw daily data'!$F:$F,"<0")) | Q41: =IF($A41="","",SUMIFS('Raw daily data'!$F:$F,'Raw daily data'!$I:$I,$A41,'Raw daily data'!$F:$F,">0")) | R41: =IF($A41="","",ABS(SUMIFS('Raw daily data'!$F:$F,'Raw daily data'!$I:$I,$A41,'Raw daily data'!$F:$F,"<0"))) | S41: =IF($A41="","",IF(N41>0,O41/N41,"")) | T41: =IF($A41="","",IF(R41>0,Q41/ABS(R41),"")) | U41: =IF($A41="","",IF(F41>0,H41/F41,"")) | V41: =IF($A41="","",IFERROR(IF(H41<0,MIN(ABS(H41)/G41,1),0),"")) | W41: =IF($A41="","",_xlfn.MAXIFS('Raw daily data'!$J:$J,'Raw daily data'!$I:$I,$A41)) | X41: =IF($A41="","",IFERROR(IF(W41>=0,0,ABS(W41)/G41),"")) | Y41: =IF($A41="","",IFERROR(ABS(MIN(0,_xlfn.MINIFS('Raw daily data'!$J:$J,'Raw daily data'!$I:$I,$A41)))/G41,""))
C42: =IF($A42="","",TEXT($A42,"dddd")) | E42: =IF($A42="","", E41+H41) | F42: =IF($A42="","",$E42*Summary!$B$8) | G42: =IF($A42="","",F42*Summary!$B$9) | H42: =IF($A42="","",SUMIFS('Raw daily data'!$F:$F,'Raw daily data'!$I:$I,$A42)) | I42: =IF($A42="","", I41+H42) | J42: =IF($A42="","",SUMIF($B$2:$B$100,B42,$H$2:$H$100)) | K42: =IF($A42="","",Summary!$B$6) | L42: =IF($A42="","",IFERROR(J42-K42,"")) | N42: =IF($A42="","",COUNTIFS('Raw daily data'!$I:$I,$A42)) | O42: =IF($A42="","",COUNTIFS('Raw daily data'!$I:$I,$A42,'Raw daily data'!$F:$F,">0")) | P42: =IF($A42="","",COUNTIFS('Raw daily data'!$I:$I,$A42,'Raw daily data'!$F:$F,"<0")) | Q42: =IF($A42="","",SUMIFS('Raw daily data'!$F:$F,'Raw daily data'!$I:$I,$A42,'Raw daily data'!$F:$F,">0")) | R42: =IF($A42="","",ABS(SUMIFS('Raw daily data'!$F:$F,'Raw daily data'!$I:$I,$A42,'Raw daily data'!$F:$F,"<0"))) | S42: =IF($A42="","",IF(N42>0,O42/N42,"")) | T42: =IF($A42="","",IF(R42>0,Q42/ABS(R42),"")) | U42: =IF($A42="","",IF(F42>0,H42/F42,"")) | V42: =IF($A42="","",IFERROR(IF(H42<0,MIN(ABS(H42)/G42,1),0),"")) | W42: =IF($A42="","",_xlfn.MAXIFS('Raw daily data'!$J:$J,'Raw daily data'!$I:$I,$A42)) | X42: =IF($A42="","",IF(W42>=0,0,ABS(W42)/G42)) | Y42: =IFERROR(IF($A42="","",ABS(MIN(0,_xlfn.MINIFS('Raw daily data'!$J:$J,'Raw daily data'!$I:$I,$A42)))/G42),"")
C43: =IF($A43="","",TEXT($A43,"dddd")) | E43: =IF($A43="","", E42+H42) | F43: =IF($A43="","",$E43*Summary!$B$8) | G43: =IF($A43="","",F43*Summary!$B$9) | H43: =IF($A43="","",SUMIFS('Raw daily data'!$F:$F,'Raw daily data'!$I:$I,$A43)) | I43: =IF($A43="","", I42+H43) | J43: =IF($A43="","",SUMIF($B$2:$B$100,B43,$H$2:$H$100)) | K43: =IF($A43="","",Summary!$B$6) | L43: =IF($A43="","",IFERROR(J43-K43,"")) | N43: =IF($A43="","",COUNTIFS('Raw daily data'!$I:$I,$A43)) | O43: =IF($A43="","",COUNTIFS('Raw daily data'!$I:$I,$A43,'Raw daily data'!$F:$F,">0")) | P43: =IF($A43="","",COUNTIFS('Raw daily data'!$I:$I,$A43,'Raw daily data'!$F:$F,"<0")) | Q43: =IF($A43="","",SUMIFS('Raw daily data'!$F:$F,'Raw daily data'!$I:$I,$A43,'Raw daily data'!$F:$F,">0")) | R43: =IF($A43="","",ABS(SUMIFS('Raw daily data'!$F:$F,'Raw daily data'!$I:$I,$A43,'Raw daily data'!$F:$F,"<0"))) | S43: =IF($A43="","",IF(N43>0,O43/N43,"")) | T43: =IF($A43="","",IF(R43>0,Q43/ABS(R43),"")) | U43: =IF($A43="","",IF(F43>0,H43/F43,"")) | V43: =IF($A43="","",IFERROR(IF(H43<0,MIN(ABS(H43)/G43,1),0),"")) | W43: =IF($A43="","",_xlfn.MAXIFS('Raw daily data'!$J:$J,'Raw daily data'!$I:$I,$A43)) | X43: =IF($A43="","",IF(W43>=0,0,ABS(W43)/G43)) | Y43: =IFERROR(IF($A43="","",ABS(MIN(0,_xlfn.MINIFS('Raw daily data'!$J:$J,'Raw daily data'!$I:$I,$A43)))/G43),"")
C44: =IF($A44="","",TEXT($A44,"dddd")) | E44: =IF($A44="","", E43+H43) | F44: =IF($A44="","",$E44*Summary!$B$8) | G44: =IF($A44="","",F44*Summary!$B$9) | H44: =IF($A44="","",SUMIFS('Raw daily data'!$F:$F,'Raw daily data'!$I:$I,$A44)) | I44: =IF($A44="","", I43+H44) | J44: =IF($A44="","",SUMIF($B$2:$B$100,B44,$H$2:$H$100)) | K44: =IF($A44="","",Summary!$B$6) | L44: =IF($A44="","",IFERROR(J44-K44,"")) | N44: =IF($A44="","",COUNTIFS('Raw daily data'!$I:$I,$A44)) | O44: =IF($A44="","",COUNTIFS('Raw daily data'!$I:$I,$A44,'Raw daily data'!$F:$F,">0")) | P44: =IF($A44="","",COUNTIFS('Raw daily data'!$I:$I,$A44,'Raw daily data'!$F:$F,"<0")) | Q44: =IF($A44="","",SUMIFS('Raw daily data'!$F:$F,'Raw daily data'!$I:$I,$A44,'Raw daily data'!$F:$F,">0")) | R44: =IF($A44="","",ABS(SUMIFS('Raw daily data'!$F:$F,'Raw daily data'!$I:$I,$A44,'Raw daily data'!$F:$F,"<0"))) | S44: =IF($A44="","",IF(N44>0,O44/N44,"")) | T44: =IF($A44="","",IF(R44>0,Q44/ABS(R44),"")) | U44: =IF($A44="","",IF(F44>0,H44/F44,"")) | V44: =IF($A44="","",IFERROR(IF(H44<0,MIN(ABS(H44)/G44,1),0),"")) | W44: =IF($A44="","",_xlfn.MAXIFS('Raw daily data'!$J:$J,'Raw daily data'!$I:$I,$A44)) | X44: =IF($A44="","",IF(W44>=0,0,ABS(W44)/G44)) | Y44: =IFERROR(IF($A44="","",ABS(MIN(0,_xlfn.MINIFS('Raw daily data'!$J:$J,'Raw daily data'!$I:$I,$A44)))/G44),"")
C45: =IF($A45="","",TEXT($A45,"dddd")) | E45: =IF($A45="","", E44+H44) | F45: =IF($A45="","",$E45*Summary!$B$8) | G45: =IF($A45="","",F45*Summary!$B$9) | H45: =IF($A45="","",SUMIFS('Raw daily data'!$F:$F,'Raw daily data'!$I:$I,$A45)) | I45: =IF($A45="","", I44+H45) | J45: =IF($A45="","",SUMIF($B$2:$B$100,B45,$H$2:$H$100)) | K45: =IF($A45="","",Summary!$B$6) | L45: =IF($A45="","",IFERROR(J45-K45,"")) | N45: =IF($A45="","",COUNTIFS('Raw daily data'!$I:$I,$A45)) | O45: =IF($A45="","",COUNTIFS('Raw daily data'!$I:$I,$A45,'Raw daily data'!$F:$F,">0")) | P45: =IF($A45="","",COUNTIFS('Raw daily data'!$I:$I,$A45,'Raw daily data'!$F:$F,"<0")) | Q45: =IF($A45="","",SUMIFS('Raw daily data'!$F:$F,'Raw daily data'!$I:$I,$A45,'Raw daily data'!$F:$F,">0")) | R45: =IF($A45="","",ABS(SUMIFS('Raw daily data'!$F:$F,'Raw daily data'!$I:$I,$A45,'Raw daily data'!$F:$F,"<0"))) | S45: =IF($A45="","",IF(N45>0,O45/N45,"")) | T45: =IF($A45="","",IF(R45>0,Q45/ABS(R45),"")) | U45: =IF($A45="","",IF(F45>0,H45/F45,"")) | V45: =IF($A45="","",IFERROR(IF(H45<0,MIN(ABS(H45)/G45,1),0),"")) | W45: =IF($A45="","",_xlfn.MAXIFS('Raw daily data'!$J:$J,'Raw daily data'!$I:$I,$A45)) | X45: =IF($A45="","",IF(W45>=0,0,ABS(W45)/G45)) | Y45: =IFERROR(IF($A45="","",ABS(MIN(0,_xlfn.MINIFS('Raw daily data'!$J:$J,'Raw daily data'!$I:$I,$A45)))/G45),"")
C46: =IF($A46="","",TEXT($A46,"dddd")) | E46: =IF($A46="","", E45+H45) | F46: =IF($A46="","",$E46*Summary!$B$8) | G46: =IF($A46="","",F46*Summary!$B$9) | H46: =IF($A46="","",SUMIFS('Raw daily data'!$F:$F,'Raw daily data'!$I:$I,$A46)) | I46: =IF($A46="","", I45+H46) | J46: =IF($A46="","",SUMIF($B$2:$B$100,B46,$H$2:$H$100)) | K46: =IF($A46="","",Summary!$B$6) | L46: =IF($A46="","",IFERROR(J46-K46,"")) | N46: =IF($A46="","",COUNTIFS('Raw daily data'!$I:$I,$A46)) | O46: =IF($A46="","",COUNTIFS('Raw daily data'!$I:$I,$A46,'Raw daily data'!$F:$F,">0")) | P46: =IF($A46="","",COUNTIFS('Raw daily data'!$I:$I,$A46,'Raw daily data'!$F:$F,"<0")) | Q46: =IF($A46="","",SUMIFS('Raw daily data'!$F:$F,'Raw daily data'!$I:$I,$A46,'Raw daily data'!$F:$F,">0")) | R46: =IF($A46="","",ABS(SUMIFS('Raw daily data'!$F:$F,'Raw daily data'!$I:$I,$A46,'Raw daily data'!$F:$F,"<0"))) | S46: =IF($A46="","",IF(N46>0,O46/N46,"")) | T46: =IF($A46="","",IF(R46>0,Q46/ABS(R46),"")) | U46: =IF($A46="","",IF(F46>0,H46/F46,"")) | V46: =IF($A46="","",IFERROR(IF(H46<0,MIN(ABS(H46)/G46,1),0),"")) | W46: =IF($A46="","",_xlfn.MAXIFS('Raw daily data'!$J:$J,'Raw daily data'!$I:$I,$A46)) | X46: =IF($A46="","",IF(W46>=0,0,ABS(W46)/G46)) | Y46: =IFERROR(IF($A46="","",ABS(MIN(0,_xlfn.MINIFS('Raw daily data'!$J:$J,'Raw daily data'!$I:$I,$A46)))/G46),"")
C47: =IF($A47="","",TEXT($A47,"dddd")) | E47: =IF($A47="","", E46+H46) | F47: =IF($A47="","",$E47*Summary!$B$8) | G47: =IF($A47="","",F47*Summary!$B$9) | H47: =IF($A47="","",SUMIFS('Raw daily data'!$F:$F,'Raw daily data'!$I:$I,$A47)) | I47: =IF($A47="","", I46+H47) | J47: =IF($A47="","",SUMIF($B$2:$B$100,B47,$H$2:$H$100)) | K47: =IF($A47="","",Summary!$B$6) | L47: =IF($A47="","",IFERROR(J47-K47,"")) | N47: =IF($A47="","",COUNTIFS('Raw daily data'!$I:$I,$A47)) | O47: =IF($A47="","",COUNTIFS('Raw daily data'!$I:$I,$A47,'Raw daily data'!$F:$F,">0")) | P47: =IF($A47="","",COUNTIFS('Raw daily data'!$I:$I,$A47,'Raw daily data'!$F:$F,"<0")) | Q47: =IF($A47="","",SUMIFS('Raw daily data'!$F:$F,'Raw daily data'!$I:$I,$A47,'Raw daily data'!$F:$F,">0")) | R47: =IF($A47="","",ABS(SUMIFS('Raw daily data'!$F:$F,'Raw daily data'!$I:$I,$A47,'Raw daily data'!$F:$F,"<0"))) | S47: =IF($A47="","",IF(N47>0,O47/N47,"")) | T47: =IF($A47="","",IF(R47>0,Q47/ABS(R47),"")) | U47: =IF($A47="","",IF(F47>0,H47/F47,"")) | V47: =IF($A47="","",IFERROR(IF(H47<0,MIN(ABS(H47)/G47,1),0),"")) | W47: =IF($A47="","",_xlfn.MAXIFS('Raw daily data'!$J:$J,'Raw daily data'!$I:$I,$A47)) | X47: =IF($A47="","",IF(W47>=0,0,ABS(W47)/G47)) | Y47: =IFERROR(IF($A47="","",ABS(MIN(0,_xlfn.MINIFS('Raw daily data'!$J:$J,'Raw daily data'!$I:$I,$A47)))/G47),"")
C48: =IF($A48="","",TEXT($A48,"dddd")) | E48: =IF($A48="","", E47+H47) | F48: =IF($A48="","",$E48*Summary!$B$8) | G48: =IF($A48="","",F48*Summary!$B$9) | H48: =IF($A48="","",SUMIFS('Raw daily data'!$F:$F,'Raw daily data'!$I:$I,$A48)) | I48: =IF($A48="","", I47+H48) | J48: =IF($A48="","",SUMIF($B$2:$B$100,B48,$H$2:$H$100)) | K48: =IF($A48="","",Summary!$B$6) | L48: =IF($A48="","",IFERROR(J48-K48,"")) | N48: =IF($A48="","",COUNTIFS('Raw daily data'!$I:$I,$A48)) | O48: =IF($A48="","",COUNTIFS('Raw daily data'!$I:$I,$A48,'Raw daily data'!$F:$F,">0")) | P48: =IF($A48="","",COUNTIFS('Raw daily data'!$I:$I,$A48,'Raw daily data'!$F:$F,"<0")) | Q48: =IF($A48="","",SUMIFS('Raw daily data'!$F:$F,'Raw daily data'!$I:$I,$A48,'Raw daily data'!$F:$F,">0")) | R48: =IF($A48="","",ABS(SUMIFS('Raw daily data'!$F:$F,'Raw daily data'!$I:$I,$A48,'Raw daily data'!$F:$F,"<0"))) | S48: =IF($A48="","",IF(N48>0,O48/N48,"")) | T48: =IF($A48="","",IF(R48>0,Q48/ABS(R48),"")) | U48: =IF($A48="","",IF(F48>0,H48/F48,"")) | V48: =IF($A48="","",IFERROR(IF(H48<0,MIN(ABS(H48)/G48,1),0),"")) | W48: =IF($A48="","",_xlfn.MAXIFS('Raw daily data'!$J:$J,'Raw daily data'!$I:$I,$A48)) | X48: =IF($A48="","",IF(W48>=0,0,ABS(W48)/G48)) | Y48: =IFERROR(IF($A48="","",ABS(MIN(0,_xlfn.MINIFS('Raw daily data'!$J:$J,'Raw daily data'!$I:$I,$A48)))/G48),"")
C49: =IF($A49="","",TEXT($A49,"dddd")) | E49: =IF($A49="","", E48+H48) | F49: =IF($A49="","",$E49*Summary!$B$8) | G49: =IF($A49="","",F49*Summary!$B$9) | H49: =IF($A49="","",SUMIFS('Raw daily data'!$F:$F,'Raw daily data'!$I:$I,$A49)) | I49: =IF($A49="","", I48+H49) | J49: =IF($A49="","",SUMIF($B$2:$B$100,B49,$H$2:$H$100)) | K49: =IF($A49="","",Summary!$B$6) | L49: =IF($A49="","",IFERROR(J49-K49,"")) | N49: =IF($A49="","",COUNTIFS('Raw daily data'!$I:$I,$A49)) | O49: =IF($A49="","",COUNTIFS('Raw daily data'!$I:$I,$A49,'Raw daily data'!$F:$F,">0")) | P49: =IF($A49="","",COUNTIFS('Raw daily data'!$I:$I,$A49,'Raw daily data'!$F:$F,"<0")) | Q49: =IF($A49="","",SUMIFS('Raw daily data'!$F:$F,'Raw daily data'!$I:$I,$A49,'Raw daily data'!$F:$F,">0")) | R49: =IF($A49="","",ABS(SUMIFS('Raw daily data'!$F:$F,'Raw daily data'!$I:$I,$A49,'Raw daily data'!$F:$F,"<0"))) | S49: =IF($A49="","",IF(N49>0,O49/N49,"")) | T49: =IF($A49="","",IF(R49>0,Q49/ABS(R49),"")) | U49: =IF($A49="","",IF(F49>0,H49/F49,"")) | V49: =IF($A49="","",IFERROR(IF(H49<0,MIN(ABS(H49)/G49,1),0),"")) | W49: =IF($A49="","",_xlfn.MAXIFS('Raw daily data'!$J:$J,'Raw daily data'!$I:$I,$A49)) | X49: =IF($A49="","",IF(W49>=0,0,ABS(W49)/G49)) | Y49: =IFERROR(IF($A49="","",ABS(MIN(0,_xlfn.MINIFS('Raw daily data'!$J:$J,'Raw daily data'!$I:$I,$A49)))/G49),"")
C50: =IF($A50="","",TEXT($A50,"dddd")) | E50: =IF($A50="","", E49+H49) | F50: =IF($A50="","",$E50*Summary!$B$8) | G50: =IF($A50="","",F50*Summary!$B$9) | H50: =IF($A50="","",SUMIFS('Raw daily data'!$F:$F,'Raw daily data'!$I:$I,$A50)) | I50: =IF($A50="","", I49+H50) | J50: =IF($A50="","",SUMIF($B$2:$B$100,B50,$H$2:$H$100)) | K50: =IF($A50="","",Summary!$B$6) | L50: =IF($A50="","",IFERROR(J50-K50,"")) | N50: =IF($A50="","",COUNTIFS('Raw daily data'!$I:$I,$A50)) | O50: =IF($A50="","",COUNTIFS('Raw daily data'!$I:$I,$A50,'Raw daily data'!$F:$F,">0")) | P50: =IF($A50="","",COUNTIFS('Raw daily data'!$I:$I,$A50,'Raw daily data'!$F:$F,"<0")) | Q50: =IF($A50="","",SUMIFS('Raw daily data'!$F:$F,'Raw daily data'!$I:$I,$A50,'Raw daily data'!$F:$F,">0")) | R50: =IF($A50="","",ABS(SUMIFS('Raw daily data'!$F:$F,'Raw daily data'!$I:$I,$A50,'Raw daily data'!$F:$F,"<0"))) | S50: =IF($A50="","",IF(N50>0,O50/N50,"")) | T50: =IF($A50="","",IF(R50>0,Q50/ABS(R50),"")) | U50: =IF($A50="","",IF(F50>0,H50/F50,"")) | V50: =IF($A50="","",IFERROR(IF(H50<0,MIN(ABS(H50)/G50,1),0),"")) | W50: =IF($A50="","",_xlfn.MAXIFS('Raw daily data'!$J:$J,'Raw daily data'!$I:$I,$A50)) | X50: =IF($A50="","",IF(W50>=0,0,ABS(W50)/G50)) | Y50: =IFERROR(IF($A50="","",ABS(MIN(0,_xlfn.MINIFS('Raw daily data'!$J:$J,'Raw daily data'!$I:$I,$A50)))/G50),"")
C51: =IF($A51="","",TEXT($A51,"dddd")) | E51: =IF($A51="","", E50+H50) | F51: =IF($A51="","",$E51*Summary!$B$8) | G51: =IF($A51="","",F51*Summary!$B$9) | H51: =IF($A51="","",SUMIFS('Raw daily data'!$F:$F,'Raw daily data'!$I:$I,$A51)) | I51: =IF($A51="","", I50+H51) | J51: =IF($A51="","",SUMIF($B$2:$B$100,B51,$H$2:$H$100)) | K51: =IF($A51="","",Summary!$B$6) | L51: =IF($A51="","",IFERROR(J51-K51,"")) | N51: =IF($A51="","",COUNTIFS('Raw daily data'!$I:$I,$A51)) | O51: =IF($A51="","",COUNTIFS('Raw daily data'!$I:$I,$A51,'Raw daily data'!$F:$F,">0")) | P51: =IF($A51="","",COUNTIFS('Raw daily data'!$I:$I,$A51,'Raw daily data'!$F:$F,"<0")) | Q51: =IF($A51="","",SUMIFS('Raw daily data'!$F:$F,'Raw daily data'!$I:$I,$A51,'Raw daily data'!$F:$F,">0")) | R51: =IF($A51="","",ABS(SUMIFS('Raw daily data'!$F:$F,'Raw daily data'!$I:$I,$A51,'Raw daily data'!$F:$F,"<0"))) | S51: =IF($A51="","",IF(N51>0,O51/N51,"")) | T51: =IF($A51="","",IF(R51>0,Q51/ABS(R51),"")) | U51: =IF($A51="","",IF(F51>0,H51/F51,"")) | V51: =IF($A51="","",IFERROR(IF(H51<0,MIN(ABS(H51)/G51,1),0),"")) | W51: =IF($A51="","",_xlfn.MAXIFS('Raw daily data'!$J:$J,'Raw daily data'!$I:$I,$A51)) | X51: =IF($A51="","",IF(W51>=0,0,ABS(W51)/G51)) | Y51: =IFERROR(IF($A51="","",ABS(MIN(0,_xlfn.MINIFS('Raw daily data'!$J:$J,'Raw daily data'!$I:$I,$A51)))/G51),"")
C52: =IF($A52="","",TEXT($A52,"dddd")) | E52: =IF($A52="","", E51+H51) | F52: =IF($A52="","",$E52*Summary!$B$8) | G52: =IF($A52="","",F52*Summary!$B$9) | H52: =IF($A52="","",SUMIFS('Raw daily data'!$F:$F,'Raw daily data'!$I:$I,$A52)) | I52: =IF($A52="","", I51+H52) | J52: =IF($A52="","",SUMIF($B$2:$B$100,B52,$H$2:$H$100)) | K52: =IF($A52="","",Summary!$B$6) | L52: =IF($A52="","",IFERROR(J52-K52,"")) | N52: =IF($A52="","",COUNTIFS('Raw daily data'!$I:$I,$A52)) | O52: =IF($A52="","",COUNTIFS('Raw daily data'!$I:$I,$A52,'Raw daily data'!$F:$F,">0")) | P52: =IF($A52="","",COUNTIFS('Raw daily data'!$I:$I,$A52,'Raw daily data'!$F:$F,"<0")) | Q52: =IF($A52="","",SUMIFS('Raw daily data'!$F:$F,'Raw daily data'!$I:$I,$A52,'Raw daily data'!$F:$F,">0")) | R52: =IF($A52="","",ABS(SUMIFS('Raw daily data'!$F:$F,'Raw daily data'!$I:$I,$A52,'Raw daily data'!$F:$F,"<0"))) | S52: =IF($A52="","",IF(N52>0,O52/N52,"")) | T52: =IF($A52="","",IF(R52>0,Q52/ABS(R52),"")) | U52: =IF($A52="","",IF(F52>0,H52/F52,"")) | V52: =IF($A52="","",IFERROR(IF(H52<0,MIN(ABS(H52)/G52,1),0),"")) | W52: =IF($A52="","",_xlfn.MAXIFS('Raw daily data'!$J:$J,'Raw daily data'!$I:$I,$A52)) | X52: =IF($A52="","",IF(W52>=0,0,ABS(W52)/G52)) | Y52: =IFERROR(IF($A52="","",ABS(MIN(0,_xlfn.MINIFS('Raw daily data'!$J:$J,'Raw daily data'!$I:$I,$A52)))/G52),"")
C53: =IF($A53="","",TEXT($A53,"dddd")) | E53: =IF($A53="","", E52+H52) | F53: =IF($A53="","",$E53*Summary!$B$8) | G53: =IF($A53="","",F53*Summary!$B$9) | H53: =IF($A53="","",SUMIFS('Raw daily data'!$F:$F,'Raw daily data'!$I:$I,$A53)) | I53: =IF($A53="","", I52+H53) | J53: =IF($A53="","",SUMIF($B$2:$B$100,B53,$H$2:$H$100)) | K53: =IF($A53="","",Summary!$B$6) | L53: =IF($A53="","",IFERROR(J53-K53,"")) | N53: =IF($A53="","",COUNTIFS('Raw daily data'!$I:$I,$A53)) | O53: =IF($A53="","",COUNTIFS('Raw daily data'!$I:$I,$A53,'Raw daily data'!$F:$F,">0")) | P53: =IF($A53="","",COUNTIFS('Raw daily data'!$I:$I,$A53,'Raw daily data'!$F:$F,"<0")) | Q53: =IF($A53="","",SUMIFS('Raw daily data'!$F:$F,'Raw daily data'!$I:$I,$A53,'Raw daily data'!$F:$F,">0")) | R53: =IF($A53="","",ABS(SUMIFS('Raw daily data'!$F:$F,'Raw daily data'!$I:$I,$A53,'Raw daily data'!$F:$F,"<0"))) | S53: =IF($A53="","",IF(N53>0,O53/N53,"")) | T53: =IF($A53="","",IF(R53>0,Q53/ABS(R53),"")) | U53: =IF($A53="","",IF(F53>0,H53/F53,"")) | V53: =IF($A53="","",IFERROR(IF(H53<0,MIN(ABS(H53)/G53,1),0),"")) | W53: =IF($A53="","",_xlfn.MAXIFS('Raw daily data'!$J:$J,'Raw daily data'!$I:$I,$A53)) | X53: =IF($A53="","",IF(W53>=0,0,ABS(W53)/G53)) | Y53: =IFERROR(IF($A53="","",ABS(MIN(0,_xlfn.MINIFS('Raw daily data'!$J:$J,'Raw daily data'!$I:$I,$A53)))/G53),"")
... C100: =IF($A100="","",TEXT($A100,"dddd")) | E100: =IF($A100="","", E99+H99) | F100: =IF($A100="","",$E100*Summary!$B$8) | G100: =IF($A100="","",F100*Summary!$B$9) | H100: =IF($A100="","",SUMIFS('Raw daily data'!$F:$F,'Raw daily data'!$I:$I,$A100)) | I100: =IF($A100="","", I99+H100) | J100: =IF($A100="","",SUMIF($B$2:$B$100,B100,$H$2:$H$100)) | K100: =IF($A100="","",Summary!$B$6) | L100: =IF($A100="","",IFERROR(J100-K100,"")) | N100: =IF($A100="","",COUNTIFS('Raw daily data'!$I:$I,$A100)) | O100: =IF($A100="","",COUNTIFS('Raw daily data'!$I:$I,$A100,'Raw daily data'!$F:$F,">0")) | P100: =IF($A100="","",COUNTIFS('Raw daily data'!$I:$I,$A100,'Raw daily data'!$F:$F,"<0")) | Q100: =IF($A100="","",SUMIFS('Raw daily data'!$F:$F,'Raw daily data'!$I:$I,$A100,'Raw daily data'!$F:$F,">0")) | R100: =IF($A100="","",ABS(SUMIFS('Raw daily data'!$F:$F,'Raw daily data'!$I:$I,$A100,'Raw daily data'!$F:$F,"<0"))) | S100: =IF($A100="","",IF(N100>0,O100/N100,"")) | T100: =IF($A100="","",IF(R100>0,Q100/ABS(R100),"")) | U100: =IF($A100="","",IF(F100>0,H100/F100,"")) | V100: =IF($A100="","",IFERROR(IF(H100<0,MIN(ABS(H100)/G100,1),0),"")) | W100: =IF($A100="","",_xlfn.MAXIFS('Raw daily data'!$J:$J,'Raw daily data'!$I:$I,$A100)) | X100: =IF($A100="","",IF(W100>=0,0,ABS(W100)/G100)) | Y100: =IFERROR(IF($A100="","",ABS(MIN(0,_xlfn.MINIFS('Raw daily data'!$J:$J,'Raw daily data'!$I:$I,$A100)))/G100),"")
C101: =IF($A101="","",TEXT($A101,"dddd")) | E101: =IF($A101="","",E41+H41)
C102: =IF($A102="","",TEXT($A102,"dddd")) | E102: =IF($A102="","",E101+H101)
C103: =IF($A103="","",TEXT($A103,"dddd")) | E103: =IF($A103="","",E102+H102)
C104: =IF($A104="","",TEXT($A104,"dddd")) | E104: =IF($A104="","",E103+H103)
C105: =IF($A105="","",TEXT($A105,"dddd")) | E105: =IF($A105="","",E104+H104)
C106: =IF($A106="","",TEXT($A106,"dddd")) | E106: =IF($A106="","",E105+H105)
C107: =IF($A107="","",TEXT($A107,"dddd")) | E107: =IF($A107="","",E106+H106)
C108: =IF($A108="","",TEXT($A108,"dddd")) | E108: =IF($A108="","",E107+H107)
C109: =IF($A109="","",TEXT($A109,"dddd")) | E109: =IF($A109="","",E108+H108)
...

Sheet Raw daily data
A1: Symbol ← Paste broker data into columns A–H only. Do not edit I–J → | B1: Name | C1: Side | D1: Quantity | E1: Price | F1: Profit | G1: Deal ID | H1: Time | I1: Trade Date | J1: Cumulative P&L for the day
A2: EURUSD | B2: EURUSD | C2: Buy | D2: 0.5 | E2: 1.156 | F2: 250 | G2: 101 | H2: Mon, 01 May 2026 09:00:00 GMT | I2: =IF(H2="","",IFERROR(IF(H2="","",IFERROR(IF(H2="","",IFERROR(IF(H2="","",IFERROR(IF(H2="","",IFERROR(IF(H2="","",IFERROR(IF(H2="","",IFERROR(IF(H2="","",IFERROR(IF(H2="","",IFERROR(IF(H2="","",IFERROR(IF(H2="","",IFERROR(IF(H2="","",IFERROR(IF(H2="","",IFERROR(IF(H2="","",IFERROR(IF(H2="","",IFERROR(IF(H2="","",IFERROR(IF(H2="","",IFERROR(IF(H2="","",IFERROR(IF(H2="","",IFERROR(IF(H2="","",IFERROR(IF(H2="","",IFERROR(IF(H2="","",IFERROR(IF(H2="","",IFERROR(IF(H2="","",IFERROR(IF(H2="","",IFERROR(IF(H2="","",IFERROR(IF(H2="","",IFERROR(IF(H2="","",IFERROR(IF(H2="","",IFERROR(IF(H2="","",IFERROR(IFERROR(IF(H2="","",DATEVALUE(MID(H2,6,11))),"Check date format"),"")),"")),"")),"")),"")),"")),"")),"")),"")),"")),"")),"")),"")),"")),"")),"")),"")),"")),"")),"")),"")),"")),"")),"")),"")),"")),"")),"")),"")),"")) -> 46143 | J2: =IF(OR(F2="",I2=""),"",F2+IF(I2=I1,N(J1),0)) -> 250
A3: EURUSD | B3: EURUSD | C3: Sell | D3: 1 | E3: 1.16 | F3: -100 | G3: 102 | H3: Tue, 09 May 2026 10:00:00 GMT | I3: =IF(H3="","",IFERROR(IF(H3="","",IFERROR(IF(H3="","",IFERROR(IF(H3="","",IFERROR(IF(H3="","",IFERROR(IF(H3="","",IFERROR(IF(H3="","",IFERROR(IF(H3="","",IFERROR(IF(H3="","",IFERROR(IF(H3="","",IFERROR(IF(H3="","",IFERROR(IF(H3="","",IFERROR(IF(H3="","",IFERROR(IF(H3="","",IFERROR(IF(H3="","",IFERROR(IF(H3="","",IFERROR(IF(H3="","",IFERROR(IF(H3="","",IFERROR(IF(H3="","",IFERROR(IF(H3="","",IFERROR(IF(H3="","",IFERROR(IF(H3="","",IFERROR(IF(H3="","",IFERROR(IF(H3="","",IFERROR(IF(H3="","",IFERROR(IF(H3="","",IFERROR(IF(H3="","",IFERROR(IF(H3="","",IFERROR(IF(H3="","",IFERROR(IF(H3="","",IFERROR(IFERROR(IF(H3="","",DATEVALUE(MID(H3,6,11))),"Check date format"),"")),"")),"")),"")),"")),"")),"")),"")),"")),"")),"")),"")),"")),"")),"")),"")),"")),"")),"")),"")),"")),"")),"")),"")),"")),"")),"")),"")),"")),"")) -> 46151 | J3: =IF(OR(F3="",I3=""),"",F3+IF(I3=I2,N(J2),0)) -> -100
A4: EURUSD | B4: EURUSD | C4: Sell | D4: 1 | E4: 1.162 | F4: -100 | G4: 103 | H4: Tue, 09 May 2026 15:00:00 GMT | I4: =IF(H4="","",IFERROR(IF(H4="","",IFERROR(IF(H4="","",IFERROR(IF(H4="","",IFERROR(IF(H4="","",IFERROR(IF(H4="","",IFERROR(IF(H4="","",IFERROR(IF(H4="","",IFERROR(IF(H4="","",IFERROR(IF(H4="","",IFERROR(IF(H4="","",IFERROR(IF(H4="","",IFERROR(IF(H4="","",IFERROR(IF(H4="","",IFERROR(IF(H4="","",IFERROR(IF(H4="","",IFERROR(IF(H4="","",IFERROR(IF(H4="","",IFERROR(IF(H4="","",IFERROR(IF(H4="","",IFERROR(IF(H4="","",IFERROR(IF(H4="","",IFERROR(IF(H4="","",IFERROR(IF(H4="","",IFERROR(IF(H4="","",IFERROR(IF(H4="","",IFERROR(IF(H4="","",IFERROR(IF(H4="","",IFERROR(IF(H4="","",IFERROR(IF(H4="","",IFERROR(IFERROR(IF(H4="","",DATEVALUE(MID(H4,6,11))),"Check date format"),"")),"")),"")),"")),"")),"")),"")),"")),"")),"")),"")),"")),"")),"")),"")),"")),"")),"")),"")),"")),"")),"")),"")),"")),"")),"")),"")),"")),"")),"")) -> 46151 | J4: =IF(OR(F4="",I4=""),"",F4+IF(I4=I3,N(J3),0)) -> -200
A5: EURUSD | B5: EURUSD | C5: Buy | D5: 2 | E5: 1.15 | F5: 800 | G5: 104 | H5: Wed, 17 May 2026 09:00:00 GMT | I5: =IF(H5="","",IFERROR(IF(H5="","",IFERROR(IF(H5="","",IFERROR(IF(H5="","",IFERROR(IF(H5="","",IFERROR(IF(H5="","",IFERROR(IF(H5="","",IFERROR(IF(H5="","",IFERROR(IF(H5="","",IFERROR(IF(H5="","",IFERROR(IF(H5="","",IFERROR(IF(H5="","",IFERROR(IF(H5="","",IFERROR(IF(H5="","",IFERROR(IF(H5="","",IFERROR(IF(H5="","",IFERROR(IF(H5="","",IFERROR(IF(H5="","",IFERROR(IF(H5="","",IFERROR(IF(H5="","",IFERROR(IF(H5="","",IFERROR(IF(H5="","",IFERROR(IF(H5="","",IFERROR(IF(H5="","",IFERROR(IF(H5="","",IFERROR(IF(H5="","",IFERROR(IF(H5="","",IFERROR(IF(H5="","",IFERROR(IF(H5="","",IFERROR(IF(H5="","",IFERROR(IFERROR(IF(H5="","",DATEVALUE(MID(H5,6,11))),"Check date format"),"")),"")),"")),"")),"")),"")),"")),"")),"")),"")),"")),"")),"")),"")),"")),"")),"")),"")),"")),"")),"")),"")),"")),"")),"")),"")),"")),"")),"")),"")) -> 46159 | J5: =IF(OR(F5="",I5=""),"",F5+IF(I5=I4,N(J4),0)) -> 800
A6: EURUSD | B6: EURUSD | C6: Buy | D6: 1 | E6: 1.155 | F6: 200 | G6: 105 | H6: Thu, 18 May 2026 14:00:00 GMT | I6: =IF(H6="","",IFERROR(IF(H6="","",IFERROR(IF(H6="","",IFERROR(IF(H6="","",IFERROR(IF(H6="","",IFERROR(IF(H6="","",IFERROR(IF(H6="","",IFERROR(IF(H6="","",IFERROR(IF(H6="","",IFERROR(IF(H6="","",IFERROR(IF(H6="","",IFERROR(IF(H6="","",IFERROR(IF(H6="","",IFERROR(IF(H6="","",IFERROR(IF(H6="","",IFERROR(IF(H6="","",IFERROR(IF(H6="","",IFERROR(IF(H6="","",IFERROR(IF(H6="","",IFERROR(IF(H6="","",IFERROR(IF(H6="","",IFERROR(IF(H6="","",IFERROR(IF(H6="","",IFERROR(IF(H6="","",IFERROR(IF(H6="","",IFERROR(IF(H6="","",IFERROR(IF(H6="","",IFERROR(IF(H6="","",IFERROR(IF(H6="","",IFERROR(IF(H6="","",IFERROR(IFERROR(IF(H6="","",DATEVALUE(MID(H6,6,11))),"Check date format"),"")),"")),"")),"")),"")),"")),"")),"")),"")),"")),"")),"")),"")),"")),"")),"")),"")),"")),"")),"")),"")),"")),"")),"")),"")),"")),"")),"")),"")),"")) -> 46160 | J6: =IF(OR(F6="",I6=""),"",F6+IF(I6=I5,N(J5),0)) -> 200
I7: =IF(H7="","",IFERROR(IF(H7="","",IFERROR(IF(H7="","",IFERROR(IF(H7="","",IFERROR(IF(H7="","",IFERROR(IF(H7="","",IFERROR(IF(H7="","",IFERROR(IF(H7="","",IFERROR(IF(H7="","",IFERROR(IF(H7="","",IFERROR(IF(H7="","",IFERROR(IF(H7="","",IFERROR(IF(H7="","",IFERROR(IF(H7="","",IFERROR(IF(H7="","",IFERROR(IF(H7="","",IFERROR(IF(H7="","",IFERROR(IF(H7="","",IFERROR(IF(H7="","",IFERROR(IF(H7="","",IFERROR(IF(H7="","",IFERROR(IF(H7="","",IFERROR(IF(H7="","",IFERROR(IF(H7="","",IFERROR(IF(H7="","",IFERROR(IF(H7="","",IFERROR(IF(H7="","",IFERROR(IF(H7="","",IFERROR(IF(H7="","",IFERROR(IF(H7="","",IFERROR(IFERROR(IF(H7="","",DATEVALUE(MID(H7,6,11))),"Check date format"),"")),"")),"")),"")),"")),"")),"")),"")),"")),"")),"")),"")),"")),"")),"")),"")),"")),"")),"")),"")),"")),"")),"")),"")),"")),"")),"")),"")),"")),"")) | J7: =IF(OR(F7="",I7=""),"",F7+IF(I7=I6,N(J6),0))
I8: =IF(H8="","",IFERROR(IF(H8="","",IFERROR(IF(H8="","",IFERROR(IF(H8="","",IFERROR(IF(H8="","",IFERROR(IF(H8="","",IFERROR(IF(H8="","",IFERROR(IF(H8="","",IFERROR(IF(H8="","",IFERROR(IF(H8="","",IFERROR(IF(H8="","",IFERROR(IF(H8="","",IFERROR(IF(H8="","",IFERROR(IF(H8="","",IFERROR(IF(H8="","",IFERROR(IF(H8="","",IFERROR(IF(H8="","",IFERROR(IF(H8="","",IFERROR(IF(H8="","",IFERROR(IF(H8="","",IFERROR(IF(H8="","",IFERROR(IF(H8="","",IFERROR(IF(H8="","",IFERROR(IF(H8="","",IFERROR(IF(H8="","",IFERROR(IF(H8="","",IFERROR(IF(H8="","",IFERROR(IF(H8="","",IFERROR(IF(H8="","",IFERROR(IF(H8="","",IFERROR(IFERROR(IF(H8="","",DATEVALUE(MID(H8,6,11))),"Check date format"),"")),"")),"")),"")),"")),"")),"")),"")),"")),"")),"")),"")),"")),"")),"")),"")),"")),"")),"")),"")),"")),"")),"")),"")),"")),"")),"")),"")),"")),"")) | J8: =IF(OR(F8="",I8=""),"",F8+IF(I8=I7,N(J7),0))
I9: =IF(H9="","",IFERROR(IF(H9="","",IFERROR(IF(H9="","",IFERROR(IF(H9="","",IFERROR(IF(H9="","",IFERROR(IF(H9="","",IFERROR(IF(H9="","",IFERROR(IF(H9="","",IFERROR(IF(H9="","",IFERROR(IF(H9="","",IFERROR(IF(H9="","",IFERROR(IF(H9="","",IFERROR(IF(H9="","",IFERROR(IF(H9="","",IFERROR(IF(H9="","",IFERROR(IF(H9="","",IFERROR(IF(H9="","",IFERROR(IF(H9="","",IFERROR(IF(H9="","",IFERROR(IF(H9="","",IFERROR(IF(H9="","",IFERROR(IF(H9="","",IFERROR(IF(H9="","",IFERROR(IF(H9="","",IFERROR(IF(H9="","",IFERROR(IF(H9="","",IFERROR(IF(H9="","",IFERROR(IF(H9="","",IFERROR(IF(H9="","",IFERROR(IF(H9="","",IFERROR(IFERROR(IF(H9="","",DATEVALUE(MID(H9,6,11))),"Check date format"),"")),"")),"")),"")),"")),"")),"")),"")),"")),"")),"")),"")),"")),"")),"")),"")),"")),"")),"")),"")),"")),"")),"")),"")),"")),"")),"")),"")),"")),"")) | J9: =IF(OR(F9="",I9=""),"",F9+IF(I9=I8,N(J8),0))
I10: =IF(H10="","",IFERROR(IF(H10="","",IFERROR(IF(H10="","",IFERROR(IF(H10="","",IFERROR(IF(H10="","",IFERROR(IF(H10="","",IFERROR(IF(H10="","",IFERROR(IF(H10="","",IFERROR(IF(H10="","",IFERROR(IF(H10="","",IFERROR(IF(H10="","",IFERROR(IF(H10="","",IFERROR(IF(H10="","",IFERROR(IF(H10="","",IFERROR(IF(H10="","",IFERROR(IF(H10="","",IFERROR(IF(H10="","",IFERROR(IF(H10="","",IFERROR(IF(H10="","",IFERROR(IF(H10="","",IFERROR(IF(H10="","",IFERROR(IF(H10="","",IFERROR(IF(H10="","",IFERROR(IF(H10="","",IFERROR(IF(H10="","",IFERROR(IF(H10="","",IFERROR(IF(H10="","",IFERROR(IF(H10="","",IFERROR(IF(H10="","",IFERROR(IF(H10="","",IFERROR(IFERROR(IF(H10="","",DATEVALUE(MID(H10,6,11))),"Check date format"),"")),"")),"")),"")),"")),"")),"")),"")),"")),"")),"")),"")),"")),"")),"")),"")),"")),"")),"")),"")),"")),"")),"")),"")),"")),"")),"")),"")),"")),"")) | J10: =IF(OR(F10="",I10=""),"",F10+IF(I10=I9,N(J9),0))
I11: =IF(H11="","",IFERROR(IF(H11="","",IFERROR(IF(H11="","",IFERROR(IF(H11="","",IFERROR(IF(H11="","",IFERROR(IF(H11="","",IFERROR(IF(H11="","",IFERROR(IF(H11="","",IFERROR(IF(H11="","",IFERROR(IF(H11="","",IFERROR(IF(H11="","",IFERROR(IF(H11="","",IFERROR(IF(H11="","",IFERROR(IF(H11="","",IFERROR(IF(H11="","",IFERROR(IF(H11="","",IFERROR(IF(H11="","",IFERROR(IF(H11="","",IFERROR(IF(H11="","",IFERROR(IF(H11="","",IFERROR(IF(H11="","",IFERROR(IF(H11="","",IFERROR(IF(H11="","",IFERROR(IF(H11="","",IFERROR(IF(H11="","",IFERROR(IF(H11="","",IFERROR(IF(H11="","",IFERROR(IF(H11="","",IFERROR(IF(H11="","",IFERROR(IF(H11="","",IFERROR(IFERROR(IF(H11="","",DATEVALUE(MID(H11,6,11))),"Check date format"),"")),"")),"")),"")),"")),"")),"")),"")),"")),"")),"")),"")),"")),"")),"")),"")),"")),"")),"")),"")),"")),"")),"")),"")),"")),"")),"")),"")),"")),"")) | J11: =IF(OR(F11="",I11=""),"",F11+IF(I11=I10,N(J10),0))
I12: =IF(H12="","",IFERROR(IF(H12="","",IFERROR(IF(H12="","",IFERROR(IF(H12="","",IFERROR(IF(H12="","",IFERROR(IF(H12="","",IFERROR(IF(H12="","",IFERROR(IF(H12="","",IFERROR(IF(H12="","",IFERROR(IF(H12="","",IFERROR(IF(H12="","",IFERROR(IF(H12="","",IFERROR(IF(H12="","",IFERROR(IF(H12="","",IFERROR(IF(H12="","",IFERROR(IF(H12="","",IFERROR(IF(H12="","",IFERROR(IF(H12="","",IFERROR(IF(H12="","",IFERROR(IF(H12="","",IFERROR(IF(H12="","",IFERROR(IF(H12="","",IFERROR(IF(H12="","",IFERROR(IF(H12="","",IFERROR(IF(H12="","",IFERROR(IF(H12="","",IFERROR(IF(H12="","",IFERROR(IF(H12="","",IFERROR(IF(H12="","",IFERROR(IF(H12="","",IFERROR(IFERROR(IF(H12="","",DATEVALUE(MID(H12,6,11))),"Check date format"),"")),"")),"")),"")),"")),"")),"")),"")),"")),"")),"")),"")),"")),"")),"")),"")),"")),"")),"")),"")),"")),"")),"")),"")),"")),"")),"")),"")),"")),"")) | J12: =IF(OR(F12="",I12=""),"",F12+IF(I12=I11,N(J11),0))
I13: =IF(H13="","",IFERROR(IF(H13="","",IFERROR(IF(H13="","",IFERROR(IF(H13="","",IFERROR(IF(H13="","",IFERROR(IF(H13="","",IFERROR(IF(H13="","",IFERROR(IF(H13="","",IFERROR(IF(H13="","",IFERROR(IF(H13="","",IFERROR(IF(H13="","",IFERROR(IF(H13="","",IFERROR(IF(H13="","",IFERROR(IF(H13="","",IFERROR(IF(H13="","",IFERROR(IF(H13="","",IFERROR(IF(H13="","",IFERROR(IF(H13="","",IFERROR(IF(H13="","",IFERROR(IF(H13="","",IFERROR(IF(H13="","",IFERROR(IF(H13="","",IFERROR(IF(H13="","",IFERROR(IF(H13="","",IFERROR(IF(H13="","",IFERROR(IF(H13="","",IFERROR(IF(H13="","",IFERROR(IF(H13="","",IFERROR(IF(H13="","",IFERROR(IF(H13="","",IFERROR(IFERROR(IF(H13="","",DATEVALUE(MID(H13,6,11))),"Check date format"),"")),"")),"")),"")),"")),"")),"")),"")),"")),"")),"")),"")),"")),"")),"")),"")),"")),"")),"")),"")),"")),"")),"")),"")),"")),"")),"")),"")),"")),"")) | J13: =IF(OR(F13="",I13=""),"",F13+IF(I13=I12,N(J12),0))
I14: =IF(H14="","",IFERROR(IF(H14="","",IFERROR(IF(H14="","",IFERROR(IF(H14="","",IFERROR(IF(H14="","",IFERROR(IF(H14="","",IFERROR(IF(H14="","",IFERROR(IF(H14="","",IFERROR(IF(H14="","",IFERROR(IF(H14="","",IFERROR(IF(H14="","",IFERROR(IF(H14="","",IFERROR(IF(H14="","",IFERROR(IF(H14="","",IFERROR(IF(H14="","",IFERROR(IF(H14="","",IFERROR(IF(H14="","",IFERROR(IF(H14="","",IFERROR(IF(H14="","",IFERROR(IF(H14="","",IFERROR(IF(H14="","",IFERROR(IF(H14="","",IFERROR(IF(H14="","",IFERROR(IF(H14="","",IFERROR(IF(H14="","",IFERROR(IF(H14="","",IFERROR(IF(H14="","",IFERROR(IF(H14="","",IFERROR(IF(H14="","",IFERROR(IF(H14="","",IFERROR(IFERROR(IF(H14="","",DATEVALUE(MID(H14,6,11))),"Check date format"),"")),"")),"")),"")),"")),"")),"")),"")),"")),"")),"")),"")),"")),"")),"")),"")),"")),"")),"")),"")),"")),"")),"")),"")),"")),"")),"")),"")),"")),"")) | J14: =IF(OR(F14="",I14=""),"",F14+IF(I14=I13,N(J13),0))
