Workbook
Name Macro_Data: Table9[[#All],[Category]:[Qualitative]]
Name tblMacroUS: Table9[[#All],[Category]:[Qualitative]]
Name tblPolicy: #REF!

Sheet Summary
A1: Label | B1: Value
A2: Monthly Target ($) | B2: 20000
A3: Planned Active Trading Days | B3: 17
A4: Average Target per Trading Day ($) | B4: =B2/B3 -> 1176.4706
A5: Weeks in Cycle | B5: 4
A6: Average Target per Week ($) | B6: =B2/B5 -> 5000
A7: Required R per week | B7: =B6/B17 -> 9.0226504
A8: Risk % of NAV per trade | B8: 0.07
A9: Max Daily Loss (R multiples) | B9: 2
A10: Current NAV ($) | B10: 7175.38
A11: Cumulative P&L Month ($) | B11: =IFERROR(LOOKUP(2,1/('Daily Log'!$I:$I<>""),'Daily Log'!$I:$I),"") -> 515.0023
A12: Remaining Target ($) | B12: =B2-B11 -> 19484.998
A13: Trading Days Used | B13: =COUNTIFS('Daily Log'!D:D,"Y") -> 2
A14: Trading Days Remaining | B14: =B3-B13 -> 15
A15: Required P&L per Remaining Day | B15: =IF(B14>0,B12/B14,"") -> 1298.9998
A16: Target R per Day (approx) | B16: =IF(AND(B14>0,B18>0),B15/B18,"") -> 2.610573
A17: Projected Month P&L ($) | B17: =B11+(B14*B16) -> 554.1609
A18: Average R value ($) | B18: =IF(K22>0,B11/K22,"") -> 497.59185
A19: Today’s expected plan P&L ($) | B19: =Planner_v2!AF18
A21: Week # | B21: Active Days | C21: Total Trades | D21: Total Wins | E21: Total Losses | F21: Week Net P&L | G21: Weekly Target | H21: Week Variance ($) | I21: Avg Win Rate % | J21: Avg Reward:Risk | K21: Total R | L21: Avg R per Day
A22: 1 | B22: =COUNTIFS('Daily Log'!$B:$B,$A22,'Daily Log'!$D:$D,"Y") -> 2 | C22: =SUMIFS('Daily Log'!$N:$N,'Daily Log'!$B:$B,$A22) -> 2 | D22: =SUMIFS('Daily Log'!$O:$O,'Daily Log'!$B:$B,$A22) -> 1 | E22: =SUMIFS('Daily Log'!$P:$P,'Daily Log'!$B:$B,$A22) -> 1 | F22: =SUMIFS('Daily Log'!$H:$H,'Daily Log'!$B:$B,$A22) -> 515.0023 | G22: =$B$6 -> 5000 | H22: =F22-G22 -> -4484.9977 | I22: =IF(B22>0,AVERAGEIFS('Daily Log'!$S:$S,'Daily Log'!$B:$B,$A22,'Daily Log'!$D:$D,"Y"),"") -> 0.5 | J22: =IF(B22>0,IFERROR(AVERAGEIFS('Daily Log'!$T:$T,'Daily Log'!$B:$B,$A22,'Daily Log'!$D:$D,"Y",'Daily Log'!$T:$T,">0"),""),"") | K22: =SUMIFS('Daily Log'!$U:$U,'Daily Log'!$B:$B,$A22,'Daily Log'!$D:$D,"Y") -> 1.0349894 | L22: =IF(B22>0,K22/B22,"") -> 0.51749471
A23: 2 | B23: =COUNTIFS('Daily Log'!$B:$B,$A23,'Daily Log'!$D:$D,"Y") -> 0 | C23: =SUMIFS('Daily Log'!$N:$N,'Daily Log'!$B:$B,$A23) -> 0 | D23: =SUMIFS('Daily Log'!$O:$O,'Daily Log'!$B:$B,$A23) -> 0 | E23: =SUMIFS('Daily Log'!$P:$P,'Daily Log'!$B:$B,$A23) -> 0 | F23: =SUMIFS('Daily Log'!$H:$H,'Daily Log'!$B:$B,$A23) -> 0 | G23: =$B$6 -> 5000 | H23: =F23-G23 -> -5000 | I23: =IF(B23>0,AVERAGEIFS('Daily Log'!$S:$S,'Daily Log'!$B:$B,$A23,'Daily Log'!$D:$D,"Y"),"") | J23: =IF(B23>0,AVERAGEIFS('Daily Log'!$T:$T,'Daily Log'!$B:$B,$A23,'Daily Log'!$D:$D,"Y",'Daily Log'!$T:$T,">0"),"") | K23: =SUMIFS('Daily Log'!$U:$U,'Daily Log'!$B:$B,$A23,'Daily Log'!$D:$D,"Y") -> 0 | L23: =IF(B23>0,K23/B23,"")
A24: 3 | B24: =COUNTIFS('Daily Log'!$B:$B,$A24,'Daily Log'!$D:$D,"Y") -> 0 | C24: =SUMIFS('Daily Log'!$N:$N,'Daily Log'!$B:$B,$A24) -> 0 | D24: =SUMIFS('Daily Log'!$O:$O,'Daily Log'!$B:$B,$A24) -> 0 | E24: =SUMIFS('Daily Log'!$P:$P,'Daily Log'!$B:$B,$A24) -> 0 | F24: =SUMIFS('Daily Log'!$H:$H,'Daily Log'!$B:$B,$A24) -> 0 | G24: =$B$6 -> 5000 | H24: =F24-G24 -> -5000 | I24: =IF(B24>0,AVERAGEIFS('Daily Log'!$S:$S,'Daily Log'!$B:$B,$A24,'Daily Log'!$D:$D,"Y"),"") | J24: =IF(B24>0,AVERAGEIFS('Daily Log'!$T:$T,'Daily Log'!$B:$B,$A24,'Daily Log'!$D:$D,"Y",'Daily Log'!$T:$T,">0"),"") | K24: =SUMIFS('Daily Log'!$U:$U,'Daily Log'!$B:$B,$A24,'Daily Log'!$D:$D,"Y") -> 0 | L24: =IF(B24>0,K24/B24,"")
A25: 4 | B25: =COUNTIFS('Daily Log'!$B:$B,$A25,'Daily Log'!$D:$D,"Y") -> 0 | C25: =SUMIFS('Daily Log'!$N:$N,'Daily Log'!$B:$B,$A25) -> 0 | D25: =SUMIFS('Daily Log'!$O:$O,'Daily Log'!$B:$B,$A25) -> 0 | E25: =SUMIFS('Daily Log'!$P:$P,'Daily Log'!$B:$B,$A25) -> 0 | F25: =SUMIFS('Daily Log'!$H:$H,'Daily Log'!$B:$B,$A25) -> 0 | G25: =$B$6 -> 5000 | H25: =F25-G25 -> -5000 | I25: =IF(B25>0,AVERAGEIFS('Daily Log'!$S:$S,'Daily Log'!$B:$B,$A25,'Daily Log'!$D:$D,"Y"),"") | J25: =IF(B25>0,AVERAGEIFS('Daily Log'!$T:$T,'Daily Log'!$B:$B,$A25,'Daily Log'!$D:$D,"Y",'Daily Log'!$T:$T,">0"),"") | K25: =SUMIFS('Daily Log'!$U:$U,'Daily Log'!$B:$B,$A25,'Daily Log'!$D:$D,"Y") -> 0 | L25: =IF(B25>0,K25/B25,"")

Sheet Daily Log
A1: Date | B1: Week # | C1: Day of Week | D1: Active Trading Day? (Y/N) | E1: Start NAV ($) | F1: Risk per Trade R ($) | G1: Max Daily Loss Cap ($) | H1: Net P&L ($) | I1: Cumulative P&L Month ($) | J1: Week P&L ($) | K1: Weekly Target ($) | L1: Week Variance vs Target ($) | M1: Notes | N1: # Trades | O1: # Wins | P1: # Losses | Q1: Total Wins ($) | R1: Total Losses ($) | S1: Win Rate (%) | T1: Reward:Risk | U1: Daily R-multiple | V1: Losses vs Cap | W1: Intraday Net P&L (so far) | X1: % of Cap Used (Net) | Y1: Worst Intraday DD % of Cap
A2: 46033 | B2: 1 | C2: =TEXT(A2,"dddd") -> Sunday | D2: Y | E2: 7175.38 | F2: =IF($A2="","",$E2*Summary!$B$8) -> 502.2766 | G2: =IF($A2="","",F2*Summary!$B$9) -> 1004.5532 | H2: =IF($A2="","",SUMIFS('Raw daily data'!$F:$F,'Raw daily data'!$I:$I,$A2)) -> -60 | I2: =H2 -> -60 | J2: =SUMIF($B$2:$B$41,B2,$H$2:$H$41) -> 515.0023 | K2: =Summary!$B$6 -> 5000 | L2: =J2-K2 -> -4484.9977 | N2: =IF($A2="","",COUNTIFS('Raw daily data'!$I:$I,$A2)) -> 1 | O2: =IF($A2="","",COUNTIFS('Raw daily data'!$I:$I,$A2,'Raw daily data'!$F:$F,">0")) -> 0 | P2: =IF($A2="","",COUNTIFS('Raw daily data'!$I:$I,$A2,'Raw daily data'!$F:$F,"<0")) -> 1 | Q2: =IF($A2="","",SUMIFS('Raw daily data'!$F:$F,'Raw daily data'!$I:$I,$A2,'Raw daily data'!$F:$F,">0")) -> 0 | R2: =IF($A2="","",ABS(SUMIFS('Raw daily data'!$F:$F,'Raw daily data'!$I:$I,$A2,'Raw daily data'!$F:$F,"<0"))) -> 60 | S2: =IF(N2>0,O2/N2,"") -> 0 | T2: =IF(R2>0,Q2/ABS(R2),"") -> 0 | U2: =IF(F2>0,H2/F2,"") -> -0.11945609 | V2: =IF(H2<0,MIN(ABS(H2)/G2,1),0) -> 0.059728046 | W2: =IF($A2="","",_xlfn.MAXIFS('Raw daily data'!$J:$J,'Raw daily data'!$I:$I,$A2)) -> -60 | X2: =IF(W2>=0,0,ABS(W2)/G2) -> 0.059728046 | Y2: =IF($A2="","",ABS(MIN(0,_xlfn.MINIFS('Raw daily data'!$J:$J,'Raw daily data'!$I:$I,$A2)))/G2) -> 0.059728046
A3: 46034 | B3: 1 | C3: =TEXT(A3,"dddd") -> Monday | D3: Y | E3: =E2+H2 -> 7115.38 | F3: =IF($A3="","",$E3*Summary!$B$8) -> 498.0766 | G3: =IF($A3="","",F3*Summary!$B$9) -> 996.1532 | H3: =IF($A3="","",SUMIFS('Raw daily data'!$F:$F,'Raw daily data'!$I:$I,$A3)) -> 575.0023 | I3: =I2+H3 -> 515.0023 | J3: =SUMIF($B$2:$B$41,B3,$H$2:$H$41) -> 515.0023 | K3: =Summary!$B$6 -> 5000 | L3: =J3-K3 -> -4484.9977 | N3: =IF($A3="","",COUNTIFS('Raw daily data'!$I:$I,$A3)) -> 1 | O3: =IF($A3="","",COUNTIFS('Raw daily data'!$I:$I,$A3,'Raw daily data'!$F:$F,">0")) -> 1 | P3: =IF($A3="","",COUNTIFS('Raw daily data'!$I:$I,$A3,'Raw daily data'!$F:$F,"<0")) -> 0 | Q3: =IF($A3="","",SUMIFS('Raw daily data'!$F:$F,'Raw daily data'!$I:$I,$A3,'Raw daily data'!$F:$F,">0")) -> 575.0023 | R3: =IF($A3="","",ABS(SUMIFS('Raw daily data'!$F:$F,'Raw daily data'!$I:$I,$A3,'Raw daily data'!$F:$F,"<0"))) -> 0 | S3: =IF(N3>0,O3/N3,"") -> 1 | T3: =IF(R3>0,Q3/ABS(R3),"") | U3: =IF(F3>0,H3/F3,"") -> 1.1544455 | V3: =IF(H3<0,MIN(ABS(H3)/G3,1),0) -> 0 | W3: =IF($A3="","",_xlfn.MAXIFS('Raw daily data'!$J:$J,'Raw daily data'!$I:$I,$A3)) -> 575.0023 | X3: =IF(W3>=0,0,ABS(W3)/G3) -> 0 | Y3: =IF($A3="","",ABS(MIN(0,_xlfn.MINIFS('Raw daily data'!$J:$J,'Raw daily data'!$I:$I,$A3)))/G3) -> 0
A4: 46035 | B4: 1 | C4: =TEXT(A4,"dddd") -> Tuesday | D4: N | E4: =E3+H3 -> 7690.3823 | F4: =IF($A4="","",$E4*Summary!$B$8) -> 538.32676 | G4: =IF($A4="","",F4*Summary!$B$9) -> 1076.6535 | H4: =IF($A4="","",SUMIFS('Raw daily data'!$F:$F,'Raw daily data'!$I:$I,$A4)) -> 0 | I4: =I3+H4 -> 515.0023 | J4: =SUMIF($B$2:$B$41,B4,$H$2:$H$41) -> 515.0023 | K4: =Summary!$B$6 -> 5000 | L4: =J4-K4 -> -4484.9977 | N4: =IF($A4="","",COUNTIFS('Raw daily data'!$I:$I,$A4)) -> 0 | O4: =IF($A4="","",COUNTIFS('Raw daily data'!$I:$I,$A4,'Raw daily data'!$F:$F,">0")) -> 0 | P4: =IF($A4="","",COUNTIFS('Raw daily data'!$I:$I,$A4,'Raw daily data'!$F:$F,"<0")) -> 0 | Q4: =IF($A4="","",SUMIFS('Raw daily data'!$F:$F,'Raw daily data'!$I:$I,$A4,'Raw daily data'!$F:$F,">0")) -> 0 | R4: =IF($A4="","",ABS(SUMIFS('Raw daily data'!$F:$F,'Raw daily data'!$I:$I,$A4,'Raw daily data'!$F:$F,"<0"))) -> 0 | S4: =IF(N4>0,O4/N4,"") | T4: =IF(R4>0,Q4/ABS(R4),"") | U4: =IF(F4>0,H4/F4,"") -> 0 | V4: =IF(H4<0,MIN(ABS(H4)/G4,1),0) -> 0 | W4: =IF($A4="","",_xlfn.MAXIFS('Raw daily data'!$J:$J,'Raw daily data'!$I:$I,$A4)) -> 0 | X4: =IF(W4>=0,0,ABS(W4)/G4) -> 0 | Y4: =IF($A4="","",ABS(MIN(0,_xlfn.MINIFS('Raw daily data'!$J:$J,'Raw daily data'!$I:$I,$A4)))/G4) -> 0
A5: 46036 | B5: 1 | C5: =TEXT(A5,"dddd") -> Wednesday | D5: N | E5: =E4+H4 -> 7690.3823 | F5: =IF($A5="","",$E5*Summary!$B$8) -> 538.32676 | G5: =IF($A5="","",F5*Summary!$B$9) -> 1076.6535 | H5: =IF($A5="","",SUMIFS('Raw daily data'!$F:$F,'Raw daily data'!$I:$I,$A5)) -> 0 | I5: =I4+H5 -> 515.0023 | J5: =SUMIF($B$2:$B$41,B5,$H$2:$H$41) -> 515.0023 | K5: =Summary!$B$6 -> 5000 | L5: =J5-K5 -> -4484.9977 | N5: =IF($A5="","",COUNTIFS('Raw daily data'!$I:$I,$A5)) -> 0 | O5: =IF($A5="","",COUNTIFS('Raw daily data'!$I:$I,$A5,'Raw daily data'!$F:$F,">0")) -> 0 | P5: =IF($A5="","",COUNTIFS('Raw daily data'!$I:$I,$A5,'Raw daily data'!$F:$F,"<0")) -> 0 | Q5: =IF($A5="","",SUMIFS('Raw daily data'!$F:$F,'Raw daily data'!$I:$I,$A5,'Raw daily data'!$F:$F,">0")) -> 0 | R5: =IF($A5="","",ABS(SUMIFS('Raw daily data'!$F:$F,'Raw daily data'!$I:$I,$A5,'Raw daily data'!$F:$F,"<0"))) -> 0 | S5: =IF(N5>0,O5/N5,"") | T5: =IF(R5>0,Q5/ABS(R5),"") | U5: =IF(F5>0,H5/F5,"") -> 0 | V5: =IF(H5<0,MIN(ABS(H5)/G5,1),0) -> 0 | W5: =IF($A5="","",_xlfn.MAXIFS('Raw daily data'!$J:$J,'Raw daily data'!$I:$I,$A5)) -> 0 | X5: =IF(W5>=0,0,ABS(W5)/G5) -> 0 | Y5: =IF($A5="","",ABS(MIN(0,_xlfn.MINIFS('Raw daily data'!$J:$J,'Raw daily data'!$I:$I,$A5)))/G5) -> 0
A6: 46037 | B6: 1 | C6: =TEXT(A6,"dddd") -> Thursday | D6: N | E6: =E5+H5 -> 7690.3823 | F6: =IF($A6="","",$E6*Summary!$B$8) -> 538.32676 | G6: =IF($A6="","",F6*Summary!$B$9) -> 1076.6535 | H6: =IF($A6="","",SUMIFS('Raw daily data'!$F:$F,'Raw daily data'!$I:$I,$A6)) -> 0 | I6: =I5+H6 -> 515.0023 | J6: =SUMIF($B$2:$B$41,B6,$H$2:$H$41) -> 515.0023 | K6: =Summary!$B$6 -> 5000 | L6: =J6-K6 -> -4484.9977 | N6: =IF($A6="","",COUNTIFS('Raw daily data'!$I:$I,$A6)) -> 0 | O6: =IF($A6="","",COUNTIFS('Raw daily data'!$I:$I,$A6,'Raw daily data'!$F:$F,">0")) -> 0 | P6: =IF($A6="","",COUNTIFS('Raw daily data'!$I:$I,$A6,'Raw daily data'!$F:$F,"<0")) -> 0 | Q6: =IF($A6="","",SUMIFS('Raw daily data'!$F:$F,'Raw daily data'!$I:$I,$A6,'Raw daily data'!$F:$F,">0")) -> 0 | R6: =IF($A6="","",ABS(SUMIFS('Raw daily data'!$F:$F,'Raw daily data'!$I:$I,$A6,'Raw daily data'!$F:$F,"<0"))) -> 0 | S6: =IF(N6>0,O6/N6,"") | T6: =IF(R6>0,Q6/ABS(R6),"") | U6: =IF(F6>0,H6/F6,"") -> 0 | V6: =IF(H6<0,MIN(ABS(H6)/G6,1),0) -> 0 | W6: =IF($A6="","",_xlfn.MAXIFS('Raw daily data'!$J:$J,'Raw daily data'!$I:$I,$A6)) -> 0 | X6: =IF(W6>=0,0,ABS(W6)/G6) -> 0 | Y6: =IF($A6="","",ABS(MIN(0,_xlfn.MINIFS('Raw daily data'!$J:$J,'Raw daily data'!$I:$I,$A6)))/G6) -> 0
A7: 46038 | B7: 1 | C7: =TEXT(A7,"dddd") -> Friday | D7: N | E7: =E6+H6 -> 7690.3823 | F7: =IF($A7="","",$E7*Summary!$B$8) -> 538.32676 | G7: =IF($A7="","",F7*Summary!$B$9) -> 1076.6535 | H7: =IF($A7="","",SUMIFS('Raw daily data'!$F:$F,'Raw daily data'!$I:$I,$A7)) -> 0 | I7: =I6+H7 -> 515.0023 | J7: =SUMIF($B$2:$B$41,B7,$H$2:$H$41) -> 515.0023 | K7: =Summary!$B$6 -> 5000 | L7: =J7-K7 -> -4484.9977 | N7: =IF($A7="","",COUNTIFS('Raw daily data'!$I:$I,$A7)) -> 0 | O7: =IF($A7="","",COUNTIFS('Raw daily data'!$I:$I,$A7,'Raw daily data'!$F:$F,">0")) -> 0 | P7: =IF($A7="","",COUNTIFS('Raw daily data'!$I:$I,$A7,'Raw daily data'!$F:$F,"<0")) -> 0 | Q7: =IF($A7="","",SUMIFS('Raw daily data'!$F:$F,'Raw daily data'!$I:$I,$A7,'Raw daily data'!$F:$F,">0")) -> 0 | R7: =IF($A7="","",ABS(SUMIFS('Raw daily data'!$F:$F,'Raw daily data'!$I:$I,$A7,'Raw daily data'!$F:$F,"<0"))) -> 0 | S7: =IF(N7>0,O7/N7,"") | T7: =IF(R7>0,Q7/ABS(R7),"") | U7: =IF(F7>0,H7/F7,"") -> 0 | V7: =IF(H7<0,MIN(ABS(H7)/G7,1),0) -> 0 | W7: =IF($A7="","",_xlfn.MAXIFS('Raw daily data'!$J:$J,'Raw daily data'!$I:$I,$A7)) -> 0 | X7: =IF(W7>=0,0,ABS(W7)/G7) -> 0 | Y7: =IF($A7="","",ABS(MIN(0,_xlfn.MINIFS('Raw daily data'!$J:$J,'Raw daily data'!$I:$I,$A7)))/G7) -> 0
A8: 46039 | B8: 1 | C8: =TEXT(A8,"dddd") -> Saturday | D8: N | E8: =E7+H7 -> 7690.3823 | F8: =IF($A8="","",$E8*Summary!$B$8) -> 538.32676 | G8: =IF($A8="","",F8*Summary!$B$9) -> 1076.6535 | H8: =IF($A8="","",SUMIFS('Raw daily data'!$F:$F,'Raw daily data'!$I:$I,$A8)) -> 0 | I8: =I7+H8 -> 515.0023 | J8: =SUMIF($B$2:$B$41,B8,$H$2:$H$41) -> 515.0023 | K8: =Summary!$B$6 -> 5000 | L8: =J8-K8 -> -4484.9977 | N8: =IF($A8="","",COUNTIFS('Raw daily data'!$I:$I,$A8)) -> 0 | O8: =IF($A8="","",COUNTIFS('Raw daily data'!$I:$I,$A8,'Raw daily data'!$F:$F,">0")) -> 0 | P8: =IF($A8="","",COUNTIFS('Raw daily data'!$I:$I,$A8,'Raw daily data'!$F:$F,"<0")) -> 0 | Q8: =IF($A8="","",SUMIFS('Raw daily data'!$F:$F,'Raw daily data'!$I:$I,$A8,'Raw daily data'!$F:$F,">0")) -> 0 | R8: =IF($A8="","",ABS(SUMIFS('Raw daily data'!$F:$F,'Raw daily data'!$I:$I,$A8,'Raw daily data'!$F:$F,"<0"))) -> 0 | S8: =IF(N8>0,O8/N8,"") | T8: =IF(R8>0,Q8/ABS(R8),"") | U8: =IF(F8>0,H8/F8,"") -> 0 | V8: =IF(H8<0,MIN(ABS(H8)/G8,1),0) -> 0 | W8: =IF($A8="","",_xlfn.MAXIFS('Raw daily data'!$J:$J,'Raw daily data'!$I:$I,$A8)) -> 0 | X8: =IF(W8>=0,0,ABS(W8)/G8) -> 0 | Y8: =IF($A8="","",ABS(MIN(0,_xlfn.MINIFS('Raw daily data'!$J:$J,'Raw daily data'!$I:$I,$A8)))/G8) -> 0
A9: 46040 | B9: 2 | C9: =TEXT(A9,"dddd") -> Sunday | D9: N | E9: =E8+H8 -> 7690.3823 | F9: =IF($A9="","",$E9*Summary!$B$8) -> 538.32676 | G9: =IF($A9="","",F9*Summary!$B$9) -> 1076.6535 | H9: =IF($A9="","",SUMIFS('Raw daily data'!$F:$F,'Raw daily data'!$I:$I,$A9)) -> 0 | I9: =I8+H9 -> 515.0023 | J9: =SUMIF($B$2:$B$41,B9,$H$2:$H$41) -> 0 | K9: =Summary!$B$6 -> 5000 | L9: =J9-K9 -> -5000 | N9: =IF($A9="","",COUNTIFS('Raw daily data'!$I:$I,$A9)) -> 0 | O9: =IF($A9="","",COUNTIFS('Raw daily data'!$I:$I,$A9,'Raw daily data'!$F:$F,">0")) -> 0 | P9: =IF($A9="","",COUNTIFS('Raw daily data'!$I:$I,$A9,'Raw daily data'!$F:$F,"<0")) -> 0 | Q9: =IF($A9="","",SUMIFS('Raw daily data'!$F:$F,'Raw daily data'!$I:$I,$A9,'Raw daily data'!$F:$F,">0")) -> 0 | R9: =IF($A9="","",ABS(SUMIFS('Raw daily data'!$F:$F,'Raw daily data'!$I:$I,$A9,'Raw daily data'!$F:$F,"<0"))) -> 0 | S9: =IF(N9>0,O9/N9,"") | T9: =IF(R9>0,Q9/ABS(R9),"") | U9: =IF(F9>0,H9/F9,"") -> 0 | V9: =IF(H9<0,MIN(ABS(H9)/G9,1),0) -> 0 | W9: =IF($A9="","",_xlfn.MAXIFS('Raw daily data'!$J:$J,'Raw daily data'!$I:$I,$A9)) -> 0 | X9: =IF(W9>=0,0,ABS(W9)/G9) -> 0 | Y9: =IF($A9="","",ABS(MIN(0,_xlfn.MINIFS('Raw daily data'!$J:$J,'Raw daily data'!$I:$I,$A9)))/G9) -> 0
A10: 46041 | B10: 2 | C10: =TEXT(A10,"dddd") -> Monday | E10: =E9+H9 -> 7690.3823 | F10: =IF($A10="","",$E10*Summary!$B$8) -> 538.32676 | G10: =IF($A10="","",F10*Summary!$B$9) -> 1076.6535 | H10: =IF($A10="","",SUMIFS('Raw daily data'!$F:$F,'Raw daily data'!$I:$I,$A10)) -> 0 | I10: =I9+H10 -> 515.0023 | J10: =SUMIF($B$2:$B$41,B10,$H$2:$H$41) -> 0 | K10: =Summary!$B$6 -> 5000 | L10: =J10-K10 -> -5000 | N10: =IF($A10="","",COUNTIFS('Raw daily data'!$I:$I,$A10)) -> 0 | O10: =IF($A10="","",COUNTIFS('Raw daily data'!$I:$I,$A10,'Raw daily data'!$F:$F,">0")) -> 0 | P10: =IF($A10="","",COUNTIFS('Raw daily data'!$I:$I,$A10,'Raw daily data'!$F:$F,"<0")) -> 0 | Q10: =IF($A10="","",SUMIFS('Raw daily data'!$F:$F,'Raw daily data'!$I:$I,$A10,'Raw daily data'!$F:$F,">0")) -> 0 | R10: =IF($A10="","",ABS(SUMIFS('Raw daily data'!$F:$F,'Raw daily data'!$I:$I,$A10,'Raw daily data'!$F:$F,"<0"))) -> 0 | S10: =IF(N10>0,O10/N10,"") | T10: =IF(R10>0,Q10/ABS(R10),"") | U10: =IF(F10>0,H10/F10,"") -> 0 | V10: =IF(H10<0,MIN(ABS(H10)/G10,1),0) -> 0 | W10: =IF($A10="","",_xlfn.MAXIFS('Raw daily data'!$J:$J,'Raw daily data'!$I:$I,$A10)) -> 0 | X10: =IF(W10>=0,0,ABS(W10)/G10) -> 0 | Y10: =IF($A10="","",ABS(MIN(0,_xlfn.MINIFS('Raw daily data'!$J:$J,'Raw daily data'!$I:$I,$A10)))/G10) -> 0
A11: 46042 | B11: 2 | C11: =TEXT(A11,"dddd") -> Tuesday | E11: =E10+H10 -> 7690.3823 | F11: =IF($A11="","",$E11*Summary!$B$8) -> 538.32676 | G11: =IF($A11="","",F11*Summary!$B$9) -> 1076.6535 | H11: =IF($A11="","",SUMIFS('Raw daily data'!$F:$F,'Raw daily data'!$I:$I,$A11)) -> 0 | I11: =I10+H11 -> 515.0023 | J11: =SUMIF($B$2:$B$41,B11,$H$2:$H$41) -> 0 | K11: =Summary!$B$6 -> 5000 | L11: =J11-K11 -> -5000 | N11: =IF($A11="","",COUNTIFS('Raw daily data'!$I:$I,$A11)) -> 0 | O11: =IF($A11="","",COUNTIFS('Raw daily data'!$I:$I,$A11,'Raw daily data'!$F:$F,">0")) -> 0 | P11: =IF($A11="","",COUNTIFS('Raw daily data'!$I:$I,$A11,'Raw daily data'!$F:$F,"<0")) -> 0 | Q11: =IF($A11="","",SUMIFS('Raw daily data'!$F:$F,'Raw daily data'!$I:$I,$A11,'Raw daily data'!$F:$F,">0")) -> 0 | R11: =IF($A11="","",ABS(SUMIFS('Raw daily data'!$F:$F,'Raw daily data'!$I:$I,$A11,'Raw daily data'!$F:$F,"<0"))) -> 0 | S11: =IF(N11>0,O11/N11,"") | T11: =IF(R11>0,Q11/ABS(R11),"") | U11: =IF(F11>0,H11/F11,"") -> 0 | V11: =IF(H11<0,MIN(ABS(H11)/G11,1),0) -> 0 | W11: =IF($A11="","",_xlfn.MAXIFS('Raw daily data'!$J:$J,'Raw daily data'!$I:$I,$A11)) -> 0 | X11: =IF(W11>=0,0,ABS(W11)/G11) -> 0 | Y11: =IF($A11="","",ABS(MIN(0,_xlfn.MINIFS('Raw daily data'!$J:$J,'Raw daily data'!$I:$I,$A11)))/G11) -> 0
A12: 46043 | B12: 2 | C12: =TEXT(A12,"dddd") -> Wednesday | E12: =E11+H11 -> 7690.3823 | F12: =IF($A12="","",$E12*Summary!$B$8) -> 538.32676 | G12: =IF($A12="","",F12*Summary!$B$9) -> 1076.6535 | H12: =IF($A12="","",SUMIFS('Raw daily data'!$F:$F,'Raw daily data'!$I:$I,$A12)) -> 0 | I12: =I11+H12 -> 515.0023 | J12: =SUMIF($B$2:$B$41,B12,$H$2:$H$41) -> 0 | K12: =Summary!$B$6 -> 5000 | L12: =J12-K12 -> -5000 | N12: =IF($A12="","",COUNTIFS('Raw daily data'!$I:$I,$A12)) -> 0 | O12: =IF($A12="","",COUNTIFS('Raw daily data'!$I:$I,$A12,'Raw daily data'!$F:$F,">0")) -> 0 | P12: =IF($A12="","",COUNTIFS('Raw daily data'!$I:$I,$A12,'Raw daily data'!$F:$F,"<0")) -> 0 | Q12: =IF($A12="","",SUMIFS('Raw daily data'!$F:$F,'Raw daily data'!$I:$I,$A12,'Raw daily data'!$F:$F,">0")) -> 0 | R12: =IF($A12="","",ABS(SUMIFS('Raw daily data'!$F:$F,'Raw daily data'!$I:$I,$A12,'Raw daily data'!$F:$F,"<0"))) -> 0 | S12: =IF(N12>0,O12/N12,"") | T12: =IF(R12>0,Q12/ABS(R12),"") | U12: =IF(F12>0,H12/F12,"") -> 0 | V12: =IF(H12<0,MIN(ABS(H12)/G12,1),0) -> 0 | W12: =IF($A12="","",_xlfn.MAXIFS('Raw daily data'!$J:$J,'Raw daily data'!$I:$I,$A12)) -> 0 | X12: =IF(W12>=0,0,ABS(W12)/G12) -> 0 | Y12: =IF($A12="","",ABS(MIN(0,_xlfn.MINIFS('Raw daily data'!$J:$J,'Raw daily data'!$I:$I,$A12)))/G12) -> 0
A13: 46044 | B13: 2 | C13: =TEXT(A13,"dddd") -> Thursday | E13: =E12+H12 -> 7690.3823 | F13: =IF($A13="","",$E13*Summary!$B$8) -> 538.32676 | G13: =IF($A13="","",F13*Summary!$B$9) -> 1076.6535 | H13: =IF($A13="","",SUMIFS('Raw daily data'!$F:$F,'Raw daily data'!$I:$I,$A13)) -> 0 | I13: =I12+H13 -> 515.0023 | J13: =SUMIF($B$2:$B$41,B13,$H$2:$H$41) -> 0 | K13: =Summary!$B$6 -> 5000 | L13: =J13-K13 -> -5000 | N13: =IF($A13="","",COUNTIFS('Raw daily data'!$I:$I,$A13)) -> 0 | O13: =IF($A13="","",COUNTIFS('Raw daily data'!$I:$I,$A13,'Raw daily data'!$F:$F,">0")) -> 0 | P13: =IF($A13="","",COUNTIFS('Raw daily data'!$I:$I,$A13,'Raw daily data'!$F:$F,"<0")) -> 0 | Q13: =IF($A13="","",SUMIFS('Raw daily data'!$F:$F,'Raw daily data'!$I:$I,$A13,'Raw daily data'!$F:$F,">0")) -> 0 | R13: =IF($A13="","",ABS(SUMIFS('Raw daily data'!$F:$F,'Raw daily data'!$I:$I,$A13,'Raw daily data'!$F:$F,"<0"))) -> 0 | S13: =IF(N13>0,O13/N13,"") | T13: =IF(R13>0,Q13/ABS(R13),"") | U13: =IF(F13>0,H13/F13,"") -> 0 | V13: =IF(H13<0,MIN(ABS(H13)/G13,1),0) -> 0 | W13: =IF($A13="","",_xlfn.MAXIFS('Raw daily data'!$J:$J,'Raw daily data'!$I:$I,$A13)) -> 0 | X13: =IF(W13>=0,0,ABS(W13)/G13) -> 0 | Y13: =IF($A13="","",ABS(MIN(0,_xlfn.MINIFS('Raw daily data'!$J:$J,'Raw daily data'!$I:$I,$A13)))/G13) -> 0
A14: 46045 | B14: 2 | C14: =TEXT(A14,"dddd") -> Friday | E14: =E13+H13 -> 7690.3823 | F14: =IF($A14="","",$E14*Summary!$B$8) -> 538.32676 | G14: =IF($A14="","",F14*Summary!$B$9) -> 1076.6535 | H14: =IF($A14="","",SUMIFS('Raw daily data'!$F:$F,'Raw daily data'!$I:$I,$A14)) -> 0 | I14: =I13+H14 -> 515.0023 | J14: =SUMIF($B$2:$B$41,B14,$H$2:$H$41) -> 0 | K14: =Summary!$B$6 -> 5000 | L14: =J14-K14 -> -5000 | N14: =IF($A14="","",COUNTIFS('Raw daily data'!$I:$I,$A14)) -> 0 | O14: =IF($A14="","",COUNTIFS('Raw daily data'!$I:$I,$A14,'Raw daily data'!$F:$F,">0")) -> 0 | P14: =IF($A14="","",COUNTIFS('Raw daily data'!$I:$I,$A14,'Raw daily data'!$F:$F,"<0")) -> 0 | Q14: =IF($A14="","",SUMIFS('Raw daily data'!$F:$F,'Raw daily data'!$I:$I,$A14,'Raw daily data'!$F:$F,">0")) -> 0 | R14: =IF($A14="","",ABS(SUMIFS('Raw daily data'!$F:$F,'Raw daily data'!$I:$I,$A14,'Raw daily data'!$F:$F,"<0"))) -> 0 | S14: =IF(N14>0,O14/N14,"") | T14: =IF(R14>0,Q14/ABS(R14),"") | U14: =IF(F14>0,H14/F14,"") -> 0 | V14: =IF(H14<0,MIN(ABS(H14)/G14,1),0) -> 0 | W14: =IF($A14="","",_xlfn.MAXIFS('Raw daily data'!$J:$J,'Raw daily data'!$I:$I,$A14)) -> 0 | X14: =IF(W14>=0,0,ABS(W14)/G14) -> 0 | Y14: =IF($A14="","",ABS(MIN(0,_xlfn.MINIFS('Raw daily data'!$J:$J,'Raw daily data'!$I:$I,$A14)))/G14) -> 0
A15: 46046 | B15: 2 | C15: =TEXT(A15,"dddd") -> Saturday | D15: N | E15: =E14+H14 -> 7690.3823 | F15: =IF($A15="","",$E15*Summary!$B$8) -> 538.32676 | G15: =IF($A15="","",F15*Summary!$B$9) -> 1076.6535 | H15: =IF($A15="","",SUMIFS('Raw daily data'!$F:$F,'Raw daily data'!$I:$I,$A15)) -> 0 | I15: =I14+H15 -> 515.0023 | J15: =SUMIF($B$2:$B$41,B15,$H$2:$H$41) -> 0 | K15: =Summary!$B$6 -> 5000 | L15: =J15-K15 -> -5000 | N15: =IF($A15="","",COUNTIFS('Raw daily data'!$I:$I,$A15)) -> 0 | O15: =IF($A15="","",COUNTIFS('Raw daily data'!$I:$I,$A15,'Raw daily data'!$F:$F,">0")) -> 0 | P15: =IF($A15="","",COUNTIFS('Raw daily data'!$I:$I,$A15,'Raw daily data'!$F:$F,"<0")) -> 0 | Q15: =IF($A15="","",SUMIFS('Raw daily data'!$F:$F,'Raw daily data'!$I:$I,$A15,'Raw daily data'!$F:$F,">0")) -> 0 | R15: =IF($A15="","",ABS(SUMIFS('Raw daily data'!$F:$F,'Raw daily data'!$I:$I,$A15,'Raw daily data'!$F:$F,"<0"))) -> 0 | S15: =IF(N15>0,O15/N15,"") | T15: =IF(R15>0,Q15/ABS(R15),"") | U15: =IF(F15>0,H15/F15,"") -> 0 | V15: =IF(H15<0,MIN(ABS(H15)/G15,1),0) -> 0 | W15: =IF($A15="","",_xlfn.MAXIFS('Raw daily data'!$J:$J,'Raw daily data'!$I:$I,$A15)) -> 0 | X15: =IF(W15>=0,0,ABS(W15)/G15) -> 0 | Y15: =IF($A15="","",ABS(MIN(0,_xlfn.MINIFS('Raw daily data'!$J:$J,'Raw daily data'!$I:$I,$A15)))/G15) -> 0
A16: 46047 | B16: 3 | C16: =TEXT(A16,"dddd") -> Sunday | D16: N | E16: =E15+H15 -> 7690.3823 | F16: =IF($A16="","",$E16*Summary!$B$8) -> 538.32676 | G16: =IF($A16="","",F16*Summary!$B$9) -> 1076.6535 | H16: =IF($A16="","",SUMIFS('Raw daily data'!$F:$F,'Raw daily data'!$I:$I,$A16)) -> 0 | I16: =I15+H16 -> 515.0023 | J16: =SUMIF($B$2:$B$41,B16,$H$2:$H$41) -> 0 | K16: =Summary!$B$6 -> 5000 | L16: =J16-K16 -> -5000 | N16: =IF($A16="","",COUNTIFS('Raw daily data'!$I:$I,$A16)) -> 0 | O16: =IF($A16="","",COUNTIFS('Raw daily data'!$I:$I,$A16,'Raw daily data'!$F:$F,">0")) -> 0 | P16: =IF($A16="","",COUNTIFS('Raw daily data'!$I:$I,$A16,'Raw daily data'!$F:$F,"<0")) -> 0 | Q16: =IF($A16="","",SUMIFS('Raw daily data'!$F:$F,'Raw daily data'!$I:$I,$A16,'Raw daily data'!$F:$F,">0")) -> 0 | R16: =IF($A16="","",ABS(SUMIFS('Raw daily data'!$F:$F,'Raw daily data'!$I:$I,$A16,'Raw daily data'!$F:$F,"<0"))) -> 0 | S16: =IF(N16>0,O16/N16,"") | T16: =IF(R16>0,Q16/ABS(R16),"") | U16: =IF(F16>0,H16/F16,"") -> 0 | V16: =IF(H16<0,MIN(ABS(H16)/G16,1),0) -> 0 | W16: =IF($A16="","",_xlfn.MAXIFS('Raw daily data'!$J:$J,'Raw daily data'!$I:$I,$A16)) -> 0 | X16: =IF(W16>=0,0,ABS(W16)/G16) -> 0 | Y16: =IF($A16="","",ABS(MIN(0,_xlfn.MINIFS('Raw daily data'!$J:$J,'Raw daily data'!$I:$I,$A16)))/G16) -> 0
A17: 46048 | B17: 3 | C17: =TEXT(A17,"dddd") -> Monday | E17: =E16+H16 -> 7690.3823 | F17: =IF($A17="","",$E17*Summary!$B$8) -> 538.32676 | G17: =IF($A17="","",F17*Summary!$B$9) -> 1076.6535 | H17: =IF($A17="","",SUMIFS('Raw daily data'!$F:$F,'Raw daily data'!$I:$I,$A17)) -> 0 | I17: =I16+H17 -> 515.0023 | J17: =SUMIF($B$2:$B$41,B17,$H$2:$H$41) -> 0 | K17: =Summary!$B$6 -> 5000 | L17: =J17-K17 -> -5000 | N17: =IF($A17="","",COUNTIFS('Raw daily data'!$I:$I,$A17)) -> 0 | O17: =IF($A17="","",COUNTIFS('Raw daily data'!$I:$I,$A17,'Raw daily data'!$F:$F,">0")) -> 0 | P17: =IF($A17="","",COUNTIFS('Raw daily data'!$I:$I,$A17,'Raw daily data'!$F:$F,"<0")) -> 0 | Q17: =IF($A17="","",SUMIFS('Raw daily data'!$F:$F,'Raw daily data'!$I:$I,$A17,'Raw daily data'!$F:$F,">0")) -> 0 | R17: =IF($A17="","",ABS(SUMIFS('Raw daily data'!$F:$F,'Raw daily data'!$I:$I,$A17,'Raw daily data'!$F:$F,"<0"))) -> 0 | S17: =IF(N17>0,O17/N17,"") | T17: =IF(R17>0,Q17/ABS(R17),"") | U17: =IF(F17>0,H17/F17,"") -> 0 | V17: =IF(H17<0,MIN(ABS(H17)/G17,1),0) -> 0 | W17: =IF($A17="","",_xlfn.MAXIFS('Raw daily data'!$J:$J,'Raw daily data'!$I:$I,$A17)) -> 0 | X17: =IF(W17>=0,0,ABS(W17)/G17) -> 0 | Y17: =IF($A17="","",ABS(MIN(0,_xlfn.MINIFS('Raw daily data'!$J:$J,'Raw daily data'!$I:$I,$A17)))/G17) -> 0
A18: 46049 | B18: 3 | C18: =TEXT(A18,"dddd") -> Tuesday | E18: =E17+H17 -> 7690.3823 | F18: =IF($A18="","",$E18*Summary!$B$8) -> 538.32676 | G18: =IF($A18="","",F18*Summary!$B$9) -> 1076.6535 | H18: =IF($A18="","",SUMIFS('Raw daily data'!$F:$F,'Raw daily data'!$I:$I,$A18)) -> 0 | I18: =I17+H18 -> 515.0023 | J18: =SUMIF($B$2:$B$41,B18,$H$2:$H$41) -> 0 | K18: =Summary!$B$6 -> 5000 | L18: =J18-K18 -> -5000 | N18: =IF($A18="","",COUNTIFS('Raw daily data'!$I:$I,$A18)) -> 0 | O18: =IF($A18="","",COUNTIFS('Raw daily data'!$I:$I,$A18,'Raw daily data'!$F:$F,">0")) -> 0 | P18: =IF($A18="","",COUNTIFS('Raw daily data'!$I:$I,$A18,'Raw daily data'!$F:$F,"<0")) -> 0 | Q18: =IF($A18="","",SUMIFS('Raw daily data'!$F:$F,'Raw daily data'!$I:$I,$A18,'Raw daily data'!$F:$F,">0")) -> 0 | R18: =IF($A18="","",ABS(SUMIFS('Raw daily data'!$F:$F,'Raw daily data'!$I:$I,$A18,'Raw daily data'!$F:$F,"<0"))) -> 0 | S18: =IF(N18>0,O18/N18,"") | T18: =IF(R18>0,Q18/ABS(R18),"") | U18: =IF(F18>0,H18/F18,"") -> 0 | V18: =IF(H18<0,MIN(ABS(H18)/G18,1),0) -> 0 | W18: =IF($A18="","",_xlfn.MAXIFS('Raw daily data'!$J:$J,'Raw daily data'!$I:$I,$A18)) -> 0 | X18: =IF(W18>=0,0,ABS(W18)/G18) -> 0 | Y18: =IF($A18="","",ABS(MIN(0,_xlfn.MINIFS('Raw daily data'!$J:$J,'Raw daily data'!$I:$I,$A18)))/G18) -> 0
A19: 46050 | B19: 3 | C19: =TEXT(A19,"dddd") -> Wednesday | E19: =E18+H18 -> 7690.3823 | F19: =IF($A19="","",$E19*Summary!$B$8) -> 538.32676 | G19: =IF($A19="","",F19*Summary!$B$9) -> 1076.6535 | H19: =IF($A19="","",SUMIFS('Raw daily data'!$F:$F,'Raw daily data'!$I:$I,$A19)) -> 0 | I19: =I18+H19 -> 515.0023 | J19: =SUMIF($B$2:$B$41,B19,$H$2:$H$41) -> 0 | K19: =Summary!$B$6 -> 5000 | L19: =J19-K19 -> -5000 | N19: =IF($A19="","",COUNTIFS('Raw daily data'!$I:$I,$A19)) -> 0 | O19: =IF($A19="","",COUNTIFS('Raw daily data'!$I:$I,$A19,'Raw daily data'!$F:$F,">0")) -> 0 | P19: =IF($A19="","",COUNTIFS('Raw daily data'!$I:$I,$A19,'Raw daily data'!$F:$F,"<0")) -> 0 | Q19: =IF($A19="","",SUMIFS('Raw daily data'!$F:$F,'Raw daily data'!$I:$I,$A19,'Raw daily data'!$F:$F,">0")) -> 0 | R19: =IF($A19="","",ABS(SUMIFS('Raw daily data'!$F:$F,'Raw daily data'!$I:$I,$A19,'Raw daily data'!$F:$F,"<0"))) -> 0 | S19: =IF(N19>0,O19/N19,"") | T19: =IF(R19>0,Q19/ABS(R19),"") | U19: =IF(F19>0,H19/F19,"") -> 0 | V19: =IF(H19<0,MIN(ABS(H19)/G19,1),0) -> 0 | W19: =IF($A19="","",_xlfn.MAXIFS('Raw daily data'!$J:$J,'Raw daily data'!$I:$I,$A19)) -> 0 | X19: =IF(W19>=0,0,ABS(W19)/G19) -> 0 | Y19: =IF($A19="","",ABS(MIN(0,_xlfn.MINIFS('Raw daily data'!$J:$J,'Raw daily data'!$I:$I,$A19)))/G19) -> 0
A20: 46051 | B20: 3 | C20: =TEXT(A20,"dddd") -> Thursday | E20: =E19+H19 -> 7690.3823 | F20: =IF($A20="","",$E20*Summary!$B$8) -> 538.32676 | G20: =IF($A20="","",F20*Summary!$B$9) -> 1076.6535 | H20: =IF($A20="","",SUMIFS('Raw daily data'!$F:$F,'Raw daily data'!$I:$I,$A20)) -> 0 | I20: =I19+H20 -> 515.0023 | J20: =SUMIF($B$2:$B$41,B20,$H$2:$H$41) -> 0 | K20: =Summary!$B$6 -> 5000 | L20: =J20-K20 -> -5000 | N20: =IF($A20="","",COUNTIFS('Raw daily data'!$I:$I,$A20)) -> 0 | O20: =IF($A20="","",COUNTIFS('Raw daily data'!$I:$I,$A20,'Raw daily data'!$F:$F,">0")) -> 0 | P20: =IF($A20="","",COUNTIFS('Raw daily data'!$I:$I,$A20,'Raw daily data'!$F:$F,"<0")) -> 0 | Q20: =IF($A20="","",SUMIFS('Raw daily data'!$F:$F,'Raw daily data'!$I:$I,$A20,'Raw daily data'!$F:$F,">0")) -> 0 | R20: =IF($A20="","",ABS(SUMIFS('Raw daily data'!$F:$F,'Raw daily data'!$I:$I,$A20,'Raw daily data'!$F:$F,"<0"))) -> 0 | S20: =IF(N20>0,O20/N20,"") | T20: =IF(R20>0,Q20/ABS(R20),"") | U20: =IF(F20>0,H20/F20,"") -> 0 | V20: =IF(H20<0,MIN(ABS(H20)/G20,1),0) -> 0 | W20: =IF($A20="","",_xlfn.MAXIFS('Raw daily data'!$J:$J,'Raw daily data'!$I:$I,$A20)) -> 0 | X20: =IF(W20>=0,0,ABS(W20)/G20) -> 0 | Y20: =IF($A20="","",ABS(MIN(0,_xlfn.MINIFS('Raw daily data'!$J:$J,'Raw daily data'!$I:$I,$A20)))/G20) -> 0
A21: 46052 | B21: 3 | C21: =TEXT(A21,"dddd") -> Friday | E21: =E20+H20 -> 7690.3823 | F21: =IF($A21="","",$E21*Summary!$B$8) -> 538.32676 | G21: =IF($A21="","",F21*Summary!$B$9) -> 1076.6535 | H21: =IF($A21="","",SUMIFS('Raw daily data'!$F:$F,'Raw daily data'!$I:$I,$A21)) -> 0 | I21: =I20+H21 -> 515.0023 | J21: =SUMIF($B$2:$B$41,B21,$H$2:$H$41) -> 0 | K21: =Summary!$B$6 -> 5000 | L21: =J21-K21 -> -5000 | N21: =IF($A21="","",COUNTIFS('Raw daily data'!$I:$I,$A21)) -> 0 | O21: =IF($A21="","",COUNTIFS('Raw daily data'!$I:$I,$A21,'Raw daily data'!$F:$F,">0")) -> 0 | P21: =IF($A21="","",COUNTIFS('Raw daily data'!$I:$I,$A21,'Raw daily data'!$F:$F,"<0")) -> 0 | Q21: =IF($A21="","",SUMIFS('Raw daily data'!$F:$F,'Raw daily data'!$I:$I,$A21,'Raw daily data'!$F:$F,">0")) -> 0 | R21: =IF($A21="","",ABS(SUMIFS('Raw daily data'!$F:$F,'Raw daily data'!$I:$I,$A21,'Raw daily data'!$F:$F,"<0"))) -> 0 | S21: =IF(N21>0,O21/N21,"") | T21: =IF(R21>0,Q21/ABS(R21),"") | U21: =IF(F21>0,H21/F21,"") -> 0 | V21: =IF(H21<0,MIN(ABS(H21)/G21,1),0) -> 0 | W21: =IF($A21="","",_xlfn.MAXIFS('Raw daily data'!$J:$J,'Raw daily data'!$I:$I,$A21)) -> 0 | X21: =IF(W21>=0,0,ABS(W21)/G21) -> 0 | Y21: =IF($A21="","",ABS(MIN(0,_xlfn.MINIFS('Raw daily data'!$J:$J,'Raw daily data'!$I:$I,$A21)))/G21) -> 0
A22: 46053 | B22: 3 | C22: =TEXT(A22,"dddd") -> Saturday | D22: N | E22: =E21+H21 -> 7690.3823 | F22: =IF($A22="","",$E22*Summary!$B$8) -> 538.32676 | G22: =IF($A22="","",F22*Summary!$B$9) -> 1076.6535 | H22: =IF($A22="","",SUMIFS('Raw daily data'!$F:$F,'Raw daily data'!$I:$I,$A22)) -> 0 | I22: =I21+H22 -> 515.0023 | J22: =SUMIF($B$2:$B$41,B22,$H$2:$H$41) -> 0 | K22: =Summary!$B$6 -> 5000 | L22: =J22-K22 -> -5000 | N22: =IF($A22="","",COUNTIFS('Raw daily data'!$I:$I,$A22)) -> 0 | O22: =IF($A22="","",COUNTIFS('Raw daily data'!$I:$I,$A22,'Raw daily data'!$F:$F,">0")) -> 0 | P22: =IF($A22="","",COUNTIFS('Raw daily data'!$I:$I,$A22,'Raw daily data'!$F:$F,"<0")) -> 0 | Q22: =IF($A22="","",SUMIFS('Raw daily data'!$F:$F,'Raw daily data'!$I:$I,$A22,'Raw daily data'!$F:$F,">0")) -> 0 | R22: =IF($A22="","",ABS(SUMIFS('Raw daily data'!$F:$F,'Raw daily data'!$I:$I,$A22,'Raw daily data'!$F:$F,"<0"))) -> 0 | S22: =IF(N22>0,O22/N22,"") | T22: =IF(R22>0,Q22/ABS(R22),"") | U22: =IF(F22>0,H22/F22,"") -> 0 | V22: =IF(H22<0,MIN(ABS(H22)/G22,1),0) -> 0 | W22: =IF($A22="","",_xlfn.MAXIFS('Raw daily data'!$J:$J,'Raw daily data'!$I:$I,$A22)) -> 0 | X22: =IF(W22>=0,0,ABS(W22)/G22) -> 0 | Y22: =IF($A22="","",ABS(MIN(0,_xlfn.MINIFS('Raw daily data'!$J:$J,'Raw daily data'!$I:$I,$A22)))/G22) -> 0
A23: 46054 | B23: 4 | C23: =TEXT(A23,"dddd") -> Sunday | D23: N | E23: =E22+H22 -> 7690.3823 | F23: =IF($A23="","",$E23*Summary!$B$8) -> 538.32676 | G23: =IF($A23="","",F23*Summary!$B$9) -> 1076.6535 | H23: =IF($A23="","",SUMIFS('Raw daily data'!$F:$F,'Raw daily data'!$I:$I,$A23)) -> 0 | I23: =I22+H23 -> 515.0023 | J23: =SUMIF($B$2:$B$41,B23,$H$2:$H$41) -> 0 | K23: =Summary!$B$6 -> 5000 | L23: =J23-K23 -> -5000 | N23: =IF($A23="","",COUNTIFS('Raw daily data'!$I:$I,$A23)) -> 0 | O23: =IF($A23="","",COUNTIFS('Raw daily data'!$I:$I,$A23,'Raw daily data'!$F:$F,">0")) -> 0 | P23: =IF($A23="","",COUNTIFS('Raw daily data'!$I:$I,$A23,'Raw daily data'!$F:$F,"<0")) -> 0 | Q23: =IF($A23="","",SUMIFS('Raw daily data'!$F:$F,'Raw daily data'!$I:$I,$A23,'Raw daily data'!$F:$F,">0")) -> 0 | R23: =IF($A23="","",ABS(SUMIFS('Raw daily data'!$F:$F,'Raw daily data'!$I:$I,$A23,'Raw daily data'!$F:$F,"<0"))) -> 0 | S23: =IF(N23>0,O23/N23,"") | T23: =IF(R23>0,Q23/ABS(R23),"") | U23: =IF(F23>0,H23/F23,"") -> 0 | V23: =IF(H23<0,MIN(ABS(H23)/G23,1),0) -> 0 | W23: =IF($A23="","",_xlfn.MAXIFS('Raw daily data'!$J:$J,'Raw daily data'!$I:$I,$A23)) -> 0 | X23: =IF(W23>=0,0,ABS(W23)/G23) -> 0 | Y23: =IF($A23="","",ABS(MIN(0,_xlfn.MINIFS('Raw daily data'!$J:$J,'Raw daily data'!$I:$I,$A23)))/G23) -> 0
A24: 46055 | B24: 4 | C24: =TEXT(A24,"dddd") -> Monday | F24: =IF($A24="","",$E24*Summary!$B$8) -> 0 | G24: =IF($A24="","",F24*Summary!$B$9) -> 0 | H24: =IF($A24="","",SUMIFS('Raw daily data'!$F:$F,'Raw daily data'!$I:$I,$A24)) -> 0 | I24: =I23+H24 -> 515.0023 | J24: =SUMIF($B$2:$B$41,B24,$H$2:$H$41) -> 0 | K24: =Summary!$B$6 -> 5000 | L24: =J24-K24 -> -5000 | N24: =IF($A24="","",COUNTIFS('Raw daily data'!$I:$I,$A24)) -> 0 | O24: =IF($A24="","",COUNTIFS('Raw daily data'!$I:$I,$A24,'Raw daily data'!$F:$F,">0")) -> 0 | P24: =IF($A24="","",COUNTIFS('Raw daily data'!$I:$I,$A24,'Raw daily data'!$F:$F,"<0")) -> 0 | Q24: =IF($A24="","",SUMIFS('Raw daily data'!$F:$F,'Raw daily data'!$I:$I,$A24,'Raw daily data'!$F:$F,">0")) -> 0 | R24: =IF($A24="","",ABS(SUMIFS('Raw daily data'!$F:$F,'Raw daily data'!$I:$I,$A24,'Raw daily data'!$F:$F,"<0"))) -> 0 | S24: =IF(N24>0,O24/N24,"") | T24: =IF(R24>0,Q24/ABS(R24),"") | U24: =IF(F24>0,H24/F24,"") | V24: =IF(H24<0,MIN(ABS(H24)/G24,1),0) -> 0 | W24: =IF($A24="","",_xlfn.MAXIFS('Raw daily data'!$J:$J,'Raw daily data'!$I:$I,$A24)) -> 0 | X24: =IF(W24>=0,0,ABS(W24)/G24) -> 0 | Y24: =IFERROR(IF($A24="","",ABS(MIN(0,_xlfn.MINIFS('Raw daily data'!$J:$J,'Raw daily data'!$I:$I,$A24)))/G24),"")
A25: 46056 | B25: 4 | C25: =TEXT(A25,"dddd") -> Tuesday | F25: =IF($A25="","",$E25*Summary!$B$8) -> 0 | G25: =IF($A25="","",F25*Summary!$B$9) -> 0 | H25: =IF($A25="","",SUMIFS('Raw daily data'!$F:$F,'Raw daily data'!$I:$I,$A25)) -> 0 | I25: =I24+H25 -> 515.0023 | J25: =SUMIF($B$2:$B$41,B25,$H$2:$H$41) -> 0 | K25: =Summary!$B$6 -> 5000 | L25: =J25-K25 -> -5000 | N25: =IF($A25="","",COUNTIFS('Raw daily data'!$I:$I,$A25)) -> 0 | O25: =IF($A25="","",COUNTIFS('Raw daily data'!$I:$I,$A25,'Raw daily data'!$F:$F,">0")) -> 0 | P25: =IF($A25="","",COUNTIFS('Raw daily data'!$I:$I,$A25,'Raw daily data'!$F:$F,"<0")) -> 0 | Q25: =IF($A25="","",SUMIFS('Raw daily data'!$F:$F,'Raw daily data'!$I:$I,$A25,'Raw daily data'!$F:$F,">0")) -> 0 | R25: =IF($A25="","",ABS(SUMIFS('Raw daily data'!$F:$F,'Raw daily data'!$I:$I,$A25,'Raw daily data'!$F:$F,"<0"))) -> 0 | S25: =IF(N25>0,O25/N25,"") | T25: =IF(R25>0,Q25/ABS(R25),"") | U25: =IF(F25>0,H25/F25,"") | V25: =IF(H25<0,MIN(ABS(H25)/G25,1),0) -> 0 | W25: =IF($A25="","",_xlfn.MAXIFS('Raw daily data'!$J:$J,'Raw daily data'!$I:$I,$A25)) -> 0 | X25: =IF(W25>=0,0,ABS(W25)/G25) -> 0 | Y25: =IFERROR(IF($A25="","",ABS(MIN(0,_xlfn.MINIFS('Raw daily data'!$J:$J,'Raw daily data'!$I:$I,$A25)))/G25),"")
A26: 46057 | B26: 4 | C26: =TEXT(A26,"dddd") -> Wednesday | F26: =IF($A26="","",$E26*Summary!$B$8) -> 0 | G26: =IF($A26="","",F26*Summary!$B$9) -> 0 | H26: =IF($A26="","",SUMIFS('Raw daily data'!$F:$F,'Raw daily data'!$I:$I,$A26)) -> 0 | I26: =I25+H26 -> 515.0023 | J26: =SUMIF($B$2:$B$41,B26,$H$2:$H$41) -> 0 | K26: =Summary!$B$6 -> 5000 | L26: =J26-K26 -> -5000 | N26: =IF($A26="","",COUNTIFS('Raw daily data'!$I:$I,$A26)) -> 0 | O26: =IF($A26="","",COUNTIFS('Raw daily data'!$I:$I,$A26,'Raw daily data'!$F:$F,">0")) -> 0 | P26: =IF($A26="","",COUNTIFS('Raw daily data'!$I:$I,$A26,'Raw daily data'!$F:$F,"<0")) -> 0 | Q26: =IF($A26="","",SUMIFS('Raw daily data'!$F:$F,'Raw daily data'!$I:$I,$A26,'Raw daily data'!$F:$F,">0")) -> 0 | R26: =IF($A26="","",ABS(SUMIFS('Raw daily data'!$F:$F,'Raw daily data'!$I:$I,$A26,'Raw daily data'!$F:$F,"<0"))) -> 0 | S26: =IF(N26>0,O26/N26,"") | T26: =IF(R26>0,Q26/ABS(R26),"") | U26: =IF(F26>0,H26/F26,"") | V26: =IF(H26<0,MIN(ABS(H26)/G26,1),0) -> 0 | W26: =IF($A26="","",_xlfn.MAXIFS('Raw daily data'!$J:$J,'Raw daily data'!$I:$I,$A26)) -> 0 | X26: =IF(W26>=0,0,ABS(W26)/G26) -> 0 | Y26: =IFERROR(IF($A26="","",ABS(MIN(0,_xlfn.MINIFS('Raw daily data'!$J:$J,'Raw daily data'!$I:$I,$A26)))/G26),"")
A27: 46058 | B27: 4 | C27: =TEXT(A27,"dddd") -> Thursday | F27: =IF($A27="","",$E27*Summary!$B$8) -> 0 | G27: =IF($A27="","",F27*Summary!$B$9) -> 0 | H27: =IF($A27="","",SUMIFS('Raw daily data'!$F:$F,'Raw daily data'!$I:$I,$A27)) -> 0 | I27: =I26+H27 -> 515.0023 | J27: =SUMIF($B$2:$B$41,B27,$H$2:$H$41) -> 0 | K27: =Summary!$B$6 -> 5000 | L27: =J27-K27 -> -5000 | N27: =IF($A27="","",COUNTIFS('Raw daily data'!$I:$I,$A27)) -> 0 | O27: =IF($A27="","",COUNTIFS('Raw daily data'!$I:$I,$A27,'Raw daily data'!$F:$F,">0")) -> 0 | P27: =IF($A27="","",COUNTIFS('Raw daily data'!$I:$I,$A27,'Raw daily data'!$F:$F,"<0")) -> 0 | Q27: =IF($A27="","",SUMIFS('Raw daily data'!$F:$F,'Raw daily data'!$I:$I,$A27,'Raw daily data'!$F:$F,">0")) -> 0 | R27: =IF($A27="","",ABS(SUMIFS('Raw daily data'!$F:$F,'Raw daily data'!$I:$I,$A27,'Raw daily data'!$F:$F,"<0"))) -> 0 | S27: =IF(N27>0,O27/N27,"") | T27: =IF(R27>0,Q27/ABS(R27),"") | U27: =IF(F27>0,H27/F27,"") | V27: =IF(H27<0,MIN(ABS(H27)/G27,1),0) -> 0 | W27: =IF($A27="","",_xlfn.MAXIFS('Raw daily data'!$J:$J,'Raw daily data'!$I:$I,$A27)) -> 0 | X27: =IF(W27>=0,0,ABS(W27)/G27) -> 0 | Y27: =IFERROR(IF($A27="","",ABS(MIN(0,_xlfn.MINIFS('Raw daily data'!$J:$J,'Raw daily data'!$I:$I,$A27)))/G27),"")
A28: 46059 | B28: 4 | C28: =TEXT(A28,"dddd") -> Friday | F28: =IF($A28="","",$E28*Summary!$B$8) -> 0 | G28: =IF($A28="","",F28*Summary!$B$9) -> 0 | H28: =IF($A28="","",SUMIFS('Raw daily data'!$F:$F,'Raw daily data'!$I:$I,$A28)) -> 0 | I28: =I27+H28 -> 515.0023 | J28: =SUMIF($B$2:$B$41,B28,$H$2:$H$41) -> 0 | K28: =Summary!$B$6 -> 5000 | L28: =J28-K28 -> -5000 | N28: =IF($A28="","",COUNTIFS('Raw daily data'!$I:$I,$A28)) -> 0 | O28: =IF($A28="","",COUNTIFS('Raw daily data'!$I:$I,$A28,'Raw daily data'!$F:$F,">0")) -> 0 | P28: =IF($A28="","",COUNTIFS('Raw daily data'!$I:$I,$A28,'Raw daily data'!$F:$F,"<0")) -> 0 | Q28: =IF($A28="","",SUMIFS('Raw daily data'!$F:$F,'Raw daily data'!$I:$I,$A28,'Raw daily data'!$F:$F,">0")) -> 0 | R28: =IF($A28="","",ABS(SUMIFS('Raw daily data'!$F:$F,'Raw daily data'!$I:$I,$A28,'Raw daily data'!$F:$F,"<0"))) -> 0 | S28: =IF(N28>0,O28/N28,"") | T28: =IF(R28>0,Q28/ABS(R28),"") | U28: =IF(F28>0,H28/F28,"") | V28: =IF(H28<0,MIN(ABS(H28)/G28,1),0) -> 0 | W28: =IF($A28="","",_xlfn.MAXIFS('Raw daily data'!$J:$J,'Raw daily data'!$I:$I,$A28)) -> 0 | X28: =IF(W28>=0,0,ABS(W28)/G28) -> 0 | Y28: =IFERROR(IF($A28="","",ABS(MIN(0,_xlfn.MINIFS('Raw daily data'!$J:$J,'Raw daily data'!$I:$I,$A28)))/G28),"")
A29: 46060 | B29: 4 | C29: =TEXT(A29,"dddd") -> Saturday | D29: N | F29: =IF($A29="","",$E29*Summary!$B$8) -> 0 | G29: =IF($A29="","",F29*Summary!$B$9) -> 0 | H29: =IF($A29="","",SUMIFS('Raw daily data'!$F:$F,'Raw daily data'!$I:$I,$A29)) -> 0 | I29: =I28+H29 -> 515.0023 | J29: =SUMIF($B$2:$B$41,B29,$H$2:$H$41) -> 0 | K29: =Summary!$B$6 -> 5000 | L29: =J29-K29 -> -5000 | N29: =IF($A29="","",COUNTIFS('Raw daily data'!$I:$I,$A29)) -> 0 | O29: =IF($A29="","",COUNTIFS('Raw daily data'!$I:$I,$A29,'Raw daily data'!$F:$F,">0")) -> 0 | P29: =IF($A29="","",COUNTIFS('Raw daily data'!$I:$I,$A29,'Raw daily data'!$F:$F,"<0")) -> 0 | Q29: =IF($A29="","",SUMIFS('Raw daily data'!$F:$F,'Raw daily data'!$I:$I,$A29,'Raw daily data'!$F:$F,">0")) -> 0 | R29: =IF($A29="","",ABS(SUMIFS('Raw daily data'!$F:$F,'Raw daily data'!$I:$I,$A29,'Raw daily data'!$F:$F,"<0"))) -> 0 | S29: =IF(N29>0,O29/N29,"") | T29: =IF(R29>0,Q29/ABS(R29),"") | U29: =IF(F29>0,H29/F29,"") | V29: =IF(H29<0,MIN(ABS(H29)/G29,1),0) -> 0 | W29: =IF($A29="","",_xlfn.MAXIFS('Raw daily data'!$J:$J,'Raw daily data'!$I:$I,$A29)) -> 0 | X29: =IF(W29>=0,0,ABS(W29)/G29) -> 0 | Y29: =IFERROR(IF($A29="","",ABS(MIN(0,_xlfn.MINIFS('Raw daily data'!$J:$J,'Raw daily data'!$I:$I,$A29)))/G29),"")
A30: 46061 | B30: 4 | C30: =TEXT(A30,"dddd") -> Sunday | D30: N | F30: =IF($A30="","",$E30*Summary!$B$8) -> 0 | G30: =IF($A30="","",F30*Summary!$B$9) -> 0 | H30: =IF($A30="","",SUMIFS('Raw daily data'!$F:$F,'Raw daily data'!$I:$I,$A30)) -> 0 | I30: =I29+H30 -> 515.0023 | J30: =SUMIF($B$2:$B$41,B30,$H$2:$H$41) -> 0 | K30: =Summary!$B$6 -> 5000 | L30: =J30-K30 -> -5000 | N30: =IF($A30="","",COUNTIFS('Raw daily data'!$I:$I,$A30)) -> 0 | O30: =IF($A30="","",COUNTIFS('Raw daily data'!$I:$I,$A30,'Raw daily data'!$F:$F,">0")) -> 0 | P30: =IF($A30="","",COUNTIFS('Raw daily data'!$I:$I,$A30,'Raw daily data'!$F:$F,"<0")) -> 0 | Q30: =IF($A30="","",SUMIFS('Raw daily data'!$F:$F,'Raw daily data'!$I:$I,$A30,'Raw daily data'!$F:$F,">0")) -> 0 | R30: =IF($A30="","",ABS(SUMIFS('Raw daily data'!$F:$F,'Raw daily data'!$I:$I,$A30,'Raw daily data'!$F:$F,"<0"))) -> 0 | S30: =IF(N30>0,O30/N30,"") | T30: =IF(R30>0,Q30/ABS(R30),"") | U30: =IF(F30>0,H30/F30,"") | V30: =IF(H30<0,MIN(ABS(H30)/G30,1),0) -> 0 | W30: =IF($A30="","",_xlfn.MAXIFS('Raw daily data'!$J:$J,'Raw daily data'!$I:$I,$A30)) -> 0 | X30: =IF(W30>=0,0,ABS(W30)/G30) -> 0 | Y30: =IFERROR(IF($A30="","",ABS(MIN(0,_xlfn.MINIFS('Raw daily data'!$J:$J,'Raw daily data'!$I:$I,$A30)))/G30),"")
A31: 46062 | C31: =TEXT(A31,"dddd") -> Monday | F31: =IF($A31="","",$E31*Summary!$B$8) -> 0 | G31: =IF($A31="","",F31*Summary!$B$9) -> 0 | H31: =IF($A31="","",SUMIFS('Raw daily data'!$F:$F,'Raw daily data'!$I:$I,$A31)) -> 0 | I31: =I30+H31 -> 515.0023 | J31: =SUMIF($B$2:$B$41,B31,$H$2:$H$41) -> 0 | K31: =Summary!$B$6 -> 5000 | L31: =J31-K31 -> -5000 | N31: =IF($A31="","",COUNTIFS('Raw daily data'!$I:$I,$A31)) -> 0 | O31: =IF($A31="","",COUNTIFS('Raw daily data'!$I:$I,$A31,'Raw daily data'!$F:$F,">0")) -> 0 | P31: =IF($A31="","",COUNTIFS('Raw daily data'!$I:$I,$A31,'Raw daily data'!$F:$F,"<0")) -> 0 | Q31: =IF($A31="","",SUMIFS('Raw daily data'!$F:$F,'Raw daily data'!$I:$I,$A31,'Raw daily data'!$F:$F,">0")) -> 0 | R31: =IF($A31="","",ABS(SUMIFS('Raw daily data'!$F:$F,'Raw daily data'!$I:$I,$A31,'Raw daily data'!$F:$F,"<0"))) -> 0 | S31: =IF(N31>0,O31/N31,"") | T31: =IF(R31>0,Q31/ABS(R31),"") | U31: =IF(F31>0,H31/F31,"") | V31: =IF(H31<0,MIN(ABS(H31)/G31,1),0) -> 0 | W31: =IF($A31="","",_xlfn.MAXIFS('Raw daily data'!$J:$J,'Raw daily data'!$I:$I,$A31)) -> 0 | X31: =IF(W31>=0,0,ABS(W31)/G31) -> 0 | Y31: =IFERROR(IF($A31="","",ABS(MIN(0,_xlfn.MINIFS('Raw daily data'!$J:$J,'Raw daily data'!$I:$I,$A31)))/G31),"")
A32: 46063 | C32: =TEXT(A32,"dddd") -> Tuesday | F32: =IF($A32="","",$E32*Summary!$B$8) -> 0 | G32: =IF($A32="","",F32*Summary!$B$9) -> 0 | H32: =IF($A32="","",SUMIFS('Raw daily data'!$F:$F,'Raw daily data'!$I:$I,$A32)) -> 0 | I32: =I31+H32 -> 515.0023 | J32: =SUMIF($B$2:$B$41,B32,$H$2:$H$41) -> 0 | K32: =Summary!$B$6 -> 5000 | L32: =J32-K32 -> -5000 | N32: =IF($A32="","",COUNTIFS('Raw daily data'!$I:$I,$A32)) -> 0 | O32: =IF($A32="","",COUNTIFS('Raw daily data'!$I:$I,$A32,'Raw daily data'!$F:$F,">0")) -> 0 | P32: =IF($A32="","",COUNTIFS('Raw daily data'!$I:$I,$A32,'Raw daily data'!$F:$F,"<0")) -> 0 | Q32: =IF($A32="","",SUMIFS('Raw daily data'!$F:$F,'Raw daily data'!$I:$I,$A32,'Raw daily data'!$F:$F,">0")) -> 0 | R32: =IF($A32="","",ABS(SUMIFS('Raw daily data'!$F:$F,'Raw daily data'!$I:$I,$A32,'Raw daily data'!$F:$F,"<0"))) -> 0 | S32: =IF(N32>0,O32/N32,"") | T32: =IF(R32>0,Q32/ABS(R32),"") | U32: =IF(F32>0,H32/F32,"") | V32: =IF(H32<0,MIN(ABS(H32)/G32,1),0) -> 0 | W32: =IF($A32="","",_xlfn.MAXIFS('Raw daily data'!$J:$J,'Raw daily data'!$I:$I,$A32)) -> 0 | X32: =IF(W32>=0,0,ABS(W32)/G32) -> 0 | Y32: =IFERROR(IF($A32="","",ABS(MIN(0,_xlfn.MINIFS('Raw daily data'!$J:$J,'Raw daily data'!$I:$I,$A32)))/G32),"")
A33: 46064 | C33: =TEXT(A33,"dddd") -> Wednesday | F33: =IF($A33="","",$E33*Summary!$B$8) -> 0 | G33: =IF($A33="","",F33*Summary!$B$9) -> 0 | H33: =IF($A33="","",SUMIFS('Raw daily data'!$F:$F,'Raw daily data'!$I:$I,$A33)) -> 0 | I33: =I32+H33 -> 515.0023 | J33: =SUMIF($B$2:$B$41,B33,$H$2:$H$41) -> 0 | K33: =Summary!$B$6 -> 5000 | L33: =J33-K33 -> -5000 | N33: =IF($A33="","",COUNTIFS('Raw daily data'!$I:$I,$A33)) -> 0 | O33: =IF($A33="","",COUNTIFS('Raw daily data'!$I:$I,$A33,'Raw daily data'!$F:$F,">0")) -> 0 | P33: =IF($A33="","",COUNTIFS('Raw daily data'!$I:$I,$A33,'Raw daily data'!$F:$F,"<0")) -> 0 | Q33: =IF($A33="","",SUMIFS('Raw daily data'!$F:$F,'Raw daily data'!$I:$I,$A33,'Raw daily data'!$F:$F,">0")) -> 0 | R33: =IF($A33="","",ABS(SUMIFS('Raw daily data'!$F:$F,'Raw daily data'!$I:$I,$A33,'Raw daily data'!$F:$F,"<0"))) -> 0 | S33: =IF(N33>0,O33/N33,"") | T33: =IF(R33>0,Q33/ABS(R33),"") | U33: =IF(F33>0,H33/F33,"") | V33: =IF(H33<0,MIN(ABS(H33)/G33,1),0) -> 0 | W33: =IF($A33="","",_xlfn.MAXIFS('Raw daily data'!$J:$J,'Raw daily data'!$I:$I,$A33)) -> 0 | X33: =IF(W33>=0,0,ABS(W33)/G33) -> 0 | Y33: =IFERROR(IF($A33="","",ABS(MIN(0,_xlfn.MINIFS('Raw daily data'!$J:$J,'Raw daily data'!$I:$I,$A33)))/G33),"")
A34: 46065 | C34: =TEXT(A34,"dddd") -> Thursday | F34: =IF($A34="","",$E34*Summary!$B$8) -> 0 | G34: =IF($A34="","",F34*Summary!$B$9) -> 0 | H34: =IF($A34="","",SUMIFS('Raw daily data'!$F:$F,'Raw daily data'!$I:$I,$A34)) -> 0 | I34: =I33+H34 -> 515.0023 | J34: =SUMIF($B$2:$B$41,B34,$H$2:$H$41) -> 0 | K34: =Summary!$B$6 -> 5000 | L34: =J34-K34 -> -5000 | N34: =IF($A34="","",COUNTIFS('Raw daily data'!$I:$I,$A34)) -> 0 | O34: =IF($A34="","",COUNTIFS('Raw daily data'!$I:$I,$A34,'Raw daily data'!$F:$F,">0")) -> 0 | P34: =IF($A34="","",COUNTIFS('Raw daily data'!$I:$I,$A34,'Raw daily data'!$F:$F,"<0")) -> 0 | Q34: =IF($A34="","",SUMIFS('Raw daily data'!$F:$F,'Raw daily data'!$I:$I,$A34,'Raw daily data'!$F:$F,">0")) -> 0 | R34: =IF($A34="","",ABS(SUMIFS('Raw daily data'!$F:$F,'Raw daily data'!$I:$I,$A34,'Raw daily data'!$F:$F,"<0"))) -> 0 | S34: =IF(N34>0,O34/N34,"") | T34: =IF(R34>0,Q34/ABS(R34),"") | U34: =IF(F34>0,H34/F34,"") | V34: =IF(H34<0,MIN(ABS(H34)/G34,1),0) -> 0 | W34: =IF($A34="","",_xlfn.MAXIFS('Raw daily data'!$J:$J,'Raw daily data'!$I:$I,$A34)) -> 0 | X34: =IF(W34>=0,0,ABS(W34)/G34) -> 0 | Y34: =IFERROR(IF($A34="","",ABS(MIN(0,_xlfn.MINIFS('Raw daily data'!$J:$J,'Raw daily data'!$I:$I,$A34)))/G34),"")
A35: 46066 | C35: =TEXT(A35,"dddd") -> Friday | F35: =IF($A35="","",$E35*Summary!$B$8) -> 0 | G35: =IF($A35="","",F35*Summary!$B$9) -> 0 | H35: =IF($A35="","",SUMIFS('Raw daily data'!$F:$F,'Raw daily data'!$I:$I,$A35)) -> 0 | I35: =I34+H35 -> 515.0023 | J35: =SUMIF($B$2:$B$41,B35,$H$2:$H$41) -> 0 | K35: =Summary!$B$6 -> 5000 | L35: =J35-K35 -> -5000 | N35: =IF($A35="","",COUNTIFS('Raw daily data'!$I:$I,$A35)) -> 0 | O35: =IF($A35="","",COUNTIFS('Raw daily data'!$I:$I,$A35,'Raw daily data'!$F:$F,">0")) -> 0 | P35: =IF($A35="","",COUNTIFS('Raw daily data'!$I:$I,$A35,'Raw daily data'!$F:$F,"<0")) -> 0 | Q35: =IF($A35="","",SUMIFS('Raw daily data'!$F:$F,'Raw daily data'!$I:$I,$A35,'Raw daily data'!$F:$F,">0")) -> 0 | R35: =IF($A35="","",ABS(SUMIFS('Raw daily data'!$F:$F,'Raw daily data'!$I:$I,$A35,'Raw daily data'!$F:$F,"<0"))) -> 0 | S35: =IF(N35>0,O35/N35,"") | T35: =IF(R35>0,Q35/ABS(R35),"") | U35: =IF(F35>0,H35/F35,"") | V35: =IF(H35<0,MIN(ABS(H35)/G35,1),0) -> 0 | W35: =IF($A35="","",_xlfn.MAXIFS('Raw daily data'!$J:$J,'Raw daily data'!$I:$I,$A35)) -> 0 | X35: =IF(W35>=0,0,ABS(W35)/G35) -> 0 | Y35: =IFERROR(IF($A35="","",ABS(MIN(0,_xlfn.MINIFS('Raw daily data'!$J:$J,'Raw daily data'!$I:$I,$A35)))/G35),"")
A36: 46067 | C36: =TEXT(A36,"dddd") -> Saturday | F36: =IF($A36="","",$E36*Summary!$B$8) -> 0 | G36: =IF($A36="","",F36*Summary!$B$9) -> 0 | H36: =IF($A36="","",SUMIFS('Raw daily data'!$F:$F,'Raw daily data'!$I:$I,$A36)) -> 0 | I36: =I35+H36 -> 515.0023 | J36: =SUMIF($B$2:$B$41,B36,$H$2:$H$41) -> 0 | K36: =Summary!$B$6 -> 5000 | L36: =J36-K36 -> -5000 | N36: =IF($A36="","",COUNTIFS('Raw daily data'!$I:$I,$A36)) -> 0 | O36: =IF($A36="","",COUNTIFS('Raw daily data'!$I:$I,$A36,'Raw daily data'!$F:$F,">0")) -> 0 | P36: =IF($A36="","",COUNTIFS('Raw daily data'!$I:$I,$A36,'Raw daily data'!$F:$F,"<0")) -> 0 | Q36: =IF($A36="","",SUMIFS('Raw daily data'!$F:$F,'Raw daily data'!$I:$I,$A36,'Raw daily data'!$F:$F,">0")) -> 0 | R36: =IF($A36="","",ABS(SUMIFS('Raw daily data'!$F:$F,'Raw daily data'!$I:$I,$A36,'Raw daily data'!$F:$F,"<0"))) -> 0 | S36: =IF(N36>0,O36/N36,"") | T36: =IF(R36>0,Q36/ABS(R36),"") | U36: =IF(F36>0,H36/F36,"") | V36: =IF(H36<0,MIN(ABS(H36)/G36,1),0) -> 0 | W36: =IF($A36="","",_xlfn.MAXIFS('Raw daily data'!$J:$J,'Raw daily data'!$I:$I,$A36)) -> 0 | X36: =IF(W36>=0,0,ABS(W36)/G36) -> 0 | Y36: =IFERROR(IF($A36="","",ABS(MIN(0,_xlfn.MINIFS('Raw daily data'!$J:$J,'Raw daily data'!$I:$I,$A36)))/G36),"")
A37: 46068 | C37: =TEXT(A37,"dddd") -> Sunday | F37: =IF($A37="","",$E37*Summary!$B$8) -> 0 | G37: =IF($A37="","",F37*Summary!$B$9) -> 0 | H37: =IF($A37="","",SUMIFS('Raw daily data'!$F:$F,'Raw daily data'!$I:$I,$A37)) -> 0 | I37: =I36+H37 -> 515.0023 | J37: =SUMIF($B$2:$B$41,B37,$H$2:$H$41) -> 0 | K37: =Summary!$B$6 -> 5000 | L37: =J37-K37 -> -5000 | N37: =IF($A37="","",COUNTIFS('Raw daily data'!$I:$I,$A37)) -> 0 | O37: =IF($A37="","",COUNTIFS('Raw daily data'!$I:$I,$A37,'Raw daily data'!$F:$F,">0")) -> 0 | P37: =IF($A37="","",COUNTIFS('Raw daily data'!$I:$I,$A37,'Raw daily data'!$F:$F,"<0")) -> 0 | Q37: =IF($A37="","",SUMIFS('Raw daily data'!$F:$F,'Raw daily data'!$I:$I,$A37,'Raw daily data'!$F:$F,">0")) -> 0 | R37: =IF($A37="","",ABS(SUMIFS('Raw daily data'!$F:$F,'Raw daily data'!$I:$I,$A37,'Raw daily data'!$F:$F,"<0"))) -> 0 | S37: =IF(N37>0,O37/N37,"") | T37: =IF(R37>0,Q37/ABS(R37),"") | U37: =IF(F37>0,H37/F37,"") | V37: =IF(H37<0,MIN(ABS(H37)/G37,1),0) -> 0 | W37: =IF($A37="","",_xlfn.MAXIFS('Raw daily data'!$J:$J,'Raw daily data'!$I:$I,$A37)) -> 0 | X37: =IF(W37>=0,0,ABS(W37)/G37) -> 0 | Y37: =IFERROR(IF($A37="","",ABS(MIN(0,_xlfn.MINIFS('Raw daily data'!$J:$J,'Raw daily data'!$I:$I,$A37)))/G37),"")
A38: 46069 | C38: =TEXT(A38,"dddd") -> Monday | F38: =IF($A38="","",$E38*Summary!$B$8) -> 0 | G38: =IF($A38="","",F38*Summary!$B$9) -> 0 | H38: =IF($A38="","",SUMIFS('Raw daily data'!$F:$F,'Raw daily data'!$I:$I,$A38)) -> 0 | I38: =I37+H38 -> 515.0023 | J38: =SUMIF($B$2:$B$41,B38,$H$2:$H$41) -> 0 | K38: =Summary!$B$6 -> 5000 | L38: =J38-K38 -> -5000 | N38: =IF($A38="","",COUNTIFS('Raw daily data'!$I:$I,$A38)) -> 0 | O38: =IF($A38="","",COUNTIFS('Raw daily data'!$I:$I,$A38,'Raw daily data'!$F:$F,">0")) -> 0 | P38: =IF($A38="","",COUNTIFS('Raw daily data'!$I:$I,$A38,'Raw daily data'!$F:$F,"<0")) -> 0 | Q38: =IF($A38="","",SUMIFS('Raw daily data'!$F:$F,'Raw daily data'!$I:$I,$A38,'Raw daily data'!$F:$F,">0")) -> 0 | R38: =IF($A38="","",ABS(SUMIFS('Raw daily data'!$F:$F,'Raw daily data'!$I:$I,$A38,'Raw daily data'!$F:$F,"<0"))) -> 0 | S38: =IF(N38>0,O38/N38,"") | T38: =IF(R38>0,Q38/ABS(R38),"") | U38: =IF(F38>0,H38/F38,"") | V38: =IF(H38<0,MIN(ABS(H38)/G38,1),0) -> 0 | W38: =IF($A38="","",_xlfn.MAXIFS('Raw daily data'!$J:$J,'Raw daily data'!$I:$I,$A38)) -> 0 | X38: =IF(W38>=0,0,ABS(W38)/G38) -> 0 | Y38: =IFERROR(IF($A38="","",ABS(MIN(0,_xlfn.MINIFS('Raw daily data'!$J:$J,'Raw daily data'!$I:$I,$A38)))/G38),"")
A39: 46070 | C39: =TEXT(A39,"dddd") -> Tuesday | F39: =IF($A39="","",$E39*Summary!$B$8) -> 0 | G39: =IF($A39="","",F39*Summary!$B$9) -> 0 | H39: =IF($A39="","",SUMIFS('Raw daily data'!$F:$F,'Raw daily data'!$I:$I,$A39)) -> 0 | I39: =I38+H39 -> 515.0023 | J39: =SUMIF($B$2:$B$41,B39,$H$2:$H$41) -> 0 | K39: =Summary!$B$6 -> 5000 | L39: =J39-K39 -> -5000 | N39: =IF($A39="","",COUNTIFS('Raw daily data'!$I:$I,$A39)) -> 0 | O39: =IF($A39="","",COUNTIFS('Raw daily data'!$I:$I,$A39,'Raw daily data'!$F:$F,">0")) -> 0 | P39: =IF($A39="","",COUNTIFS('Raw daily data'!$I:$I,$A39,'Raw daily data'!$F:$F,"<0")) -> 0 | Q39: =IF($A39="","",SUMIFS('Raw daily data'!$F:$F,'Raw daily data'!$I:$I,$A39,'Raw daily data'!$F:$F,">0")) -> 0 | R39: =IF($A39="","",ABS(SUMIFS('Raw daily data'!$F:$F,'Raw daily data'!$I:$I,$A39,'Raw daily data'!$F:$F,"<0"))) -> 0 | S39: =IF(N39>0,O39/N39,"") | T39: =IF(R39>0,Q39/ABS(R39),"") | U39: =IF(F39>0,H39/F39,"") | V39: =IF(H39<0,MIN(ABS(H39)/G39,1),0) -> 0 | W39: =IF($A39="","",_xlfn.MAXIFS('Raw daily data'!$J:$J,'Raw daily data'!$I:$I,$A39)) -> 0 | X39: =IF(W39>=0,0,ABS(W39)/G39) -> 0 | Y39: =IFERROR(IF($A39="","",ABS(MIN(0,_xlfn.MINIFS('Raw daily data'!$J:$J,'Raw daily data'!$I:$I,$A39)))/G39),"")
A40: 46071 | C40: =TEXT(A40,"dddd") -> Wednesday | F40: =IF($A40="","",$E40*Summary!$B$8) -> 0 | G40: =IF($A40="","",F40*Summary!$B$9) -> 0 | H40: =IF($A40="","",SUMIFS('Raw daily data'!$F:$F,'Raw daily data'!$I:$I,$A40)) -> 0 | I40: =I39+H40 -> 515.0023 | J40: =SUMIF($B$2:$B$41,B40,$H$2:$H$41) -> 0 | K40: =Summary!$B$6 -> 5000 | L40: =J40-K40 -> -5000 | N40: =IF($A40="","",COUNTIFS('Raw daily data'!$I:$I,$A40)) -> 0 | O40: =IF($A40="","",COUNTIFS('Raw daily data'!$I:$I,$A40,'Raw daily data'!$F:$F,">0")) -> 0 | P40: =IF($A40="","",COUNTIFS('Raw daily data'!$I:$I,$A40,'Raw daily data'!$F:$F,"<0")) -> 0 | Q40: =IF($A40="","",SUMIFS('Raw daily data'!$F:$F,'Raw daily data'!$I:$I,$A40,'Raw daily data'!$F:$F,">0")) -> 0 | R40: =IF($A40="","",ABS(SUMIFS('Raw daily data'!$F:$F,'Raw daily data'!$I:$I,$A40,'Raw daily data'!$F:$F,"<0"))) -> 0 | S40: =IF(N40>0,O40/N40,"") | T40: =IF(R40>0,Q40/ABS(R40),"") | U40: =IF(F40>0,H40/F40,"") | V40: =IF(H40<0,MIN(ABS(H40)/G40,1),0) -> 0 | W40: =IF($A40="","",_xlfn.MAXIFS('Raw daily data'!$J:$J,'Raw daily data'!$I:$I,$A40)) -> 0 | X40: =IF(W40>=0,0,ABS(W40)/G40) -> 0 | Y40: =IFERROR(IF($A40="","",ABS(MIN(0,_xlfn.MINIFS('Raw daily data'!$J:$J,'Raw daily data'!$I:$I,$A40)))/G40),"")
...

Sheet Raw daily data
A1: Symbol | B1: Name | C1: Side | D1: Quantity | E1: Price | F1: Profit | G1: Deal ID | H1: Time | I1: Trade Date | J1: Cumulative P&L for the day
A2: EURUSD | B2: EUR_USD | C2: sell | D2: 200000 | E2: 1.15899 | F2: -60 | G2: 12607 | H2: Wed, 11 Jan 2026 12:06:06 GMT | I2: =IF(H2="","",DATEVALUE(MID(H2,6,11))) -> 46033 | J2: =IF(F2="","",F2+IF(I2=I1,J1,0)) -> -60
A3: EURUSD | B3: EUR_USD | C3: sell | D3: 500002 | E3: 1.15829 | F3: 575.0023 | G3: 12594 | H3: Wed, 12 Jan 2026 12:06:06 GMT | I3: =IF(H3="","",DATEVALUE(MID(H3,6,11))) -> 46034 | J3: =IF(F3="","",F3+IF(I3=I2,J2,0)) -> 575.0023
I4: =IF(H4="","",DATEVALUE(MID(H4,6,11))) | J4: =IF(F4="","",F4+IF(I4=I3,J3,0))
I5: =IF(H5="","",DATEVALUE(MID(H5,6,11))) | J5: =IF(F5="","",F5+IF(I5=I4,J4,0))
I6: =IF(H6="","",DATEVALUE(MID(H6,6,11))) | J6: =IF(F6="","",F6+IF(I6=I5,J5,0))
I7: =IF(H7="","",DATEVALUE(MID(H7,6,11))) | J7: =IF(F7="","",F7+IF(I7=I6,J6,0))
I8: =IF(H8="","",DATEVALUE(MID(H8,6,11))) | J8: =IF(F8="","",F8+IF(I8=I7,J7,0))
I9: =IF(H9="","",DATEVALUE(MID(H9,6,11))) | J9: =IF(F9="","",F9+IF(I9=I8,J8,0))
I10: =IF(H10="","",DATEVALUE(MID(H10,6,11))) | J10: =IF(F10="","",F10+IF(I10=I9,J9,0))
I11: =IF(H11="","",DATEVALUE(MID(H11,6,11))) | J11: =IF(F11="","",F11+IF(I11=I10,J10,0))
I12: =IF(H12="","",DATEVALUE(MID(H12,6,11))) | J12: =IF(F12="","",F12+IF(I12=I11,J11,0))
I13: =IF(H13="","",DATEVALUE(MID(H13,6,11))) | J13: =IF(F13="","",F13+IF(I13=I12,J12,0))
I14: =IF(H14="","",DATEVALUE(MID(H14,6,11))) | J14: =IF(F14="","",F14+IF(I14=I13,J13,0))
I15: =IF(H15="","",DATEVALUE(MID(H15,6,11))) | J15: =IF(F15="","",F15+IF(I15=I14,J14,0))
... I52: =IF(H52="","",DATEVALUE(MID(H52,6,11))) | J52: =IF(F52="","",F52+IF(I52=I51,J51,0))

Sheet Setup Planner (old)
A1: Price/EMA's | B1: Value | D1: Monthly/weekly/daily TPO | E1: Value | G1: HTF & LTF fib anchors | H1: Value | J1: RSI | K1: Value | M1: PipTol | N1: Value | S1: Column1 | T1: Entry | U1: TP | V1: SL | W1: Pips to TP1 | X1: Reward at TP1 ($) | Y1: Pips to SL | Z1: Risk at SL ($) | AA1: R multiple at TP1 | AB1: Units | AC1: TF | AD1: Trend | AE1: Last BOS | AF1: Last CHOCH | AG1: Notes
A2: Current Price | B2: 1.16438 | D2: Monthly VAH | E2: 1.16562 | G2: HTF Swing Low (4H) | H2: 1.14931 | J2: RSI 15m | K2: 49.98 | M2: PipTol Value (for VAH/VAL/FVG) | N2: =ROUND($B$15*10000*0.5,0) -> 2 | P2: LongScore | Q2: =(1-0.5*$N$23)*(1-$B$34*$B$33)*($N$5+$N$7+$N$10+$N$13+$N$15+$N$26+$N$28) -> 1.225 | S2: Entry 0.382 | T2: =IF($N$30=1,$H$25,$B$2) -> 1.1615164 | U2: =K6 -> 1.1656 | V2: =K7 -> 1.162 | W2: =IF(OR(T2="",$U$2=""),"",ABS($U$2-T2)*10000) -> 40.836 | X2: =IF(W2="","",W2*T14*0.0001) -> 156.66845 | Y2: =IF($V$2="","",ABS(T2-$V$2)*10000) -> 4.836 | Z2: =IF(Y2="","",Y2*T14*0.0001) -> 18.553448 | AA2: =IF(OR($K$5=0,X2=""),"",X2/$K$5) -> 0.42336841 | AB2: =T14 -> 38365.278 | AC2: 1D | AD2: Bull | AE2: Down | AF2: Up
A3: EMA9 15m | B3: 1.16429 | D3: Monthly POC | E3: 1.16095 | G3: HTF Swing High (4H) | H3: 1.1682 | J3: RSI 1H | K3: 42.88 | M3: PipTol Fib (for fibs) | N3: =ROUND($B$15*10000*0.3,0) -> 1 | P3: ShortScore | Q3: =(1-0.5*$N$23)*(1-$B$34*$B$33)*($N$6+$N$8+$N$11+$N$14+$N$16+$N$27+$N$29) -> 0.875 | S3: Entry 0.500 | T3: =IF($N$30=1,$H$26,$B$2) -> 1.16036 | U3: =U2 -> 1.1656 | V3: =V2 -> 1.162 | W3: =IF(OR(T3="",$U$2=""),"",ABS($U$2-T3)*10000) -> 52.4 | X3: =IF(W3="","",W3*T15*0.0001) -> 351.8096 | Y3: =IF($V$2="","",ABS(T3-$V$2)*10000) -> 16.4 | Z3: =IF(Y3="","",Y3*T15*0.0001) -> 110.10835 | AA3: =IF(OR($K$5=0,X3=""),"",X3/$K$5) -> 0.9507024 | AB3: =T15 -> 67139.236 | AC3: 4H | AD3: Bull | AE3: Up | AF3: Up
A4: EMA21 15m | B4: 1.16433 | D4: Monthly VAL | E4: 1.15958 | J4: RSI 4H | K4: 51.66 | M4: PipTol Mid | N4: =ROUND($B$15*10000*0.6,0) -> 3 | S4: Entry 0.618 | T4: =IF($N$30=1,$H$27,$B$2) -> 1.1592036 | U4: =U3 -> 1.1656 | V4: =V3 -> 1.162 | W4: =IF(OR(T4="",$U$2=""),"",ABS($U$2-T4)*10000) -> 63.964 | X4: =IF(W4="","",W4*T16*0.0001) -> 552.14924 | Y4: =IF($V$2="","",ABS(T4-$V$2)*10000) -> 27.964 | Z4: =IF(Y4="","",Y4*T16*0.0001) -> 241.39049 | AA4: =IF(OR($K$5=0,X4=""),"",X4/$K$5) -> 1.4920844 | AB4: =T16 -> 86321.875 | AC4: 1H | AD4: Bear | AE4: Down | AF4: Down
A5: EMA50 15m | B5: 1.16458 | D5: Monthly MID | E5: 1.16385 | G5: HTF Fib 0.382 | H5: =H3-(H3-H2)*0.382 -> 1.160984 | J5: Risk per Trade R ($) | K5: =Summary!B8*Summary!B10*(0.7+0.3*MAX($Q$8,$Q$9)) -> 370.05229 | M5: Long_ValScore | N5: =IF(AND($B$2>$B$6,ABS(($B$2-$E$4)*10000)<=$N$2),1,0)+IF(AND($B$2>$B$6,ABS(($B$2-$E$8)*10000)<=$N$2),1,0)+IF(AND($B$2>$B$6,ABS(($B$2-$E$12)*10000)<=$N$2),1,0)+IF(AND($N$22=1,$B$2>$B$6,ABS(($B$2-$E$17)*10000)<=$N$2),1,0) -> 0 | P5: Bias | Q5: =IF(AND($Q$8>=0.7,$Q$9<=0.3),"A+ LONG ZONE",IF(AND($Q$9>=0.7,$Q$8<=0.3),"A+ SHORT ZONE","MID / WAIT")) -> MID / WAIT | R5: =IF($N$23=1,"⚠ In MID / BALANCE zone – expect chop","") | W5: =SUBTOTAL(109,Table5[Pips to TP1]) -> 0 | X5: =SUBTOTAL(109,Table5[Reward at TP1 ($)]) -> 0 | Y5: =SUBTOTAL(109,Table5[Pips to SL]) -> 0 | Z5: =SUBTOTAL(109,Table5[Risk at SL ($)]) -> 0 | AA5: =SUBTOTAL(109,Table5[R multiple at TP1]) -> 0 | AB5: =SUBTOTAL(109,Table5[Units]) -> 0 | AC5: 15M | AD5: Bear | AE5: Down | AF5: Down
A6: SMA200 15m | B6: 1.16565 | D6: Weekly VAH | E6: 1.1656 | G6: HTF Fib 0.500 | H6: =H3-(H3-H2)*0.5 -> 1.158755 | J6: TP1 Price | K6: =IF($K$11="LONG",MIN(IF($E$2>$B$2,$E$2,10^6),IF($E$6>$B$2,$E$6,10^6),IF($E$10>$B$2,$E$10,10^6),IF($H$3>$B$2,$H$3,10^6)),MAX(IF($E$4<$B$2,$E$4,-10^6),IF($E$8<$B$2,$E$8,-10^6),IF($E$12<$B$2,$E$12,-10^6),IF($H$2<$B$2,$H$2,-10^6))) -> 1.1656 | L6: =MIN(IF($E$2>$B$2,$E$2),IF($E$6>$B$2,$E$6),IF($E$10>$B$2,$E$10),IF($H$2>$B$2,$H$2)) -> 0 | M6: Short_ValScore | N6: =IF(AND($B$2<$B$6,ABS(($B$2-$E$2)*10000)<=$N$2),1,0)+IF(AND($B$2<$B$6,ABS(($B$2-$E$6)*10000)<=$N$2),1,0)+IF(AND($B$2<$B$6,ABS(($B$2-$E$10)*10000)<=$N$2),1,0)+IF(AND($N$22=1,$B$2<$B$6,ABS(($B$2-$E$14)*10000)<=$N$2),1,0) -> 0 | P6: MaxScorePossible | Q6: 10 | AC6: HTF_Long_OK | AD6: =AND(AD2="Bull",AD3="Bull") -> TRUE
D7: Weekly POC | E7: 1.16095 | G7: HTF Fib 0.618 | H7: =H3-(H3-H2)*0.618 -> 1.156526 | J7: SL Price | K7: 1.162 | M7: Long_EMAScore | N7: =IF(AND($B$2>$B$3,$B$3>$B$4,$B$4>$B$5,$B$5>$B$6),1,0)+0.25*COUNTIF($B$8:$B$14,"<"&$B$2) -> 1.5 | S7: Pips to SL 0.382 | T7: =IF($K$7="","",ABS(T2-$K$7)*10000) -> 4.836 | AC7: HTF_Short_OK | AD7: =AND(AD2="Bear",AD3="Bear") -> FALSE
